Workbook

Sheet Materials
A1: Archetypes | B1: MICs (lbs/GSF)
B2: Cast-in-place concrete | C2: Carbon steel (rebar) | D2: Oriented strand board | E2: Softwood | F2: Plywood | G2: Stucco | H2: Cold-formed, galvanized steel | I2: Hot-rolled, structural steel | J2: Cold-formed, structural steel | K2: Polyisocyanurate foam board | L2: Expanded polystyrene foam | M2: Glass mat gypsum board | N2: Aluminum | O2: Aluminum, 20% recycled content | P2: #15 felt | Q2: #30 felt | R2: Transite | S2: Thermoplastic olefin | T2: Laminated glass | U2: Polyvinyl butyral interlayer film | V2: Concrete masonry unit | W2: Solid modular brick | X2: Type S mortar | Y2: Asphalt built-up roof membrane | Z2: Granulated modified bitumen cap sheet | AA2: Asphalt shingles | AB2: Wood cladding (softwood) | AC2: Clay tiles | AD2: Modified bitumen membrane
A3: Aircraft traffic control & operations, 1957 | B3: 76.723499 | C3: 3.4009319 | D3: - | E3: 0.62274701 | F3: 2.04 | G3: - | H3: 2.682622 | I3: 4.83 | J3: 1.4375093 | K3: 0.76555826 | L3: - | M3: 0.88248791 | N3: 0.53628084 | O3: - | P3: 0.06353913 | Q3: 0.20263687 | R3: - | S3: - | T3: - | U3: - | V3: 19.061739 | W3: - | X3: - | Y3: - | Z3: - | AA3: - | AB3: - | AC3: - | AD3: -
A4: Ammunition & Explosives storage magazine, 1952 | B4: 638.98234 | C4: 19.007149 | D4: - | E4: - | F4: - | G4: - | H4: - | I4: - | J4: - | K4: - | L4: - | M4: - | N4: - | O4: - | P4: - | Q4: - | R4: - | S4: - | T4: - | U4: - | V4: - | W4: - | X4: - | Y4: - | Z4: - | AA4: - | AB4: - | AC4: - | AD4: -
A5: Aircraft maintenance hangar, 1960 | B5: 106.43714 | C5: 4.4231189 | D5: - | E5: - | F5: 0.040819531 | G5: - | H5: 1.5365204 | I5: 3.9849631 | J5: 4.7552799 | K5: 0.72320928 | L5: - | M5: 2.5236006 | N5: 0.025564539 | O5: - | P5: 0.052332732 | Q5: 0.0056257686 | R5: 1.430428 | S5: 0.3144325 | T5: 0.07855143 | U5: 0.0040568333 | V5: 13.083183 | W5: - | X5: - | Y5: - | Z5: - | AA5: - | AB5: - | AC5: - | AD5: -
A6: Communications, 1954 | B6: 90.87 | C6: 5.96 | D6: - | E6: - | F6: - | G6: - | H6: 2.1396314 | I6: 3.3276451 | J6: 0.40136519 | K6: 1.301479 | L6: - | M6: 2.4027304 | N6: - | O6: - | P6: - | Q6: - | R6: - | S6: - | T6: 0.35949943 | U6: 0.018566553 | V6: 127.98635 | W6: - | X6: - | Y6: 7.5686007 | Z6: 1.2013652 | AA6: - | AB6: - | AC6: - | AD6: -
A7: Family Housing, 1958 | B7: 61.54 | C7: 2.46 | D7: 1.18 | E7: 9.4078745 | F7: - | G7: 14.44 | H7: - | I7: - | J7: - | K7: - | L7: - | M7: 2.49 | N7: 0.03 | O7: - | P7: 0.2 | Q7: 0.35 | R7: - | S7: - | T7: 0.18 | U7: 0.01 | V7: - | W7: - | X7: - | Y7: - | Z7: - | AA7: 1.6 | AB7: - | AC7: - | AD7: -
A8: Family service center, 1993 | B8: 83.268367 | C8: 3.3064867 | D8: 1.7433734 | E8: 3.6176567 | F8: 0.34519149 | G8: 4.5400349 | H8: - | I8: - | J8: - | K8: 1.0203614 | L8: - | M8: 1.9031459 | N8: 0.21173266 | O8: - | P8: 0.061909566 | Q8: 0.047574468 | R8: - | S8: - | T8: 0.43776178 | U8: 0.022608456 | V8: - | W8: - | X8: - | Y8: 3.524718 | Z8: 0.55947904 | AA8: - | AB8: - | AC8: - | AD8: -
A9: Industrial utilities & fire protection, 2009 | B9: 105 | C9: 4.05 | D9: 1.44 | E9: 4.4428 | F9: - | G9: - | H9: - | I9: - | J9: - | K9: 0.625 | L9: - | M9: 2.3245833 | N9: - | O9: - | P9: 0.025625 | Q9: - | R9: - | S9: - | T9: - | U9: - | V9: - | W9: - | X9: - | Y9: 6.3 | Z9: 1 | AA9: - | AB9: 0.240875 | AC9: - | AD9: -
A10: Lodging, 1993 | B10: 47.493346 | C10: 1.8792308 | D10: 0.88312891 | E10: 8.6613771 | F10: 1.3307105 | G10: 10.94654 | H10: - | I10: - | J10: - | K10: - | L10: - | M10: 1.890766 | N10: 0.055542698 | O10: - | P10: 0.149271 | Q10: - | R10: - | S10: - | T10: 0.3656561 | U10: 0.018884517 | V10: - | W10: - | X10: - | Y10: - | Z10: - | AA10: - | AB10: - | AC10: 6.4394816 | AD10: 1.2265679
A11: maintenance shop, 1959 | B11: 96.332012 | C11: 3.8856967 | D11: - | E11: - | F11: 1.7997592 | G11: - | H11: 3.2403943 | I11: 1.8920546 | J11: 3.7773876 | K11: 1.3171315 | L11: - | M11: 2.9803705 | N11: 0.65645064 | O11: - | P11: 0.21458668 | Q11: 0.24804374 | R11: 3.8087881 | S11: - | T11: 0.11557818 | U11: 0.0059691011 | V11: 19.060995 | W11: - | X11: - | Y11: - | Z11: - | AA11: - | AB11: - | AC11: - | AD11: -
A12: office, 1993 | B12: 101.99796 | C12: 5.442525 | D12: - | E12: - | F12: 0.95382286 | G12: 6.0851336 | H12: 1.0607349 | I12: 2.9344902 | J12: - | K12: 0.42217434 | L12: - | M12: 1.1791766 | N12: 0.38696686 | O12: - | P12: 0.082979095 | Q12: 0.13145636 | R12: - | S12: - | T12: 0.22637037 | U12: 0.011691027 | V12: - | W12: - | X12: - | Y12: 0.40354044 | Z12: 0.064054038 | AA12: - | AB12: - | AC12: - | AD12: -
A13: RDT&E (laboratories), 1965 | B13: 132.99213 | C13: 5.7110236 | D13: - | E13: - | F13: - | G13: - | H13: 5.5658268 | I13: 4.2472441 | J13: 1.8484252 | K13: 1.3779528 | L13: 0.12566929 | M13: 5.6496063 | N13: 0.0094488189 | O13: - | P13: 0.2480315 | Q13: - | R13: - | S13: - | T13: 0.062204724 | U13: 0.0032125984 | V13: 36.909449 | W13: - | X13: - | Y13: 6.9448819 | Z13: 1.1023622 | AA13: - | AB13: - | AC13: - | AD13: -
A14: Recreation & Culture, 1988 | B14: 70.515695 | C14: 2.7954036 | D14: 1.3514045 | E14: 5.5958311 | F14: - | G14: 9.9312407 | H14: 1.5545112 | I14: 4.071988 | J14: 3.3904933 | K14: 0.34379671 | L14: - | M14: 2.8155456 | N14: 0.040189337 | O14: - | P14: 0.13542601 | Q14: - | R14: - | S14: - | T14: 1.2028114 | U14: 0.06211988 | V14: - | W14: - | X14: - | Y14: 3.4654709 | Z14: 0.55007474 | AA14: - | AB14: - | AC14: 6.2780269 | AD14: 1.1958146
A15: Store (Retail & grocery), 1996 | B15: 75.557044 | C15: 3.1594952 | D15: - | E15: - | F15: 1.3792341 | G15: 1.3372382 | H15: 1.5954026 | I15: 1.1498038 | J15: 4.554125 | K15: 0.559485 | L15: - | M15: 0.26551362 | N15: 0.50796955 | O15: 0.063385506 | P15: 0.018235067 | Q15: 0.19008675 | R15: - | S15: - | T15: 0.083669485 | U15: 0.0043211582 | V15: 3.3154667 | W15: - | X15: - | Y15: - | Z15: - | AA15: - | AB15: - | AC15: - | AD15: -
A16: training & academic instruction, 1988 | B16: 61.656721 | C16: 3.8114696 | D16: - | E16: - | F16: 1.6227976 | G16: - | H16: 1.7226621 | I16: 1.7659553 | J16: 0.76211186 | K16: 0.6501593 | L16: - | M16: - | N16: 0.66144078 | O16: - | P16: - | Q16: 0.2236548 | R16: - | S16: - | T16: 0.45777705 | U16: 0.023642156 | V16: 70.80004 | W16: - | X16: - | Y16: - | Z16: - | AA16: - | AB16: - | AC16: - | AD16: -
A17: Unaccompanied housing (barracks), 1996 | B17: 153.02419 | C17: 9.1256845 | D17: - | E17: - | F17: - | G17: - | H17: - | I17: - | J17: - | K17: 0.24445383 | L17: - | M17: 0.78225226 | N17: 0.029569135 | O17: - | P17: - | Q17: - | R17: - | S17: - | T17: 0.19466348 | U17: 0.010053506 | V17: 46.935136 | W17: - | X17: - | Y17: 2.4640946 | Z17: 0.39112613 | AA17: - | AB17: - | AC17: - | AD17: -
A18: warehouse / storage, 1990 | B18: 178.40384 | C18: 7.1252533 | D18: - | E18: - | F18: - | G18: - | H18: 1.2717178 | I18: 0.40362767 | J18: 3.6924457 | K18: 0.64883563 | L18: 0.15260614 | M18: 2.076274 | N18: - | O18: - | P18: - | Q18: - | R18: - | S18: 0.36334795 | T18: - | U18: - | V18: - | W18: - | X18: - | Y18: - | Z18: - | AA18: - | AB18: - | AC18: - | AD18: -
A19: Public service, 1989 | B19: 84.344233 | C19: 3.3388274 | D19: 1.5189873 | E19: 3.0625879 | F19: 1.9015471 | G19: 8.2512893 | H19: 1.785654 | I19: 5.2789498 | J19: - | K19: 0.98159869 | L19: - | M19: 2.1284576 | N19: 0.93531411 | O19: - | P19: 0.11251758 | Q19: 0.2620722 | R19: - | S19: - | T19: 0.91666667 | U19: 0.047341772 | V19: - | W19: - | X19: - | Y19: 2.2151899 | Z19: 0.35161744 | AA19: - | AB19: - | AC19: - | AD19: -
A20: Ship operational, 1953 | B20: 104.36029 | C20: 3.7177941 | D20: - | E20: - | F20: 1.8352941 | G20: - | H20: 3.3858824 | I20: 2.1345882 | J20: 1.6767059 | K20: 0.99264706 | L20: - | M20: 1.2867647 | N20: 0.66941176 | O20: - | P20: 0.092647059 | Q20: 0.25294118 | R20: - | S20: - | T20: 0.33691176 | U20: 0.0174 | V20: - | W20: - | X20: - | Y20: - | Z20: - | AA20: - | AB20: - | AC20: - | AD20: -
A21: Security, 1950 | B21: 80.730459 | C21: 3.1958359 | D21: 1.4665012 | E21: 5.8032118 | F21: - | G21: 5.9139785 | H21: - | I21: - | J21: - | K21: - | L21: - | M21: 1.0215054 | N21: 0.11166253 | O21: - | P21: 0.080645161 | Q21: 0.43569065 | R21: - | S21: - | T21: 0.73511166 | U21: 0.037965261 | V21: - | W21: 3.3498759 | X21: 0.44665012 | Y21: - | Z21: - | AA21: 1.9758065 | AB21: - | AC21: - | AD21: -
A22: Military medical facilities, 1985 | B22: 163.24557 | C22: 7.4214896 | D22: - | E22: - | F22: - | G22: - | H22: 0.82801683 | I22: 1.0998679 | J22: 0.30709218 | K22: 0.31250635 | L22: 0.24303283 | M22: 1.0000203 | N22: - | O22: - | P22: - | Q22: - | R22: - | S22: - | T22: - | U22: - | V22: - | W22: - | X22: - | Y22: 3.150064 | Z22: 0.50001016 | AA22: - | AB22: - | AC22: - | AD22: -
A23: Fire station, 1947 | B23: 93.627451 | C23: 3.7184977 | D23: 1.4698962 | E23: 5.8608159 | F23: - | G23: 5.0749712 | H23: - | I23: - | J23: - | K23: 0.67266436 | L23: - | M23: 3.1280277 | N23: 0.03633218 | O23: - | P23: 0.083044983 | Q23: - | R23: - | S23: - | T23: 0.23918685 | U23: 0.012352941 | V23: - | W23: 2.9896194 | X23: 0.39861592 | Y23: 6.5397924 | Z23: 1.0380623 | AA23: - | AB23: - | AC23: - | AD23: -
A24: Dining, 1954 | B24: 341.27089 | C24: 16.548988 | D24: - | E24: - | F24: - | G24: - | H24: 0.27439402 | I24: 0.076419735 | J24: 0.045683479 | K24: 0.62688064 | L24: - | M24: 2.0060181 | N24: - | O24: - | P24: - | Q24: - | R24: - | S24: 0.35105316 | T24: 0.19695882 | U24: 0.010172051 | V24: 3.8209868 | W24: - | X24: - | Y24: - | Z24: - | AA24: - | AB24: - | AC24: - | AD24: -
A25: armory, 1967 | B25: 97.116938 | C25: 5.8257736 | D25: - | E25: - | F25: - | G25: - | H25: 1.7605008 | I25: - | J25: 3.0845035 | K25: 0.66018392 | L25: - | M25: 2.1125885 | N25: - | O25: - | P25: - | Q25: - | R25: - | S25: - | T25: 0.0085901578 | U25: 0.00044364359 | V25: 106.87213 | W25: - | X25: - | Y25: 6.6546539 | Z25: 1.0562943 | AA25: - | AB25: - | AC25: - | AD25: -

Sheet Components
A1: Archetype | B1: Components (SF/GSF)
B2: steel doors | C2: overhead doors | D2: blast resisitant doors | E2: overhead roll-up doors | F2: glazed doors w/ metal | G2: insulated, hot-rolled sheet steel hangar door | H2: sliding glass patio door | I2: wood door | J2: FRP door | K2: Vault door
A3: Aircraft traffic control & operations, 1957 | B3: 0.013343217 | C3: 0.02700413 | D3: - | E3: - | F3: - | G3: - | H3: - | I3: - | J3: - | K3: -
A4: Ammunition & Explosives storage magazine, 1952 | B4: - | C4: - | D4: 0.040370059 | E4: - | F4: - | G4: - | H4: - | I4: - | J4: - | K4: -
A5: Aircraft maintenance hangar, 1960 | B5: 0.0059 | C5: - | D5: - | E5: 0.0044 | F5: 0.0009 | G5: 0.1514 | H5: - | I5: - | J5: - | K5: -
A6: Communications, 1954 | B6: 0.0717 | C6: - | D6: - | E6: - | F6: - | G6: - | H6: - | I6: - | J6: - | K6: -
A7: Family Housing, 1958 | B7: - | C7: - | D7: - | E7: - | F7: - | G7: - | H7: - | I7: - | J7: - | K7: -
A8: Family service center, 1993 | B8: 0.040447583 | C8: - | D8: - | E8: - | F8: 0.0038521508 | G8: - | H8: - | I8: - | J8: - | K8: -
A9: Industrial utilities & fire protection, 2009 | B9: 0.175 | C9: - | D9: - | E9: - | F9: - | G9: - | H9: - | I9: - | J9: - | K9: -
A10: Lodging, 1993 | B10: - | C10: - | D10: - | E10: - | F10: - | G10: - | H10: 0.037028466 | I10: 0.064799815 | J10: - | K10: -
A11: maintenance shop, 1959 | B11: 0.018960674 | C11: 0.16252006 | D11: - | E11: - | F11: - | G11: - | H11: - | I11: - | J11: - | K11: -
A12: office, 1993 | B12: 0.0015285623 | C12: - | D12: - | E12: - | F12: 0.003362837 | G12: - | H12: - | I12: - | J12: - | K12: -
A13: RDT&E (laboratories), 1965 | B13: - | C13: - | D13: - | E13: - | F13: - | G13: - | H13: - | I13: - | J13: - | K13: -
A14: Recreation & Culture, 1988 | B14: 0.0087892377 | C14: - | D14: - | E14: - | F14: 0.011300448 | G14: - | H14: - | I14: - | J14: - | K14: -
A15: Store (Retail & grocery), 1996 | B15: 0.0011604133 | C15: 0.0037575289 | D15: - | E15: - | F15: 0.0012764547 | G15: - | H15: - | I15: - | J15: - | K15: -
A16: training & academic instruction, 1988 | B16: 0.024426014 | C16: - | D16: - | E16: - | F16: 0.005310003 | G16: - | H16: - | I16: - | J16: 0.0031860018 | K16: -
A17: Unaccompanied housing (barracks), 1996 | B17: 0.0037548109 | C17: - | D17: - | E17: - | F17: - | G17: - | H17: - | I17: 0.041302919 | J17: - | K17: -
A18: warehouse / storage, 1990 | B18: 0.0012208491 | C18: 0.014949173 | D18: - | E18: - | F18: - | G18: - | H18: - | I18: - | J18: - | K18: -
A19: Public service, 1989 | B19: - | C19: - | D19: - | E19: - | F19: 0.019690577 | G19: - | H19: 0.1125 | I19: - | J19: - | K19: -
A20: Ship operational, 1953 | B20: - | C20: 0.035294118 | D20: - | E20: - | F20: - | G20: - | H20: - | I20: - | J20: 0.019764706 | K20: -
A21: Security, 1950 | B21: 0.023883375 | C21: - | D21: - | E21: - | F21: 0.0086848635 | G21: - | H21: - | I21: - | J21: - | K21: -
A22: Military medical facilities, 1985 | B22: - | C22: - | D22: - | E22: - | F22: 0.0034149812 | G22: - | H22: - | I22: - | J22: - | K22: -
A23: Fire station, 1947 | B23: 0.0096885813 | C23: 0.15224913 | D23: - | E23: - | F23: - | G23: - | H23: - | I23: - | J23: - | K23: -
A24: Dining, 1954 | B24: 0.0050150451 | C24: - | D24: - | E24: - | F24: 0.0040120361 | G24: - | H24: - | I24: 0.0055165496 | J24: - | K24: -
A25: armory, 1967 | B25: 0.023487014 | C25: - | D25: - | E25: - | F25: - | G25: - | H25: - | I25: - | J25: - | K25: 0.019763784

Sheet MIC by location
B1: MIC (lbs/GSF)
A2: Archetype | B2: FOOTING | C2: Slab | D2: Basement | E2: Floor construction | H2: Roof construction | M2: Exterior walls | V2: Windows | AA2: Roof covering
B3: Strip footing | C3: Reinforced slab | D3: CIP concrete | E3: Wood beam, joist, and deck | F3: Light gauge steel floor system | G3: CIP concrete beam and slab | H3: Steel deck, beams, and bar joist | I3: Metal structural frame | J3: CIP concrete cap | K3: wood deck and rafter | L3: CIP concrete beams and slab | M3: Concrete block | N3: CIP concrete | O3: Metal siding panels | P3: Stucco | Q3: Wood cladding w/ stud backup | R3: Transite siding panel | S3: Precast concrete panel (tilt up) | T3: Solid brick - single wythe | U3: Brick veneer w/ stud backup | V3: Aluminum | W3: Steel | X3: Curtain wall | Y3: tubular aluminum framing - storefronts | Z3: wood | AA3: Preformed metal | AB3: Single ply membrane | AC3: BUR | AD3: Asphalt shingles | AE3: Clay tile | AF3: Transite formed metal
A4: Aircraft traffic control & operations, 1957 | B4: =SUM('Aircraft traffic control & oper'!Q2:Q4) -> 6.2474849 | C4: =SUM('Aircraft traffic control & oper'!Q5:Q6) -> 73.514773 | D4: - | E4: =SUM('Aircraft traffic control & oper'!Q7:Q17) -> 1.1910692 | F4: - | G4: - | H4: =SUM('Aircraft traffic control & oper'!Q18:Q29) -> 7.9362914 | I4: - | J4: - | K4: - | L4: - | M4: =SUM('Aircraft traffic control & oper'!Q30:Q31) -> 19.423912 | N4: - | O4: =SUM('Aircraft traffic control & oper'!Q32:Q35) -> 2.1391507 | P4: - | Q4: - | R4: - | S4: - | T4: - | U4: - | V4: - | W4: - | X4: - | Y4: - | Z4: - | AA4: =SUM('Aircraft traffic control & oper'!Q39:Q49) -> 2.7982739 | AB4: - | AC4: - | AD4: - | AE4: - | AF4: - | AG4: =SUM(B4:AF4) -> 113.25095
A5: Ammunition & Explosives storage magazine, 1952 | B5: =SUM('Ammunition & explosives storage'!Q2:Q5) -> 14.36291 | C5: =SUM('Ammunition & explosives storage'!Q6:Q7) -> 75.441548 | D5: - | E5: - | F5: - | G5: - | H5: - | I5: - | J5: =SUM('Ammunition & explosives storage'!Q8:Q9) -> 328.00673 | K5: - | L5: - | M5: - | N5: =SUM('Ammunition & explosives storage'!Q10:Q19) -> 240.1783 | O5: - | P5: - | Q5: - | R5: - | S5: - | T5: - | U5: - | V5: - | W5: - | X5: - | Y5: - | Z5: - | AA5: - | AB5: - | AC5: - | AD5: - | AE5: - | AF5: - | AG5: =SUM(B5:AF5) -> 657.98949
A6: Aircraft maintenance hangar, 1960 | B6: =SUM('Aircraft maintenance hangar'!Q2:Q4) -> 2.8436298 | C6: =SUM('Aircraft maintenance hangar'!Q5:Q6) -> 96.243382 | D6: - | E6: - | F6: =SUM('Aircraft maintenance hangar'!Q7:Q21) -> 9.680554 | G6: - | H6: =SUM('Aircraft maintenance hangar'!Q22:Q35) -> 6.5916704 | I6: =SUM('Aircraft maintenance hangar'!Q36:Q39) -> 1.812914 | J6: - | K6: - | L6: - | M6: =SUM('Aircraft maintenance hangar'!Q45:Q46) -> 13.331763 | N6: =SUM('Aircraft maintenance hangar'!Q40:Q44) -> 3.7122659 | O6: =SUM('Aircraft maintenance hangar'!Q47:Q50) -> 2.3549729 | P6: - | Q6: - | R6: - | S6: - | T6: - | U6: - | V6: =SUM('Aircraft maintenance hangar'!Q62:Q70) -> 0.084588534 | W6: =SUM('Aircraft maintenance hangar'!Q55:Q61) -> 0.012725227 | X6: - | Y6: - | Z6: - | AA6: =SUM('Aircraft maintenance hangar'!Q81:Q91) -> 0.07768794 | AB6: =SUM('Aircraft maintenance hangar'!Q71:Q80) -> 2.6726762 | AC6: - | AD6: - | AE6: - | AF6: - | AG6: =SUM(B6:AF6) -> 139.41883
A7: Communications, 1954 | B7: =SUM(Communications!Q2:Q5) -> 21.194539 | C7: =SUM(Communications!Q6:Q8) -> 73.208191 | D7: - | E7: - | F7: - | G7: - | H7: =SUM(Communications!Q9:Q20) -> 5.718471 | I7: - | J7: - | K7: - | L7: - | M7: =SUM(Communications!Q21:Q23) -> 130.41809 | N7: - | O7: - | P7: - | Q7: - | R7: - | S7: - | T7: - | U7: - | V7: - | W7: =SUM(Communications!Q24:Q31) -> 0.52823663 | X7: - | Y7: - | Z7: - | AA7: - | AB7: - | AC7: =SUM(Communications!Q33:Q43) -> 12.474175 | AD7: - | AE7: - | AF7: - | AG7: =SUM(B7:AF7) -> 243.5417
A8: Family Housing, 1958 | B8: - | C8: =SUM('Family housing'!Q2:Q3) -> 64.002193 | D8: - | E8: - | F8: - | G8: - | H8: - | I8: - | J8: - | K8: =SUM('Family housing'!Q4:Q12) -> 10.589453 | L8: - | M8: - | N8: - | O8: - | P8: =SUM('Family housing'!Q13:Q18) -> 17.132895 | Q8: - | R8: - | S8: - | T8: - | U8: - | V8: =SUM('Family housing'!Q19:Q28) -> 0.2128527 | W8: - | X8: - | Y8: - | Z8: - | AA8: - | AB8: - | AC8: - | AD8: =SUM('Family housing'!Q29:Q35) -> 1.9528874 | AE8: - | AF8: - | AG8: =SUM(B8:AF8) -> 93.890281
A9: Family service center, 1993 | B9: =SUM('Family service center'!Q2:Q4) -> 5.0193181 | C9: =SUM('Family service center'!Q5:Q6) -> 81.555535 | D9: - | E9: - | F9: - | G9: - | H9: - | I9: - | J9: - | K9: =SUM('Family service center'!Q7:Q35) -> 5.3610301 | L9: - | M9: - | N9: - | O9: - | P9: =SUM('Family service center'!Q36:Q41) -> 5.3861323 | Q9: - | R9: - | S9: - | T9: - | U9: - | V9: =SUM('Family service center'!Q44:Q53) -> 0.38152343 | W9: - | X9: =SUM('Family service center'!Q54:Q59) -> 0.16467308 | Y9: - | Z9: - | AA9: =SUM('Family service center'!Q71:Q82) -> 1.1893593 | AB9: - | AC9: =SUM('Family service center'!Q60:Q70) -> 5.5528295 | AD9: - | AE9: - | AF9: - | AG9: =SUM(B9:AF9) -> 104.6104
A10: Industrial utilities & fire protection, 2009 | B10: =SUM('Industrial utilities'!Q2:Q4) -> 31.05 | C10: =SUM('Industrial utilities'!Q5:Q6) -> 78 | D10: - | E10: - | F10: - | G10: - | H10: - | I10: - | J10: - | K10: =SUM('Industrial utilities'!Q7:Q20) -> 5.5828 | L10: - | M10: - | N10: - | O10: - | P10: - | Q10: =SUM('Industrial utilities'!Q21:Q27) -> 0.89108333 | R10: - | S10: - | T10: - | U10: - | V10: - | W10: - | X10: - | Y10: - | Z10: - | AA10: - | AB10: - | AC10: =SUM('Industrial utilities'!Q29:Q39) -> 9.925 | AD10: - | AE10: - | AF10: - | AG10: =SUM(B10:AF10) -> 125.44888
A11: Lodging, 1993 | B11: =SUM(Lodging!Q2:Q4) -> 4.2441347 | C11: =SUM(Lodging!Q5:Q6) -> 45.128442 | D11: - | E11: =SUM(Lodging!Q7:Q17) -> 3.4349487 | F11: - | G11: - | H11: - | I11: - | J11: - | K11: =SUM(Lodging!Q18:Q27) -> 4.9352921 | L11: - | M11: - | N11: - | O11: - | P11: =SUM(Lodging!Q28:Q33) -> 12.986577 | Q11: - | R11: - | S11: - | T11: - | U11: - | V11: =SUM(Lodging!Q34:Q43) -> 0.44008331 | W11: - | X11: - | Y11: - | Z11: - | AA11: - | AB11: - | AC11: - | AD11: - | AE11: =SUM(Lodging!Q46:Q54) -> 10.171025 | AF11: - | AG11: =SUM(B11:AF11) -> 81.340504
A12: maintenance shop, 1959 | B12: =SUM('Maintenance shop'!Q2:Q4) -> 7.3591117 | C12: =SUM('Maintenance shop'!Q5:Q6) -> 76.716693 | D12: - | E12: - | F12: - | G12: - | H12: =SUM('Maintenance shop'!Q7:Q19) -> 7.49689 | I12: - | J12: - | K12: - | L12: - | M12: =SUM('Maintenance shop'!Q25:Q26) -> 19.423154 | N12: =SUM('Maintenance shop'!Q20:Q24) -> 15.779745 | O12: =SUM('Maintenance shop'!Q27:Q30) -> 2.8877408 | P12: - | Q12: - | R12: =SUM('Maintenance shop'!Q31:Q34) -> 5.796549 | S12: - | T12: - | U12: - | V12: - | W12: =SUM('Maintenance shop'!Q39:Q46) -> 0.16210206 | X12: - | Y12: - | Z12: - | AA12: =SUM('Maintenance shop'!Q47:Q57) -> 3.425311 | AB12: - | AC12: - | AD12: - | AE12: - | AF12: =SUM('Maintenance shop'!Q58:Q60) -> 0.28792135 | AG12: =SUM(B12:AF12) -> 139.33522
A13: office, 1993 | B13: =SUM(Office!Q2:Q4) -> 1.864573 | C13: =SUM(Office!Q5:Q6) -> 46.55564 | D13: - | E13: - | F13: - | G13: =SUM(Office!Q7:Q12) -> 59.020271 | H13: =SUM(Office!Q13:Q22) -> 3.9952251 | I13: - | J13: - | K13: - | L13: - | M13: - | N13: - | O13: - | P13: =SUM(Office!Q23:Q28) -> 7.2191813 | Q13: - | R13: - | S13: - | T13: - | U13: - | V13: =SUM(Office!Q29:Q38) -> 0.21477387 | W13: - | X13: =SUM(Office!Q39:Q43) -> 0.062353614 | Y13: - | Z13: - | AA13: =SUM(Office!Q59:Q70) -> 1.8153206 | AB13: - | AC13: =SUM(Office!Q46:Q58) -> 0.63573633 | AD13: - | AE13: - | AF13: - | AG13: =SUM(B13:AF13) -> 121.38307
A14: RDT&E (laboratories), 1965 | B14: =SUM('RDT&E'!Q2:Q5) -> 15.769488 | C14: =SUM('RDT&E'!Q6:Q8) -> 80.456693 | D14: - | E14: - | F14: - | G14: - | H14: =SUM('RDT&E'!Q9:Q21) -> 7.6929921 | I14: - | J14: - | K14: - | L14: - | M14: =SUM('RDT&E'!Q22:Q24) -> 37.376969 | N14: - | O14: =SUM('RDT&E'!Q30:Q34) -> 8.3503937 | P14: - | Q14: - | R14: - | S14: =SUM('RDT&E'!Q25:Q29) -> 42.135118 | T14: - | U14: - | V14: =SUM('RDT&E'!Q35:Q44) -> 0.074866142 | W14: - | X14: - | Y14: - | Z14: - | AA14: - | AB14: - | AC14: =SUM('RDT&E'!Q45:Q55) -> 10.940945 | AD14: - | AE14: - | AF14: - | AG14: =SUM(B14:AF14) -> 202.79746
A15: Recreation & Culture, 1988 | B15: =SUM('Recreation & culture'!Q2:Q4) -> 5.2214126 | C15: =SUM('Recreation & culture'!Q5:Q6) -> 68.089686 | D15: - | E15: - | F15: - | G15: - | H15: =SUM('Recreation & culture'!Q19:Q28) -> 9.0169925 | I15: - | J15: - | K15: =SUM('Recreation & culture'!Q7:Q18) -> 1.9043713 | L15: - | M15: - | N15: - | O15: - | P15: =SUM('Recreation & culture'!Q29:Q34) -> 11.782063 | Q15: - | R15: - | S15: - | T15: - | U15: - | V15: =SUM('Recreation & culture'!Q38:Q47) -> 0.2250274 | W15: - | X15: =SUM('Recreation & culture'!Q58:Q63) -> 0.0333142 | Y15: - | Z15: =SUM('Recreation & culture'!Q48:Q57) -> 3.5263904 | AA15: - | AB15: - | AC15: =SUM('Recreation & culture'!Q64:Q74) -> 5.4594918 | AD15: - | AE15: =SUM('Recreation & culture'!Q75:Q83) -> 10.037095 | AF15: - | AG15: =SUM(B15:AF15) -> 115.29584
A16: Store (Retail & grocery), 1996 | B16: =SUM('Store (retail & grocery)'!Q2:Q4) -> 2.1712867 | C16: =SUM('Store (retail & grocery)'!Q5:Q6) -> 66.239443 | D16: - | E16: - | F16: - | G16: - | H16: =SUM('Store (retail & grocery)'!Q14:Q25) -> 7.2595458 | I16: - | J16: - | K16: - | L16: =SUM('Store (retail & grocery)'!Q7:Q13) -> 6.663908 | M16: =SUM('Store (retail & grocery)'!Q37:Q38) -> 3.3784605 | N16: =SUM('Store (retail & grocery)'!Q26:Q30) -> 3.5789081 | O16: =SUM('Store (retail & grocery)'!Q39:Q42) -> 0.083715533 | P16: =SUM('Store (retail & grocery)'!Q31:Q36) -> 1.5864508 | Q16: - | R16: - | S16: - | T16: - | U16: - | V16: - | W16: - | X16: =SUM('Store (retail & grocery)'!Q47:Q52) -> 0.024031147 | Y16: =SUM('Store (retail & grocery)'!Q53:Q60) -> 0.13224775 | Z16: - | AA16: =SUM('Store (retail & grocery)'!Q61:Q71) -> 2.6249655 | AB16: - | AC16: - | AD16: - | AE16: - | AF16: - | AG16: =SUM(B16:AF16) -> 93.742963
A17: training & academic instruction, 1988 | B17: - | C17: =SUM('Training & academic instruction'!Q2:Q3) -> 64.12299 | D17: - | E17: - | F17: - | G17: - | H17: =SUM('Training & academic instruction'!Q4:Q10) -> 4.2507292 | I17: - | J17: - | K17: - | L17: - | M17: =SUM('Training & academic instruction'!Q11:Q13) -> 72.145241 | N17: - | O17: - | P17: - | Q17: - | R17: - | S17: - | T17: - | U17: - | V17: =SUM('Training & academic instruction'!Q17:Q26) -> 0.55095496 | W17: - | X17: - | Y17: - | Z17: - | AA17: =SUM('Training & academic instruction'!Q27:Q38) -> 3.0885167 | AB17: - | AC17: - | AD17: - | AE17: - | AF17: - | AG17: =SUM(B17:AF17) -> 144.15843
A18: Unaccompanied housing (barracks), 1996 | B18: =SUM('Unaccompanied housing (barracks'!Q2:Q4) -> 1.82167 | C18: =SUM('Unaccompanied housing (barracks'!Q5:Q6) -> 40.677118 | D18: - | E18: - | F18: - | G18: =SUM('Unaccompanied housing (barracks'!Q7:Q12) -> 79.172878 | H18: - | I18: - | J18: - | K18: - | L18: =SUM('Unaccompanied housing (barracks'!Q13:Q19) -> 39.586439 | M18: =SUM('Unaccompanied housing (barracks'!Q20:Q22) -> 47.826903 | N18: - | O18: - | P18: - | Q18: - | R18: - | S18: - | T18: - | U18: - | V18: =SUM('Unaccompanied housing (barracks'!Q25:Q35) -> 0.23428612 | W18: - | X18: - | Y18: - | Z18: - | AA18: - | AB18: - | AC18: =SUM('Unaccompanied housing (barracks'!Q36:Q46) -> 3.8819268 | AD18: - | AE18: - | AF18: - | AG18: =SUM(B18:AF18) -> 213.20122
A19: warehouse / storage, 1990 | B19: =SUM('Warehouse & storage'!Q2:Q4) -> 2.2563908 | C19: =SUM('Warehouse & storage'!Q5:Q6) -> 132.25865 | D19: - | E19: - | F19: - | G19: - | H19: =SUM('Warehouse & storage'!Q7:Q18) -> 5.3677912 | I19: - | J19: - | K19: - | L19: - | M19: - | N19: - | O19: - | P19: - | Q19: - | R19: - | S19: =SUM('Warehouse & storage'!Q19:Q23) -> 51.166658 | T19: - | U19: - | V19: - | W19: - | X19: - | Y19: - | Z19: - | AA19: - | AB19: =SUM('Warehouse & storage'!Q31:Q40) -> 3.0884576 | AC19: - | AD19: - | AE19: - | AF19: - | AG19: =SUM(B19:AF19) -> 194.13795
A20: Public service, 1989 | B20: =SUM('Public service'!Q2:Q4) -> 7.2329905 | C20: =SUM('Public service'!Q5:Q6) -> 80.45007 | D20: - | E20: - | F20: - | G20: - | H20: =SUM('Public service'!Q14:Q23) -> 7.0646038 | I20: - | J20: - | K20: =SUM('Public service'!Q7:Q13) -> 4.5815752 | L20: - | M20: - | N20: - | O20: - | P20: =SUM('Public service'!Q24:Q29) -> 9.7890295 | Q20: - | R20: - | S20: - | T20: - | U20: - | V20: =SUM('Public service'!Q33:Q42) -> 0.26745429 | W20: - | X20: =SUM('Public service'!Q43:Q48) -> 0.93829114 | Y20: - | Z20: - | AA20: =SUM('Public service'!Q60:Q70) -> 3.6190342 | AB20: - | AC20: =SUM('Public service'!Q49:Q59) -> 3.4898031 | AD20: - | AE20: - | AF20: - | AG20: =SUM(B20:AF20) -> 117.43285
A21: Ship operational, 1953 | B21: =SUM('Ship operational'!Q2:Q4) -> 6.3013235 | C21: =SUM('Ship operational'!Q5:Q6) -> 78.917647 | D21: - | E21: - | F21: - | G21: - | H21: =SUM('Ship operational'!Q7:Q23) -> 5.5647059 | I21: - | J21: - | K21: - | L21: - | M21: - | N21: =SUM('Ship operational'!Q24:Q28) -> 22.859118 | O21: =SUM('Ship operational'!Q29:Q32) -> 3.1191176 | P21: - | Q21: - | R21: - | S21: - | T21: - | U21: - | V21: - | W21: =SUM('Ship operational'!Q35:Q41) -> 0.50442941 | X21: - | Y21: - | Z21: - | AA21: =SUM('Ship operational'!Q42:Q51) -> 3.4929412 | AB21: - | AC21: - | AD21: - | AE21: - | AF21: - | AG21: =SUM(B21:AF21) -> 120.75928
A22: Security, 1950 | B22: =SUM(Security!Q2:Q4) -> 6.9101659 | C22: =SUM(Security!Q5:Q6) -> 77.016129 | D22: - | E22: - | F22: - | G22: - | H22: - | I22: - | J22: - | K22: =SUM(Security!Q7:Q16) -> 7.2697131 | L22: - | M22: - | N22: - | O22: - | P22: =SUM(Security!Q17:Q22) -> 7.016129 | Q22: - | R22: - | S22: - | T22: =SUM(Security!Q23:Q34) -> 3.7965261 | U22: - | V22: =SUM(Security!Q35:Q43) -> 0.88473945 | W22: - | X22: - | Y22: - | Z22: - | AA22: - | AB22: - | AC22: - | AD22: =SUM(Security!Q46:Q52) -> 2.4114971 | AE22: - | AF22: - | AG22: =SUM(B22:AF22) -> 105.3049
A23: Medical facilities, 1985 | B23: - | C23: =SUM(Medical!Q5:Q7) -> 39.000793 | D23: - | E23: - | F23: - | G23: =SUM(Medical!Q8:Q13) -> 50.42386 | H23: =SUM(Medical!Q14:Q29) -> 2.2349769 | I23: - | J23: - | K23: - | L23: - | M23: - | N23: - | O23: - | P23: - | Q23: - | R23: - | S23: =SUM(Medical!Q30:Q35) -> 81.485436 | T23: - | U23: - | V23: - | W23: - | X23: - | Y23: - | Z23: - | AA23: - | AB23: - | AC23: =SUM(Medical!Q37:Q47) -> 4.9626009 | AD23: - | AE23: - | AF23: - | AG23: =SUM(B23:AF23) -> 178.10767
A24: Fire station, 1947 | B24: =SUM('Fire station'!Q2:Q4) -> 5.5062716 | C24: =SUM('Fire station'!Q5:Q6) -> 91.839677 | D24: - | E24: - | F24: - | G24: - | H24: - | I24: - | J24: - | K24: =SUM('Fire station'!Q7:Q29) -> 7.3307121 | L24: - | M24: - | N24: - | O24: - | P24: =SUM('Fire station'!Q30:Q35) -> 6.0207612 | Q24: - | R24: - | S24: - | T24: - | U24: =SUM('Fire station'!Q36:Q48) -> 3.5773933 | V24: =SUM('Fire station'!Q51:Q60) -> 0.28787197 | W24: - | X24: - | Y24: - | Z24: - | AA24: - | AB24: - | AC24: =SUM('Fire station'!Q61:Q71) -> 10.326644 | AD24: - | AE24: - | AF24: - | AG24: =SUM(B24:AF24) -> 124.88933
A25: Dining, 1954 | B25: =SUM(Dining!Q2:Q4) -> 4.8198166 | C25: =SUM(Dining!Q5:Q6) -> 76.651383 | D25: =SUM(Dining!Q7:Q9) -> 28.21339 | E25: - | F25: - | G25: =SUM(Dining!Q10:Q15) -> 97.859245 | H25: =SUM(Dining!Q16:Q27) -> 0.22492597 | I25: - | J25: - | K25: - | L25: =SUM(Dining!Q28:Q33) -> 103.80173 | M25: =SUM(Dining!Q39:Q40) -> 3.8935855 | N25: =SUM(Dining!Q34:Q38) -> 46.401705 | O25: - | P25: - | Q25: - | R25: - | S25: - | T25: - | U25: - | V25: - | W25: =SUM(Dining!Q44:Q50) -> 0.37870213 | X25: - | Y25: - | Z25: - | AA25: - | AB25: =SUM(Dining!Q51:Q60) -> 2.9839519 | AC25: - | AD25: - | AE25: - | AF25: - | AG25: =SUM(B25:AF25) -> 365.22844
A26: armory, 1967 | B26: =SUM(Armory!Q2:Q4) -> 18.521188 | C26: =SUM(Armory!Q5:Q6) -> 82.390953 | D26: - | E26: - | F26: - | G26: - | H26: =SUM(Armory!Q7:Q16) -> 4.8337269 | I26: - | J26: - | K26: - | L26: - | M26: =SUM(Armory!Q17:Q19) -> 108.9027 | N26: - | O26: - | P26: - | Q26: - | R26: - | S26: - | T26: - | U26: - | V26: - | W26: =SUM(Armory!Q20:Q27) -> 0.020311296 | X26: - | Y26: - | Z26: - | AA26: - | AB26: - | AC26: =SUM(Armory!Q31:Q41) -> 10.483721 | AD26: - | AE26: - | AF26: - | AG26: =SUM(B26:AF26) -> 225.1526
A27: Average MICs | B27: =AVERAGE(B4:B26) -> 8.5358853 | C27: =AVERAGE(C4:C26) -> 73.412071 | D27: =AVERAGE(D4:D26) -> 28.21339 | E27: =AVERAGE(E4:E26) -> 2.313009 | F27: =AVERAGE(F4:F26) -> 9.680554 | G27: =AVERAGE(G4:G26) -> 71.619063 | H27: =AVERAGE(H4:H26) -> 5.6833025 | I27: =AVERAGE(I4:I26) -> 1.812914 | ... AF27: =AVERAGE(AF4:AF26) -> 0.28792135 | AG27: =SUM(AG4:AG26) -> 4020.4183

Sheet MIC % by location
B1: MIC (lbs/GSF)
A2: Archetype | B2: FOOTING | C2: Slab | D2: Basement | E2: Floor construction | H2: Roof construction | M2: Exterior walls | V2: Windows | AA2: Roof covering
B3: Strip footing | C3: Reinforced slab | D3: CIP concrete | E3: Wood beam, joist, and deck | F3: Light gauge steel floor system | G3: CIP concrete beam and slab | H3: Steel deck, beams, and bar joist | I3: Metal structural frame | J3: CIP concrete cap | K3: wood deck and rafter | L3: CIP concrete beams and slab | M3: Concrete block | N3: CIP concrete | O3: Metal siding panels | P3: Stucco | Q3: Wood cladding w/ stud backup | R3: Transite siding panel | S3: Precast concrete panel (tilt up) | T3: Solid brick - single wythe | U3: Brick veneer w/ stud backup | V3: Aluminum | W3: Steel | X3: Curtain wall | Y3: tubular aluminum framing - storefronts | Z3: wood | AA3: Preformed metal | AB3: Single ply membrane | AC3: BUR | AD3: Asphalt shingles | AE3: Clay tile | AF3: Transite formed metal
A4: Aircraft traffic control & operations | B4: ='MIC by location'!B4/'MIC by location'!$AG4 -> 0.055164965 | C4: ='MIC by location'!C4/'MIC by location'!$AG4 -> 0.64913159 | D4: - | E4: ='MIC by location'!E4/'MIC by location'!$AG4 -> 0.010517079 | F4: - | G4: - | H4: ='MIC by location'!H4/'MIC by location'!$AG4 -> 0.070077038 | I4: - | J4: - | K4: - | L4: - | M4: ='MIC by location'!M4/'MIC by location'!$AG4 -> 0.17151212 | N4: - | O4: ='MIC by location'!O4/'MIC by location'!$AG4 -> 0.018888589 | P4: - | Q4: - | R4: - | S4: - | T4: - | U4: - | V4: - | W4: - | X4: - | Y4: - | Z4: - | AA4: ='MIC by location'!AA4/'MIC by location'!$AG4 -> 0.024708612 | AB4: - | AC4: - | AD4: - | AE4: - | AF4: - | AG4: =SUM(B4:AF4) -> 1
A5: Ammunition & Explosives storage magazine | B5: ='MIC by location'!B5/'MIC by location'!$AG5 -> 0.021828479 | C5: ='MIC by location'!C5/'MIC by location'!$AG5 -> 0.11465464 | D5: - | E5: - | F5: - | G5: - | H5: - | I5: - | J5: ='MIC by location'!J5/'MIC by location'!$AG5 -> 0.49849843 | K5: - | L5: - | M5: - | N5: ='MIC by location'!N5/'MIC by location'!$AG5 -> 0.36501845 | O5: - | P5: - | Q5: - | R5: - | S5: - | T5: - | U5: - | V5: - | W5: - | X5: - | Y5: - | Z5: - | AA5: - | AB5: - | AC5: - | AD5: - | AE5: - | AF5: - | AG5: =SUM(B5:AF5) -> 1
A6: Aircraft maintenance hangar | B6: ='MIC by location'!B6/'MIC by location'!$AG6 -> 0.020396311 | C6: ='MIC by location'!C6/'MIC by location'!$AG6 -> 0.69031839 | D6: - | E6: - | F6: ='MIC by location'!F6/'MIC by location'!$AG6 -> 0.069435054 | G6: - | H6: ='MIC by location'!H6/'MIC by location'!$AG6 -> 0.047279628 | I6: ='MIC by location'!I6/'MIC by location'!$AG6 -> 0.013003365 | J6: - | K6: - | L6: - | M6: ='MIC by location'!M6/'MIC by location'!$AG6 -> 0.095623836 | N6: ='MIC by location'!N6/'MIC by location'!$AG6 -> 0.026626718 | O6: ='MIC by location'!O6/'MIC by location'!$AG6 -> 0.016891355 | P6: - | Q6: - | R6: - | S6: - | T6: - | U6: - | V6: ='MIC by location'!V6/'MIC by location'!$AG6 -> 0.00060672245 | W6: ='MIC by location'!W6/'MIC by location'!$AG6 -> 9.1273374e-05 | X6: - | Y6: - | Z6: - | AA6: ='MIC by location'!AA6/'MIC by location'!$AG6 -> 0.00055722702 | AB6: ='MIC by location'!AB6/'MIC by location'!$AG6 -> 0.019170124 | AC6: - | AD6: - | AE6: - | AF6: - | AG6: =SUM(B6:AF6) -> 1
A7: Communications | B7: ='MIC by location'!B7/'MIC by location'!$AG7 -> 0.087026325 | C7: ='MIC by location'!C7/'MIC by location'!$AG7 -> 0.30059817 | D7: - | E7: - | F7: - | G7: - | H7: ='MIC by location'!H7/'MIC by location'!$AG7 -> 0.023480459 | I7: - | J7: - | K7: - | L7: - | M7: ='MIC by location'!M7/'MIC by location'!$AG7 -> 0.53550619 | N7: - | O7: - | P7: - | Q7: - | R7: - | S7: - | T7: - | U7: - | V7: - | W7: ='MIC by location'!W7/'MIC by location'!$AG7 -> 0.0021689782 | X7: - | Y7: - | Z7: - | AA7: - | AB7: - | AC7: ='MIC by location'!AC7/'MIC by location'!$AG7 -> 0.051219874 | AD7: - | AE7: - | AF7: - | AG7: =SUM(B7:AF7) -> 1
A8: Family Housing | B8: - | C8: ='MIC by location'!C8/'MIC by location'!$AG8 -> 0.68167005 | D8: - | E8: - | F8: - | G8: - | H8: - | I8: - | J8: - | K8: ='MIC by location'!K8/'MIC by location'!$AG8 -> 0.11278541 | L8: - | M8: - | N8: - | O8: - | P8: ='MIC by location'!P8/'MIC by location'!$AG8 -> 0.18247783 | Q8: - | R8: - | S8: - | T8: - | U8: - | V8: ='MIC by location'!V8/'MIC by location'!$AG8 -> 0.0022670366 | W8: - | X8: - | Y8: - | Z8: - | AA8: - | AB8: - | AC8: - | AD8: ='MIC by location'!AD8/'MIC by location'!$AG8 -> 0.020799676 | AE8: - | AF8: - | AG8: =SUM(B8:AF8) -> 1
A9: Family service center | B9: ='MIC by location'!B9/'MIC by location'!$AG9 -> 0.047981061 | C9: ='MIC by location'!C9/'MIC by location'!$AG9 -> 0.77961211 | D9: - | E9: - | F9: - | G9: - | H9: - | I9: - | J9: - | K9: ='MIC by location'!K9/'MIC by location'!$AG9 -> 0.051247582 | L9: - | M9: - | N9: - | O9: - | P9: ='MIC by location'!P9/'MIC by location'!$AG9 -> 0.051487541 | Q9: - | R9: - | S9: - | T9: - | U9: - | V9: ='MIC by location'!V9/'MIC by location'!$AG9 -> 0.0036470889 | W9: - | X9: ='MIC by location'!X9/'MIC by location'!$AG9 -> 0.0015741559 | Y9: - | Z9: - | AA9: ='MIC by location'!AA9/'MIC by location'!$AG9 -> 0.011369417 | AB9: - | AC9: ='MIC by location'!AC9/'MIC by location'!$AG9 -> 0.053081046 | AD9: - | AE9: - | AF9: - | AG9: =SUM(B9:AF9) -> 1
A10: Industrial utilities & fire protection | B10: ='MIC by location'!B10/'MIC by location'!$AG10 -> 0.24751117 | C10: ='MIC by location'!C10/'MIC by location'!$AG10 -> 0.62176719 | D10: - | E10: - | F10: - | G10: - | H10: - | I10: - | J10: - | K10: ='MIC by location'!K10/'MIC by location'!$AG10 -> 0.044502588 | L10: - | M10: - | N10: - | O10: - | P10: - | Q10: ='MIC by location'!Q10/'MIC by location'!$AG10 -> 0.0071031588 | R10: - | S10: - | T10: - | U10: - | V10: - | W10: - | X10: - | Y10: - | Z10: - | AA10: - | AB10: - | AC10: ='MIC by location'!AC10/'MIC by location'!$AG10 -> 0.07911589 | AD10: - | AE10: - | AF10: - | AG10: =SUM(B10:AF10) -> 1
A11: Lodging | B11: ='MIC by location'!B11/'MIC by location'!$AG11 -> 0.052177385 | C11: ='MIC by location'!C11/'MIC by location'!$AG11 -> 0.55480899 | D11: - | E11: ='MIC by location'!E11/'MIC by location'!$AG11 -> 0.042229253 | F11: - | G11: - | H11: - | I11: - | J11: - | K11: ='MIC by location'!K11/'MIC by location'!$AG11 -> 0.060674471 | L11: - | M11: - | N11: - | O11: - | P11: ='MIC by location'!P11/'MIC by location'!$AG11 -> 0.15965696 | Q11: - | R11: - | S11: - | T11: - | U11: - | V11: ='MIC by location'!V11/'MIC by location'!$AG11 -> 0.0054103834 | W11: - | X11: - | Y11: - | Z11: - | AA11: - | AB11: - | AC11: - | AD11: - | AE11: ='MIC by location'!AE11/'MIC by location'!$AG11 -> 0.12504256 | AF11: - | AG11: =SUM(B11:AF11) -> 1
A12: maintenance shop | B12: ='MIC by location'!B12/'MIC by location'!$AG12 -> 0.052815876 | C12: ='MIC by location'!C12/'MIC by location'!$AG12 -> 0.55059083 | D12: - | E12: - | F12: - | G12: - | H12: ='MIC by location'!H12/'MIC by location'!$AG12 -> 0.053804703 | I12: - | J12: - | K12: - | L12: - | M12: ='MIC by location'!M12/'MIC by location'!$AG12 -> 0.13939874 | N12: ='MIC by location'!N12/'MIC by location'!$AG12 -> 0.11325023 | O12: ='MIC by location'!O12/'MIC by location'!$AG12 -> 0.020725132 | P12: - | Q12: - | R12: ='MIC by location'!R12/'MIC by location'!$AG12 -> 0.041601463 | S12: - | T12: - | U12: - | V12: - | W12: ='MIC by location'!W12/'MIC by location'!$AG12 -> 0.0011633962 | X12: - | Y12: - | Z12: - | AA12: ='MIC by location'!AA12/'MIC by location'!$AG12 -> 0.024583239 | AB12: - | AC12: - | AD12: - | AE12: - | AF12: ='MIC by location'!AF12/'MIC by location'!$AG12 -> 0.0020663932 | AG12: =SUM(B12:AF12) -> 1
A13: office | B13: ='MIC by location'!B13/'MIC by location'!$AG13 -> 0.015361063 | C13: ='MIC by location'!C13/'MIC by location'!$AG13 -> 0.38354309 | D13: - | E13: - | F13: - | G13: ='MIC by location'!G13/'MIC by location'!$AG13 -> 0.48623147 | H13: ='MIC by location'!H13/'MIC by location'!$AG13 -> 0.032914186 | I13: - | J13: - | K13: - | L13: - | M13: - | N13: - | O13: - | P13: ='MIC by location'!P13/'MIC by location'!$AG13 -> 0.059474365 | Q13: - | R13: - | S13: - | T13: - | U13: - | V13: ='MIC by location'!V13/'MIC by location'!$AG13 -> 0.001769389 | W13: - | X13: ='MIC by location'!X13/'MIC by location'!$AG13 -> 0.00051369282 | Y13: - | Z13: - | AA13: ='MIC by location'!AA13/'MIC by location'!$AG13 -> 0.014955302 | AB13: - | AC13: ='MIC by location'!AC13/'MIC by location'!$AG13 -> 0.0052374381 | AD13: - | AE13: - | AF13: - | AG13: =SUM(B13:AF13) -> 1
A14: RDT&E (laboratories) | B14: ='MIC by location'!B14/'MIC by location'!$AG14 -> 0.07775979 | C14: ='MIC by location'!C14/'MIC by location'!$AG14 -> 0.39673422 | D14: - | E14: - | F14: - | G14: - | H14: ='MIC by location'!H14/'MIC by location'!$AG14 -> 0.03793436 | I14: - | J14: - | K14: - | L14: - | M14: ='MIC by location'!M14/'MIC by location'!$AG14 -> 0.18430688 | N14: - | O14: ='MIC by location'!O14/'MIC by location'!$AG14 -> 0.041176026 | P14: - | Q14: - | R14: - | S14: ='MIC by location'!S14/'MIC by location'!$AG14 -> 0.20776945 | T14: - | U14: - | V14: ='MIC by location'!V14/'MIC by location'!$AG14 -> 0.00036916705 | W14: - | X14: - | Y14: - | Z14: - | AA14: - | AB14: - | AC14: ='MIC by location'!AC14/'MIC by location'!$AG14 -> 0.053950107 | AD14: - | AE14: - | AF14: - | AG14: =SUM(B14:AF14) -> 1
A15: Recreation & Culture | B15: ='MIC by location'!B15/'MIC by location'!$AG15 -> 0.045287084 | C15: ='MIC by location'!C15/'MIC by location'!$AG15 -> 0.59056497 | D15: - | E15: - | F15: - | G15: - | H15: ='MIC by location'!H15/'MIC by location'!$AG15 -> 0.078207438 | I15: - | J15: - | K15: ='MIC by location'!K15/'MIC by location'!$AG15 -> 0.016517259 | L15: - | M15: - | N15: - | O15: - | P15: ='MIC by location'!P15/'MIC by location'!$AG15 -> 0.10218983 | Q15: - | R15: - | S15: - | T15: - | U15: - | V15: ='MIC by location'!V15/'MIC by location'!$AG15 -> 0.0019517391 | W15: - | X15: ='MIC by location'!X15/'MIC by location'!$AG15 -> 0.00028894537 | Y15: - | Z15: ='MIC by location'!Z15/'MIC by location'!$AG15 -> 0.030585581 | AA15: - | AB15: - | AC15: ='MIC by location'!AC15/'MIC by location'!$AG15 -> 0.047352026 | AD15: - | AE15: ='MIC by location'!AE15/'MIC by location'!$AG15 -> 0.087055129 | AF15: - | AG15: =SUM(B15:AF15) -> 1
A16: Store (Retail & grocery) | B16: ='MIC by location'!B16/'MIC by location'!$AG16 -> 0.02316213 | C16: ='MIC by location'!C16/'MIC by location'!$AG16 -> 0.7066071 | D16: - | E16: - | F16: - | G16: - | H16: ='MIC by location'!H16/'MIC by location'!$AG16 -> 0.077440968 | I16: - | J16: - | K16: - | L16: ='MIC by location'!L16/'MIC by location'!$AG16 -> 0.071087021 | M16: ='MIC by location'!M16/'MIC by location'!$AG16 -> 0.036039617 | N16: ='MIC by location'!N16/'MIC by location'!$AG16 -> 0.038177886 | O16: ='MIC by location'!O16/'MIC by location'!$AG16 -> 0.00089303272 | P16: ='MIC by location'!P16/'MIC by location'!$AG16 -> 0.016923412 | Q16: - | R16: - | S16: - | T16: - | U16: - | V16: - | W16: - | X16: ='MIC by location'!X16/'MIC by location'!$AG16 -> 0.00025635148 | Y16: ='MIC by location'!Y16/'MIC by location'!$AG16 -> 0.0014107485 | Z16: - | AA16: ='MIC by location'!AA16/'MIC by location'!$AG16 -> 0.028001734 | AB16: - | AC16: - | AD16: - | AE16: - | AF16: - | AG16: =SUM(B16:AF16) -> 1
A17: training & academic instruction | B17: - | C17: ='MIC by location'!C17/'MIC by location'!$AG17 -> 0.44480915 | D17: - | E17: - | F17: - | G17: - | H17: ='MIC by location'!H17/'MIC by location'!$AG17 -> 0.029486511 | I17: - | J17: - | K17: - | L17: - | M17: ='MIC by location'!M17/'MIC by location'!$AG17 -> 0.500458 | N17: - | O17: - | P17: - | Q17: - | R17: - | S17: - | T17: - | U17: - | V17: ='MIC by location'!V17/'MIC by location'!$AG17 -> 0.0038218712 | W17: - | X17: - | Y17: - | Z17: - | AA17: ='MIC by location'!AA17/'MIC by location'!$AG17 -> 0.021424461 | AB17: - | AC17: - | AD17: - | AE17: - | AF17: - | AG17: =SUM(B17:AF17) -> 1
A18: Unaccompanied housing (barracks) | B18: ='MIC by location'!B18/'MIC by location'!$AG18 -> 0.0085443693 | C18: ='MIC by location'!C18/'MIC by location'!$AG18 -> 0.19079214 | D18: - | E18: - | F18: - | G18: ='MIC by location'!G18/'MIC by location'!$AG18 -> 0.37135284 | H18: - | I18: - | J18: - | K18: - | L18: ='MIC by location'!L18/'MIC by location'!$AG18 -> 0.18567642 | M18: ='MIC by location'!M18/'MIC by location'!$AG18 -> 0.22432753 | N18: - | O18: - | P18: - | Q18: - | R18: - | S18: - | T18: - | U18: - | V18: ='MIC by location'!V18/'MIC by location'!$AG18 -> 0.0010988967 | W18: - | X18: - | Y18: - | Z18: - | AA18: - | AB18: - | AC18: ='MIC by location'!AC18/'MIC by location'!$AG18 -> 0.018207808 | AD18: - | AE18: - | AF18: - | AG18: =SUM(B18:AF18) -> 1
A19: warehouse / storage | B19: ='MIC by location'!B19/'MIC by location'!$AG19 -> 0.011622616 | C19: ='MIC by location'!C19/'MIC by location'!$AG19 -> 0.6812612 | D19: - | E19: - | F19: - | G19: - | H19: ='MIC by location'!H19/'MIC by location'!$AG19 -> 0.027649365 | I19: - | J19: - | K19: - | L19: - | M19: - | N19: - | O19: - | P19: - | Q19: - | R19: - | S19: ='MIC by location'!S19/'MIC by location'!$AG19 -> 0.26355825 | T19: - | U19: - | V19: - | W19: - | X19: - | Y19: - | Z19: - | AA19: - | AB19: ='MIC by location'!AB19/'MIC by location'!$AG19 -> 0.015908572 | AC19: - | AD19: - | AE19: - | AF19: - | AG19: =SUM(B19:AF19) -> 1
A20: Public service | B20: ='MIC by location'!B20/'MIC by location'!$AG20 -> 0.061592564 | C20: ='MIC by location'!C20/'MIC by location'!$AG20 -> 0.68507295 | D20: - | E20: - | F20: - | G20: - | H20: ='MIC by location'!H20/'MIC by location'!$AG20 -> 0.060158667 | I20: - | J20: - | K20: ='MIC by location'!K20/'MIC by location'!$AG20 -> 0.039014425 | L20: - | M20: - | N20: - | O20: - | P20: ='MIC by location'!P20/'MIC by location'!$AG20 -> 0.083358527 | Q20: - | R20: - | S20: - | T20: - | U20: - | V20: ='MIC by location'!V20/'MIC by location'!$AG20 -> 0.0022775083 | W20: - | X20: ='MIC by location'!X20/'MIC by location'!$AG20 -> 0.0079900226 | Y20: - | Z20: - | AA20: ='MIC by location'!AA20/'MIC by location'!$AG20 -> 0.030817903 | AB20: - | AC20: ='MIC by location'!AC20/'MIC by location'!$AG20 -> 0.029717435 | AD20: - | AE20: - | AF20: - | AG20: =SUM(B20:AF20) -> 1
A21: Ship operational | B21: ='MIC by location'!B21/'MIC by location'!$AG21 -> 0.052180863 | C21: ='MIC by location'!C21/'MIC by location'!$AG21 -> 0.65351206 | D21: - | E21: - | F21: - | G21: - | H21: ='MIC by location'!H21/'MIC by location'!$AG21 -> 0.046080978 | I21: - | J21: - | K21: - | L21: - | M21: - | N21: ='MIC by location'!N21/'MIC by location'!$AG21 -> 0.18929491 | O21: - | P21: - | Q21: - | R21: - | S21: - | T21: - | U21: - | V21: - | W21: ='MIC by location'!W21/'MIC by location'!$AG21 -> 0.0041771481 | X21: - | Y21: - | Z21: - | AA21: ='MIC by location'!AA21/'MIC by location'!$AG21 -> 0.028924826 | AB21: - | AC21: - | AD21: - | AE21: - | AF21: - | AG21: =SUM(B21:AF21) -> 0.97417078
A22: Security | B22: ='MIC by location'!B22/'MIC by location'!$AG22 -> 0.065620555 | C22: ='MIC by location'!C22/'MIC by location'!$AG22 -> 0.73136321 | D22: - | E22: - | F22: - | G22: - | H22: - | I22: - | J22: - | K22: ='MIC by location'!K22/'MIC by location'!$AG22 -> 0.069034899 | L22: - | M22: - | N22: - | O22: - | P22: ='MIC by location'!P22/'MIC by location'!$AG22 -> 0.066626805 | Q22: - | R22: - | S22: - | T22: ='MIC by location'!T22/'MIC by location'!$AG22 -> 0.036052701 | U22: - | V22: ='MIC by location'!V22/'MIC by location'!$AG22 -> 0.0084016931 | W22: - | X22: - | Y22: - | Z22: - | AA22: - | AB22: - | AC22: - | AD22: ='MIC by location'!AD22/'MIC by location'!$AG22 -> 0.022900142 | AE22: - | AF22: - | AG22: =SUM(B22:AF22) -> 1
A23: Military medical facilities | B23: - | C23: ='MIC by location'!C23/'MIC by location'!$AG23 -> 0.21897313 | D23: - | E23: - | F23: - | G23: ='MIC by location'!G23/'MIC by location'!$AG23 -> 0.28310887 | H23: ='MIC by location'!H23/'MIC by location'!$AG23 -> 0.01254846 | I23: - | J23: - | K23: - | L23: - | M23: - | N23: - | O23: - | P23: - | Q23: - | R23: - | S23: ='MIC by location'!S23/'MIC by location'!$AG23 -> 0.45750662 | T23: - | U23: - | V23: - | W23: - | X23: - | Y23: - | Z23: - | AA23: - | AB23: - | AC23: ='MIC by location'!AC23/'MIC by location'!$AG23 -> 0.027862927 | AD23: - | AE23: - | AF23: - | AG23: =SUM(B23:AF23) -> 1
A24: Fire station | B24: ='MIC by location'!B24/'MIC by location'!$AG24 -> 0.044089208 | C24: ='MIC by location'!C24/'MIC by location'!$AG24 -> 0.73536848 | D24: - | E24: - | F24: - | G24: - | H24: - | I24: - | J24: - | K24: ='MIC by location'!K24/'MIC by location'!$AG24 -> 0.058697665 | L24: - | M24: - | N24: - | O24: - | P24: ='MIC by location'!P24/'MIC by location'!$AG24 -> 0.048208772 | Q24: - | R24: - | S24: - | T24: - | U24: ='MIC by location'!U24/'MIC by location'!$AG24 -> 0.028644507 | V24: ='MIC by location'!V24/'MIC by location'!$AG24 -> 0.0023050165 | W24: - | X24: - | Y24: - | Z24: - | AA24: - | AB24: - | AC24: ='MIC by location'!AC24/'MIC by location'!$AG24 -> 0.082686355 | AD24: - | AE24: - | AF24: - | AG24: =SUM(B24:AF24) -> 1
A25: Dining | B25: ='MIC by location'!B25/'MIC by location'!$AG25 -> 0.013196718 | C25: ='MIC by location'!C25/'MIC by location'!$AG25 -> 0.20987244 | D25: ='MIC by location'!D25/'MIC by location'!$AG25 -> 0.077248612 | E25: - | F25: - | G25: ='MIC by location'!G25/'MIC by location'!$AG25 -> 0.26793983 | H25: ='MIC by location'!H25/'MIC by location'!$AG25 -> 0.00061585009 | I25: - | J25: - | K25: - | L25: ='MIC by location'!L25/'MIC by location'!$AG25 -> 0.28421044 | M25: ='MIC by location'!M25/'MIC by location'!$AG25 -> 0.010660685 | N25: ='MIC by location'!N25/'MIC by location'!$AG25 -> 0.12704844 | O25: - | P25: - | Q25: - | R25: - | S25: - | T25: - | U25: - | V25: - | W25: ='MIC by location'!W25/'MIC by location'!$AG25 -> 0.0010368911 | X25: - | Y25: - | Z25: - | AA25: - | AB25: ='MIC by location'!AB25/'MIC by location'!$AG25 -> 0.0081700972 | AC25: - | AD25: - | AE25: - | AF25: - | AG25: =SUM(B25:AF25) -> 1
A26: armory | B26: ='MIC by location'!B26/'MIC by location'!$AG26 -> 0.082260601 | C26: ='MIC by location'!C26/'MIC by location'!$AG26 -> 0.36593384 | D26: - | E26: - | F26: - | G26: - | H26: ='MIC by location'!H26/'MIC by location'!$AG26 -> 0.02146867 | I26: - | J26: - | K26: - | L26: - | M26: ='MIC by location'!M26/'MIC by location'!$AG26 -> 0.48368395 | N26: - | O26: - | P26: - | Q26: - | R26: - | S26: - | T26: - | U26: - | V26: - | W26: ='MIC by location'!W26/'MIC by location'!$AG26 -> 9.0211245e-05 | X26: - | Y26: - | Z26: - | AA26: - | AB26: - | AC26: ='MIC by location'!AC26/'MIC by location'!$AG26 -> 0.046562735 | AD26: - | AE26: - | AF26: - | AG26: =SUM(B26:AF26) -> 1
A27: Average MICs | B27: =AVERAGE(B4:B26) -> 0.054278957 | C27: =AVERAGE(C4:C26) -> 0.51902434 | D27: =AVERAGE(D4:D26) -> 0.077248612 | E27: =AVERAGE(E4:E26) -> 0.026373166 | F27: =AVERAGE(F4:F26) -> 0.069435054 | G27: =AVERAGE(G4:G26) -> 0.35215825 | H27: =AVERAGE(H4:H26) -> 0.041276485 | I27: =AVERAGE(I4:I26) -> 0.013003365 | ... AF27: =AVERAGE(AF4:AF26) -> 0.0020663932
A30: For image grading: | B30: =B27 -> 0.054278957 | C30: =C27 -> 0.51902434 | E30: =AVERAGE(E27:G27) -> 0.14932216 | H30: =AVERAGE(H27:L27) -> 0.15793244 | M30: =AVERAGE(M27:U27) -> 0.1010796 | V30: =AVERAGE(V27:Z27) -> 0.0076805645 | AA30: =AVERAGE(AA27:AF27) -> 0.034995745

Sheet MIC % by location graph
B1: MIC (lbs/GSF)
A2: Archeytpe | B2: Strip footing | C2: Reinforced slab | D2: Basement | E2: Floor construction | F2: Roof construction | G2: Exterior Walls | H2: Windows | I2: Roof covering
A3: Aircraft traffic control & operations | B3: ='MIC by location'!B4/'MIC by location'!$AG4 -> 0.055164965 | C3: ='MIC by location'!C4/'MIC by location'!$AG4 -> 0.64913159 | D3: - | E3: ='MIC by location'!E4/'MIC by location'!$AG4 -> 0.010517079 | F3: ='MIC by location'!H4/'MIC by location'!$AG4 -> 0.070077038 | G3: 0.19883063 | H3: 0 | I3: 0.019533129 | J3: =SUM(B3:I3) -> 1.0032544
A4: Ammunition & explosives storage magazine | B4: ='MIC by location'!B5/'MIC by location'!$AG5 -> 0.021828479 | C4: ='MIC by location'!C5/'MIC by location'!$AG5 -> 0.11465464 | D4: - | E4: - | F4: ='MIC by location'!J5/'MIC by location'!$AG5 -> 0.49849843 | G4: 0.36501845 | H4: 0 | I4: 0 | J4: =SUM(B4:I4) -> 1
A5: Aircraft maintenance hangar | B5: ='MIC by location'!B6/'MIC by location'!$AG6 -> 0.020396311 | C5: ='MIC by location'!C6/'MIC by location'!$AG6 -> 0.69031839 | D5: - | E5: ='MIC by location'!F6/'MIC by location'!$AG6 -> 0.069435054 | F5: ='MIC by location'!H6/'MIC by location'!$AG6+'MIC by location'!I6/'MIC by location'!$AG6 -> 0.060282993 | G5: 0.14386605 | H5: 0.00069442642 | I5: 0.022703622 | J5: =SUM(B5:I5) -> 1.0076968
A6: Communications | B6: ='MIC by location'!B7/'MIC by location'!$AG7 -> 0.087026325 | C6: ='MIC by location'!C7/'MIC by location'!$AG7 -> 0.30059817 | D6: - | E6: - | F6: ='MIC by location'!H7/'MIC by location'!$AG7 -> 0.023480459 | G6: 0.5354009 | H6: 0.0021685517 | I6: 0.051406422 | J6: =SUM(B6:I6) -> 1.0000808
A7: Family Housing | B7: - | C7: ='MIC by location'!C8/'MIC by location'!$AG8 -> 0.68167005 | D7: - | E7: - | F7: ='MIC by location'!K8/'MIC by location'!$AG8 -> 0.11278541 | G7: 0.17722037 | H7: 0.0022017199 | I7: 0.033441008 | J7: =SUM(B7:I7) -> 1.0073186
A8: Family service center | B8: ='MIC by location'!B9/'MIC by location'!$AG9 -> 0.047981061 | C8: ='MIC by location'!C9/'MIC by location'!$AG9 -> 0.77961211 | D8: - | E8: - | F8: ='MIC by location'!K9/'MIC by location'!$AG9 -> 0.051247582 | G8: 0.05212467 | H8: 0.0052858548 | I8: 0.061454835 | J8: =SUM(B8:I8) -> 0.99770611
A9: Industrial utilities | B9: ='MIC by location'!B10/'MIC by location'!$AG10 -> 0.24751117 | C9: ='MIC by location'!C10/'MIC by location'!$AG10 -> 0.62176719 | D9: - | E9: - | F9: ='MIC by location'!K10/'MIC by location'!$AG10 -> 0.044502588 | G9: 0.0071304074 | H9: 0 | I9: 0.083405962 | J9: =SUM(B9:I9) -> 1.0043173
A10: Lodging | B10: ='MIC by location'!B11/'MIC by location'!$AG11 -> 0.052177385 | C10: ='MIC by location'!C11/'MIC by location'!$AG11 -> 0.55480899 | D10: - | E10: ='MIC by location'!E11/'MIC by location'!$AG11 -> 0.042229253 | F10: ='MIC by location'!K11/'MIC by location'!$AG11 -> 0.060674471 | G10: 0.15649523 | H10: 0.0053032403 | I10: 0.13306069 | J10: =SUM(B10:I10) -> 1.0047493
A11: Maintenance shop | B11: ='MIC by location'!B12/'MIC by location'!$AG12 -> 0.052815876 | C11: ='MIC by location'!C12/'MIC by location'!$AG12 -> 0.55059083 | D11: - | E11: - | F11: ='MIC by location'!H12/'MIC by location'!$AG12 -> 0.053804703 | G11: 0.32925622 | H11: 0.0011353417 | I11: 0.020956803 | J11: =SUM(B11:I11) -> 1.0085598
A12: Office | B12: ='MIC by location'!B13/'MIC by location'!$AG13 -> 0.015361063 | C12: ='MIC by location'!C13/'MIC by location'!$AG13 -> 0.38354309 | D12: - | E12: ='MIC by location'!G13/'MIC by location'!$AG13 -> 0.48623147 | F12: ='MIC by location'!H13/'MIC by location'!$AG13 -> 0.032914186 | G12: 0.058741916 | H12: 0.0022549647 | I12: 0.017094274 | J12: =SUM(B12:I12) -> 0.99614097
A13: RDT&E (laboratories) | B13: ='MIC by location'!B14/'MIC by location'!$AG14 -> 0.07775979 | C13: ='MIC by location'!C14/'MIC by location'!$AG14 -> 0.39673422 | D13: - | E13: - | F13: ='MIC by location'!H14/'MIC by location'!$AG14 -> 0.03793436 | G13: 0.4431108 | H13: 0.00036266547 | I13: 0.053122787 | J13: =SUM(B13:I13) -> 1.0090246
A14: Recreation & culture | B14: ='MIC by location'!B15/'MIC by location'!$AG15 -> 0.045287084 | C14: ='MIC by location'!C15/'MIC by location'!$AG15 -> 0.59056497 | D14: - | E14: - | F14: ='MIC by location'!H15/'MIC by location'!$AG15+'MIC by location'!K15/'MIC by location'!$AG15 -> 0.094724697 | G14: 0.10181282 | H14: 0.032705159 | I14: 0.14361616 | J14: =SUM(B14:I14) -> 1.0087109
A15: Store (retail & grocery) | B15: ='MIC by location'!B16/'MIC by location'!$AG16 -> 0.02316213 | C15: ='MIC by location'!C16/'MIC by location'!$AG16 -> 0.7066071 | D15: - | E15: - | F15: ='MIC by location'!H16/'MIC by location'!$AG16+'MIC by location'!L16/'MIC by location'!$AG16 -> 0.14852799 | G15: 0.092834677 | H15: 0.0016745793 | I15: 0.022206309 | J15: =SUM(B15:I15) -> 0.99501278
A16: Training & academic instruction | B16: - | C16: ='MIC by location'!C17/'MIC by location'!$AG17 -> 0.44480915 | D16: - | E16: - | F16: ='MIC by location'!H17/'MIC by location'!$AG17 -> 0.029486511 | G16: 0.50259779 | H16: 0.0038382122 | I16: 0.016986748 | J16: =SUM(B16:I16) -> 0.99771842
A17: Unaccompanied housing (barracks) | B17: ='MIC by location'!B18/'MIC by location'!$AG18 -> 0.0085443693 | C17: ='MIC by location'!C18/'MIC by location'!$AG18 -> 0.19079214 | D17: - | E17: ='MIC by location'!G18/'MIC by location'!$AG18 -> 0.37135284 | F17: ='MIC by location'!L18/'MIC by location'!$AG18 -> 0.18567642 | G17: 0.21683784 | H17: 0.0010622075 | I17: 0.018483351 | J17: =SUM(B17:I17) -> 0.99274917
A18: Warehouse / storage | B18: ='MIC by location'!B19/'MIC by location'!$AG19 -> 0.011622616 | C18: ='MIC by location'!C19/'MIC by location'!$AG19 -> 0.6812612 | D18: - | E18: - | F18: ='MIC by location'!H19/'MIC by location'!$AG19 -> 0.027649365 | G18: 0.26285797 | H18: 0 | I18: 0.018523309 | J18: =SUM(B18:I18) -> 1.0019145
A19: Public service | B19: ='MIC by location'!B20/'MIC by location'!$AG20 -> 0.061592564 | C19: ='MIC by location'!C20/'MIC by location'!$AG20 -> 0.68507295 | D19: - | E19: - | F19: ='MIC by location'!H20/'MIC by location'!$AG20+'MIC by location'!K20/'MIC by location'!$AG20 -> 0.099173092 | G19: 0.083467608 | H19: 0.010280967 | I19: 0.055612292 | J19: =SUM(B19:I19) -> 0.99519947
A20: Ship operational | B20: ='MIC by location'!B21/'MIC by location'!$AG21 -> 0.052180863 | C20: ='MIC by location'!C21/'MIC by location'!$AG21 -> 0.65351206 | D20: - | E20: - | F20: ='MIC by location'!H21/'MIC by location'!$AG21 -> 0.046080978 | G20: 0.19823112 | H20: 0.0043743425 | I20: 0.023913936 | J20: =SUM(B20:I20) -> 0.9782933
A21: Security | B21: ='MIC by location'!B22/'MIC by location'!$AG22 -> 0.065620555 | C21: ='MIC by location'!C22/'MIC by location'!$AG22 -> 0.73136321 | D21: - | E21: - | F21: ='MIC by location'!K22/'MIC by location'!$AG22 -> 0.069034899 | G21: 0.099172428 | H21: 0.0081147284 | I21: 0.036615469 | J21: =SUM(B21:I21) -> 1.0099213
A22: Military medical facilities | B22: - | C22: ='MIC by location'!C23/'MIC by location'!$AG23 -> 0.21897313 | D22: - | E22: ='MIC by location'!G23/'MIC by location'!$AG23 -> 0.28310887 | F22: ='MIC by location'!H23/'MIC by location'!$AG23 -> 0.01254846 | G22: 0.44470581 | H22: 0 | I22: 0.028442824 | J22: =SUM(B22:I22) -> 0.98777909
A23: Fire station | B23: ='MIC by location'!B24/'MIC by location'!$AG24 -> 0.044089208 | C23: ='MIC by location'!C24/'MIC by location'!$AG24 -> 0.73536848 | D23: - | E23: - | F23: ='MIC by location'!K24/'MIC by location'!$AG24 -> 0.058697665 | G23: 0.077042432 | H23: 0.0023106897 | I23: 0.086849381 | J23: =SUM(B23:I23) -> 1.0043579
A24: Dining | B24: ='MIC by location'!B25/'MIC by location'!$AG25 -> 0.013196718 | C24: ='MIC by location'!C25/'MIC by location'!$AG25 -> 0.20987244 | D24: ='MIC by location'!D25/'MIC by location'!$AG25 -> 0.077248612 | E24: ='MIC by location'!G25/'MIC by location'!$AG25 -> 0.26793983 | F24: ='MIC by location'!H25/'MIC by location'!$AG25+'MIC by location'!L25/'MIC by location'!$AG25 -> 0.28482629 | G24: 0.13133066 | H24: 0.00098886396 | I24: 0.0090964813 | J24: =SUM(B24:I24) -> 0.99449989
A25: Armory | B25: ='MIC by location'!B26/'MIC by location'!$AG26 -> 0.082260601 | C25: ='MIC by location'!C26/'MIC by location'!$AG26 -> 0.36593384 | D25: - | E25: - | F25: ='MIC by location'!H26/'MIC by location'!$AG26 -> 0.02146867 | G25: 0.48255608 | H25: 9.0000888e-05 | I25: 0.048785993 | J25: =SUM(B25:I25) -> 1.0010952
A26: Average MICs | B26: =AVERAGE(B3:B25) -> 0.054278957 | C26: =AVERAGE(C3:C25) -> 0.51902434 | D26: =AVERAGE(D3:D25) -> 0.077248612 | E26: =AVERAGE(E3:E25) -> 0.21868777 | F26: =AVERAGE(F3:F25) -> 0.092352054
A29: For image grading:

Sheet Aircraft traffic control & oper
A1: Archetype/Typology | B1: Asset | C1: Asset description | D1: Assembly | E1: Material Category | F1: Material | G1: Qty | H1: Size | I1: UOM | J1: thickness (ft) | K1: width (ft) | L1: density | M1: UOM | N1: Mass (lbs) | O1: Building Area | P1: Functional Unit | Q1: Mass per Functional Unit (lbs/ft2) | R1: data confidence level | S1: Source of data | T1: assumptions
A2: Aircraft traffic control/operations | B2: FOOTING | C2: STRIP FOOTINGS | D2: concrete | E2: concrete | F2: concrete | G2: 1 | H2: 380 | I2: LF | J2: 0.66666667 | K2: 1.5 | L2: 150 | M2: (lb/ft3) | N2: =L2*K2*J2*H2 -> 57000 | O2: 9443 | P2: ft2 | Q2: =N2/O2 -> 6.0362173 | R2: 4 | S2: UFC 3-220-01 1808.2: | T2: continuous footings shall be 18" wide or 8" wider than the supported wall, whichever is greater
S3: IBC 1809.8 Plain concrete footings | T3: The edge thickness of plain concrete footings supporting walls of other than light-frame construction shall not be less than 8"
D4: reinforcement | E4: steel | F4: carbon steel | L4: 5.25 | M4: (lb/ft3) | N4: =L4*K2*J2*H2 -> 1995 | Q4: =N4/$O$2 -> 0.21126761 | R4: 4 | S4: https://help.oneclicklca.com/en/articles/275888-average-quantities-of-reinforcement-in-concrete | T4: average reinforcement in footings is ~5.25 lbs/ft3
B5: SLAB | C5: PLAIN/REINFORCED | D5: concrete | E5: concrete | F5: concrete | G5: 1 | H5: 8900 | I5: SF | J5: 0.5 | K5: - | L5: 150 | M5: (lb/ft3) | N5: =L5*J5*H5 -> 667500 | Q5: =N5/$O$2 -> 70.687282 | R5: 5 | S5: iNFADS specified 10" heavy duty slab
D6: reinforcement | E6: steel | F6: carbon steel | L6: 6 | M6: (lb/ft3) | N6: =L6*J5*H5 -> 26700 | Q6: =N6/$O$2 -> 2.8274913 | R6: 5 | S6: engineering judgement, https://www.omnicalculator.com/construction/concrete-weight: | T6: slab of concrete = 150 lbs/cubic ft; reinforced conrete = 156 lbs/cubic ft
