Workbook
Name Absc_graph: INDIRECT(#REF!)
Name Absc_graph: INDIRECT(#REF!)
Name Absc_graph: INDIRECT(#REF!)
Name Absc_graph: INDIRECT(#REF!)
Name Absc_graph: INDIRECT(#REF!)
Name Absc_graph: INDIRECT(#REF!)
Name Absc_graph: INDIRECT(#REF!)
Name Absc_graph: INDIRECT(#REF!)
Name Absc_graph: INDIRECT(#REF!)
Name Absc_graph: INDIRECT('[1]33'!$R$57)
Name Companies: #REF!
Name Companies: #REF!
Name Companies: #REF!
Name Companies: #REF!
Name Companies: #REF!
Name Companies: #REF!
Name Companies: #REF!
Name Companies: #REF!
Name Companies: #REF!
Name Companies: [1]MD!$D$2:$D$66
Name Countries: #REF!
Name Countries: #REF!
Name Countries: #REF!
Name Countries: #REF!
Name Countries: #REF!
Name Countries: #REF!
Name Countries: #REF!
Name Countries: #REF!
Name Countries: #REF!
Name Countries: [1]MD!#REF!
Name Indicators: #REF!
Name Indicators: #REF!
Name Indicators: #REF!
Name Indicators: #REF!
Name Indicators: #REF!
Name Indicators: #REF!
Name Indicators: #REF!
Name Indicators: #REF!
Name Indicators: #REF!
Name Indicators: [1]MD!$F$2:$F$3
Name IQ_CH: 110000
Name IQ_CQ: 5000
Name IQ_CY: 10000
Name IQ_DAILY: 500000
Name IQ_FH: 100000
Name IQ_FQ: 500
Name IQ_FY: 1000
Name IQ_LTM: 2000
Name IQ_MONTH: 15000
Name IQ_NTM: 6000
Name IQ_WEEK: 50000
Name IQ_YTD: 3000
Name Net_Generation_by_State__Type_1: #REF!
Name Net_Generation_by_State__Type_1: #REF!
Name Net_Generation_by_State__Type_1: #REF!
Name Net_Generation_by_State__Type_1: #REF!
Name Net_Generation_by_State__Type_1: #REF!
Name Net_Generation_by_State__Type_1: #REF!
Name Net_Generation_by_State__Type_1: #REF!
Name Net_Generation_by_State__Type_1: #REF!

Sheet Cover Sheet
A1: Supplementary Data for
A2: Mapping supplementary cementitious material resource potential for concrete decarbonization in the United States
A3: Josefine A. Olsson, Kelli A. Knight, Nica Campbell, Thomas P. Hendrickson, Sabbie A. Miller
A4: All units are metric
A6: This spreadsheet includes:
A7: 1. Cement demand (kt) | B7: Future cement demand per state (for RMC only).
A8: 2. Concrete demand | B8: Future concrete demand per state (RMC only)
A9: 3. Aggregate demand | B9: Includes natural fine, crushed fine, natural coarse, and crushed coarse aggregates
A10: 4. Fly ash demand | B10: Future baseline fly ash demand
A11: 5. Slag demand | B11: Future baseline slag demand
A12: 6. Concrete waste | B12: Future baseline concrete taken out of service
A13: 7a. Fly ash supply | B13: Lower limit: Fly ash production from coal electricity generation per state
A14: 7b. Fly ash supply | B14: Upper limit: Fly ash production from coal electricity generation per state
A15: 8a. Slag supply | B15: Lower limit: Blast furnace slag production per state
A16: 8b. Slag supply | B16: Upper limit: Blast furnace slag production per state
A17: 9a. Recovered fly ash supply | B17: Availability of recoverable fly ash for: high recovery rate (75%) and high utilization rate (40% cement substitution)
A18: 9b. Recovered fly ash supply | B18: Availability of recoverable fly ash for: high recovery rate (75%) and low utilization rate (20% cement substitution)
A19: 9c. Recovered fly ash supply | B19: Availability of recoverable fly ash for: low recovery rate (50%) and low utilization rate (20% cement substitution)
A20: 10. Natural pozzolans
A22: Supplementary tabs
A23: S1 | B23: Future cement demand per state (for RMC only) broken down by application
A24: S2 | B24: Electricity generation by coal per state
A25: S3 | B25: Coal consumption for electricity generation per state
A26: S4 | B26: Blast furnace capacity
A27: S5 | B27: Pig iron production per state
A28: S6 | B28: Estimated recovered coal ash from landfill
A29: S7 | B29: Estimated recovered coal ash from ponds
A30: S8 | B30: Cement plant capacities in California
A31: S9 | B31: Scenarios for permitting and adoption of natural pozzolans in CA
A32: S10 | B32: Permitted aggregate supply in CA

Sheet S10
A1: CGS
A2: Total CA | B2: Reserves (MMT) | C2: Demand (MMT) | D2: Remaining
A3: 10 or Fewer Years | B3: 142 | C3: 1390 | D3: -1248
A4: 11 to 20 Years | B4: 674 | C4: 2024 | D4: -1350
A5: 21 to 30 Years | B5: 224 | C5: 374 | D5: -150
A6: 31 to 40 Years | B6: 804 | C6: 1160 | D6: -356
A7: 41 to 50 Years | B7: 217 | C7: 234 | D7: -17
A8: More Than 50 Years | B8: 5133 | C8: 2810 | D8: 2323
A11: Near NBVC | B11: Reserves (MMT) | C11: Demand (MMT) | D11: Site name | E11: Remaining
A12: 10 or Fewer Years | B12: 9 | C12: 754 | D12: San Fernando Valley-Saugus Newhall P-C Region | E12: -745
A13: 11 to 20 Years | B13: 48 | C13: 163 | D13: Claremont-Upland P-C Region | E13: -115
A14: 11 to 20 Years | B14: 120 | C14: 537 | D14: Palmdale P-C Region | E14: -417
A15: 11 to 20 Years | B15: 240 | C15: 512 | D15: San Gabriel Valley P-C Region | E15: -272
A16: 11 to 20 Years | B16: 57 | C16: 177 | D16: San Luis Obispo-Santa Barbara P-C Region | E16: -120
A17: 41 to 50 Years | B17: 104 | C17: 106 | D17: Western Ventura-Simi P-C Region | E17: -2
A18: More Than 50 Years
A20: Aggregate Study Area | B20: Permitted Reserves (Million Tons) | C20: 50-Year Demand (Million Tons) | D20: Years of Permitted Reserves Remaining
A21: San Bernardino P-C Region | B21: 133 | C21: 636 | D21: 10 or Fewer Years
A22: San Fernando Valley-Saugus Newhall P-C Region | B22: 9 | C22: 754 | D22: 10 or Fewer Years | E22: Near NBVC
A23: Claremont-Upland P-C Region | B23: 48 | C23: 163 | D23: 11 to 20 Years | E23: Near NBVC
A24: Glenn County | B24: 15 | C24: 57 | D24: 11 to 20 Years
A25: Palmdale P-C Region | B25: 120 | C25: 537 | D25: 11 to 20 Years | E25: Near NBVC
A26: San Gabriel Valley P-C Region | B26: 240 | C26: 512 | D26: 11 to 20 Years | E26: Near NBVC
A27: San Luis Obispo-Santa Barbara P-C Region | B27: 57 | C27: 177 | D27: 11 to 20 Years | E27: Near NBVC
A28: Stanislaus County | B28: 27 | C28: 99 | D28: 11 to 20 Years
A29: Stockton-Lodi P-C Region | B29: 167 | C29: 479 | D29: 11 to 20 Years
A30: Western San Diego County P-C Region | B30: 224 | C30: 374 | D30: 21 to 30 Years
A31: Merced County | B31: 87 | C31: 156 | D31: 31 to 40 Years
A32: Monterey Bay P-C Region | B32: 187 | C32: 283 | D32: 31 to 40 Years
A33: Shasta County | B33: 52 | C33: 70 | D33: 31 to 40 Years
A34: South San Francisco P-C Region | B34: 478 | C34: 651 | D34: 31 to 40 Years
A35: Tehama County | B35: 27 | C35: 28 | D35: 41 to 50 Years
A36: Tulare County | B36: 86 | C36: 100 | D36: 41 to 50 Years
A37: Western Ventura-Simi P-C Region | B37: 104 | C37: 106 | D37: 41 to 50 Years | E37: Near NBVC
A38: Bakersfield P-C Region | B38: 1690 | C38: 207 | D38: More Than 50 Years
A39: Barstow-Victorville P-C Region | B39: 118 | C39: 101 | D39: More Than 50 Years
A40: Fresno P-C Region | B40: 530 | C40: 227 | D40: More Than 50 Years
A41: Greater Sacramento Area | B41: 1480 | C41: 1026 | D41: More Than 50 Years
A42: North San Francisco P-C Region | B42: 279 | C42: 239 | D42: More Than 50 Years
A43: Palm Springs P-C Region | B43: 175 | C43: 174 | D43: More Than 50 Years
...

Sheet 1. Cement demand
A1: Projected cement demand per US state (thousand metric tons)
B3: 2025 | C3: 2026 | D3: 2027 | E3: 2028 | F3: 2029 | G3: 2030 | H3: 2031 | I3: 2032 | J3: 2033 | K3: 2034 | L3: 2035 | M3: 2036 | N3: 2037 | O3: 2038 | P3: 2039 | Q3: 2040 | R3: 2041 | S3: 2042 | T3: 2043 | U3: 2044 | V3: 2045 | W3: 2046 | X3: 2047 | Y3: 2048 | Z3: 2049 | AA3: 2050
A4: USA | B4: =SUM(B5:B54) -> 92473.259 | C4: =SUM(C5:C54) -> 93795.408 | D4: =SUM(D5:D54) -> 95102.691 | E4: =SUM(E5:E54) -> 96417.308 | F4: =SUM(F5:F54) -> 97714.569 | G4: =SUM(G5:G54) -> 99017.207 | H4: =SUM(H5:H54) -> 100284.53 | I4: =SUM(I5:I54) -> 101555.07 | ... AA4: =SUM(AA5:AA54) -> 136220.53
A5: Alabama | B5: ='[3]Inflow Cement results'!CR13 -> 1503.3815 | C5: ='[3]Inflow Cement results'!CS13 -> 1518.4852 | D5: ='[3]Inflow Cement results'!CT13 -> 1532.5721 | E5: ='[3]Inflow Cement results'!CU13 -> 1545.9234 | F5: ='[3]Inflow Cement results'!CV13 -> 1558.0761 | G5: ='[3]Inflow Cement results'!CW13 -> 1569.3196 | H5: ='[3]Inflow Cement results'!CX13 -> 1578.9393 | I5: ='[3]Inflow Cement results'!CY13 -> 1587.4805 | ... AA5: ='[3]Inflow Cement results'!DQ13 -> 1826.2209
A6: Alaska | B6: ='[3]Inflow Cement results'!CR18 -> 403.6755 | C6: ='[3]Inflow Cement results'!CS18 -> 407.71724 | D6: ='[3]Inflow Cement results'!CT18 -> 411.42032 | E6: ='[3]Inflow Cement results'!CU18 -> 414.88512 | F6: ='[3]Inflow Cement results'!CV18 -> 417.94785 | G6: ='[3]Inflow Cement results'!CW18 -> 420.71533 | H6: ='[3]Inflow Cement results'!CX18 -> 422.94084 | I6: ='[3]Inflow Cement results'!CY18 -> 424.82624 | ... AA6: ='[3]Inflow Cement results'!DQ18 -> 501.35277
A7: Arizona | B7: ='[3]Inflow Cement results'!CR23 -> 2766.1272 | C7: ='[3]Inflow Cement results'!CS23 -> 2836.2636 | D7: ='[3]Inflow Cement results'!CT23 -> 2907.4807 | E7: ='[3]Inflow Cement results'!CU23 -> 2980.3573 | F7: ='[3]Inflow Cement results'!CV23 -> 3054.0707 | G7: ='[3]Inflow Cement results'!CW23 -> 3129.1561 | H7: ='[3]Inflow Cement results'!CX23 -> 3204.2355 | I7: ='[3]Inflow Cement results'!CY23 -> 3280.2121 | ... AA7: ='[3]Inflow Cement results'!DQ23 -> 4272.1525
A8: Arkansas | B8: ='[3]Inflow Cement results'!CR28 -> 1021.5074 | C8: ='[3]Inflow Cement results'!CS28 -> 1032.5086 | D8: ='[3]Inflow Cement results'!CT28 -> 1043.2192 | E8: ='[3]Inflow Cement results'!CU28 -> 1053.8556 | F8: ='[3]Inflow Cement results'!CV28 -> 1064.1543 | G8: ='[3]Inflow Cement results'!CW28 -> 1074.3273 | H8: ='[3]Inflow Cement results'!CX28 -> 1083.9408 | I8: ='[3]Inflow Cement results'!CY28 -> 1093.3599 | ... AA8: ='[3]Inflow Cement results'!DQ28 -> 1411.3096
A9: California | B9: ='[3]Inflow Cement results'!CR33 -> 9881.9279 | C9: ='[3]Inflow Cement results'!CS33 -> 9974.2405 | D9: ='[3]Inflow Cement results'!CT33 -> 10063.082 | E9: ='[3]Inflow Cement results'!CU33 -> 10150.599 | F9: ='[3]Inflow Cement results'!CV33 -> 10234.23 | G9: ='[3]Inflow Cement results'!CW33 -> 10316.203 | H9: ='[3]Inflow Cement results'!CX33 -> 10392.369 | I9: ='[3]Inflow Cement results'!CY33 -> 10466.594 | ... AA9: ='[3]Inflow Cement results'!DQ33 -> 13423.151
A10: Colorado | B10: ='[3]Inflow Cement results'!CR38 -> 2000.3335 | C10: ='[3]Inflow Cement results'!CS38 -> 2027.1342 | D10: ='[3]Inflow Cement results'!CT38 -> 2052.682 | E10: ='[3]Inflow Cement results'!CU38 -> 2077.3613 | F10: ='[3]Inflow Cement results'!CV38 -> 2100.5342 | G10: ='[3]Inflow Cement results'!CW38 -> 2122.6052 | H10: ='[3]Inflow Cement results'!CX38 -> 2142.5949 | I10: ='[3]Inflow Cement results'!CY38 -> 2161.2695 | ... AA10: ='[3]Inflow Cement results'!DQ38 -> 2680.2208
A11: Connecticut | B11: ='[3]Inflow Cement results'!CR43 -> 571.6539 | C11: ='[3]Inflow Cement results'!CS43 -> 578.44423 | D11: ='[3]Inflow Cement results'!CT43 -> 584.84183 | E11: ='[3]Inflow Cement results'!CU43 -> 590.9765 | F11: ='[3]Inflow Cement results'!CV43 -> 596.64894 | G11: ='[3]Inflow Cement results'!CW43 -> 601.99167 | H11: ='[3]Inflow Cement results'!CX43 -> 606.69566 | I11: ='[3]Inflow Cement results'!CY43 -> 611.00442 | ... AA11: ='[3]Inflow Cement results'!DQ43 -> 757.22357
A12: Delaware | B12: ='[3]Inflow Cement results'!CR48 -> 212.67944 | C12: ='[3]Inflow Cement results'!CS48 -> 215.40367 | D12: ='[3]Inflow Cement results'!CT48 -> 218.01341 | E12: ='[3]Inflow Cement results'!CU48 -> 220.54881 | F12: ='[3]Inflow Cement results'!CV48 -> 222.93373 | G12: ='[3]Inflow Cement results'!CW48 -> 225.20344 | H12: ='[3]Inflow Cement results'!CX48 -> 227.2375 | I12: ='[3]Inflow Cement results'!CY48 -> 229.10352 | ... AA12: ='[3]Inflow Cement results'!DQ48 -> 263.84203
A13: Florida | B13: ='[3]Inflow Cement results'!CR58 -> 7350.083 | C13: ='[3]Inflow Cement results'!CS58 -> 7590.1717 | D13: ='[3]Inflow Cement results'!CT58 -> 7840.5314 | E13: ='[3]Inflow Cement results'!CU58 -> 8103.4479 | F13: ='[3]Inflow Cement results'!CV58 -> 8377.655 | G13: ='[3]Inflow Cement results'!CW58 -> 8665.4654 | H13: ='[3]Inflow Cement results'!CX58 -> 8964.3054 | I13: ='[3]Inflow Cement results'!CY58 -> 9277.5894 | ... AA13: ='[3]Inflow Cement results'!DQ58 -> 15944.633
A14: Georgia | B14: ='[3]Inflow Cement results'!CR63 -> 3719.6974 | C14: ='[3]Inflow Cement results'!CS63 -> 3756.3353 | D14: ='[3]Inflow Cement results'!CT63 -> 3790.6279 | E14: ='[3]Inflow Cement results'!CU63 -> 3823.3078 | F14: ='[3]Inflow Cement results'!CV63 -> 3853.4073 | G14: ='[3]Inflow Cement results'!CW63 -> 3881.6558 | H14: ='[3]Inflow Cement results'!CX63 -> 3906.4723 | I14: ='[3]Inflow Cement results'!CY63 -> 3929.13 | ... AA14: ='[3]Inflow Cement results'!DQ63 -> 4214.9613
A15: Hawaii | B15: ='[3]Inflow Cement results'!CR68 -> 372.54766 | C15: ='[3]Inflow Cement results'!CS68 -> 375.90703 | D15: ='[3]Inflow Cement results'!CT68 -> 378.9824 | E15: ='[3]Inflow Cement results'!CU68 -> 381.84565 | F15: ='[3]Inflow Cement results'!CV68 -> 384.38763 | G15: ='[3]Inflow Cement results'!CW68 -> 386.68471 | H15: ='[3]Inflow Cement results'!CX68 -> 388.56882 | I15: ='[3]Inflow Cement results'!CY68 -> 390.18156 | ... AA15: ='[3]Inflow Cement results'!DQ68 -> 444.15445
A16: Idaho | B16: ='[3]Inflow Cement results'!CR73 -> 621.60453 | C16: ='[3]Inflow Cement results'!CS73 -> 641.97715 | D16: ='[3]Inflow Cement results'!CT73 -> 663.23492 | E16: ='[3]Inflow Cement results'!CU73 -> 685.57871 | F16: ='[3]Inflow Cement results'!CV73 -> 708.93439 | G16: ='[3]Inflow Cement results'!CW73 -> 733.52399 | H16: ='[3]Inflow Cement results'!CX73 -> 759.19202 | I16: ='[3]Inflow Cement results'!CY73 -> 786.27851 | ... AA16: ='[3]Inflow Cement results'!DQ73 -> 1654.095
A17: Illinois | B17: ='[3]Inflow Cement results'!CR78 -> 3567.7064 | C17: ='[3]Inflow Cement results'!CS78 -> 3602.7466 | D17: ='[3]Inflow Cement results'!CT78 -> 3636.0893 | E17: ='[3]Inflow Cement results'!CU78 -> 3668.4165 | F17: ='[3]Inflow Cement results'!CV78 -> 3698.6933 | G17: ='[3]Inflow Cement results'!CW78 -> 3727.5975 | H17: ='[3]Inflow Cement results'!CX78 -> 3753.498 | I17: ='[3]Inflow Cement results'!CY78 -> 3777.6404 | ... AA17: ='[3]Inflow Cement results'!DQ78 -> 4551.6591
A18: Indiana | B18: ='[3]Inflow Cement results'!CR83 -> 2014.2594 | C18: ='[3]Inflow Cement results'!CS83 -> 2032.693 | D18: ='[3]Inflow Cement results'!CT83 -> 2049.7117 | E18: ='[3]Inflow Cement results'!CU83 -> 2065.7086 | F18: ='[3]Inflow Cement results'!CV83 -> 2080.0555 | G18: ='[3]Inflow Cement results'!CW83 -> 2093.1505 | H18: ='[3]Inflow Cement results'!CX83 -> 2104.014 | I18: ='[3]Inflow Cement results'!CY83 -> 2113.3844 | ... AA18: ='[3]Inflow Cement results'!DQ83 -> 2394.3192
A19: Iowa | B19: ='[3]Inflow Cement results'!CR88 -> 1409.7054 | C19: ='[3]Inflow Cement results'!CS88 -> 1419.0773 | D19: ='[3]Inflow Cement results'!CT88 -> 1427.681 | E19: ='[3]Inflow Cement results'!CU88 -> 1435.8804 | F19: ='[3]Inflow Cement results'!CV88 -> 1443.2436 | G19: ='[3]Inflow Cement results'!CW88 -> 1450.1377 | H19: ='[3]Inflow Cement results'!CX88 -> 1455.8622 | I19: ='[3]Inflow Cement results'!CY88 -> 1461.045 | ... AA19: ='[3]Inflow Cement results'!DQ88 -> 1741.9925
A20: Kansas | B20: ='[3]Inflow Cement results'!CR93 -> 1246.1798 | C20: ='[3]Inflow Cement results'!CS93 -> 1255.4785 | D20: ='[3]Inflow Cement results'!CT93 -> 1263.9286 | E20: ='[3]Inflow Cement results'!CU93 -> 1271.8196 | F20: ='[3]Inflow Cement results'!CV93 -> 1278.7529 | G20: ='[3]Inflow Cement results'!CW93 -> 1285.0208 | H20: ='[3]Inflow Cement results'!CX93 -> 1289.9959 | I20: ='[3]Inflow Cement results'!CY93 -> 1294.201 | ... AA20: ='[3]Inflow Cement results'!DQ93 -> 1470.8365
A21: Kentucky | B21: ='[3]Inflow Cement results'!CR98 -> 1299.5806 | C21: ='[3]Inflow Cement results'!CS98 -> 1312.6483 | D21: ='[3]Inflow Cement results'!CT98 -> 1325.0393 | E21: ='[3]Inflow Cement results'!CU98 -> 1337.0051 | F21: ='[3]Inflow Cement results'!CV98 -> 1348.1672 | G21: ='[3]Inflow Cement results'!CW98 -> 1358.7777 | H21: ='[3]Inflow Cement results'!CX98 -> 1368.2389 | I21: ='[3]Inflow Cement results'!CY98 -> 1377.0103 | ... AA21: ='[3]Inflow Cement results'!DQ98 -> 1640.5699
A22: Louisiana | B22: ='[3]Inflow Cement results'!CR103 -> 1767.7194 | C22: ='[3]Inflow Cement results'!CS103 -> 1780.4983 | D22: ='[3]Inflow Cement results'!CT103 -> 1792.532 | E22: ='[3]Inflow Cement results'!CU103 -> 1804.2069 | F22: ='[3]Inflow Cement results'!CV103 -> 1814.9954 | G22: ='[3]Inflow Cement results'!CW103 -> 1825.264 | H22: ='[3]Inflow Cement results'!CX103 -> 1834.1609 | I22: ='[3]Inflow Cement results'!CY103 -> 1842.3395 | ... AA22: ='[3]Inflow Cement results'!DQ103 -> 2231.515
A23: Maine | B23: ='[3]Inflow Cement results'!CR108 -> 208.47815 | C23: ='[3]Inflow Cement results'!CS108 -> 212.1488 | D23: ='[3]Inflow Cement results'!CT108 -> 215.78048 | E23: ='[3]Inflow Cement results'!CU108 -> 219.40581 | F23: ='[3]Inflow Cement results'!CV108 -> 222.9686 | G23: ='[3]Inflow Cement results'!CW108 -> 226.49864 | H23: ='[3]Inflow Cement results'!CX108 -> 229.90661 | I23: ='[3]Inflow Cement results'!CY108 -> 233.24921 | ... AA23: ='[3]Inflow Cement results'!DQ108 -> 320.4225
A24: Maryland | B24: ='[3]Inflow Cement results'!CR113 -> 1415.3855 | C24: ='[3]Inflow Cement results'!CS113 -> 1437.4523 | D24: ='[3]Inflow Cement results'!CT113 -> 1458.8242 | E24: ='[3]Inflow Cement results'!CU113 -> 1479.7245 | F24: ='[3]Inflow Cement results'!CV113 -> 1499.741 | G24: ='[3]Inflow Cement results'!CW113 -> 1519.1002 | H24: ='[3]Inflow Cement results'!CX113 -> 1537.1671 | I24: ='[3]Inflow Cement results'!CY113 -> 1554.3867 | ... AA24: ='[3]Inflow Cement results'!DQ113 -> 1998.9315
A25: Massachusetts | B25: ='[3]Inflow Cement results'!CR118 -> 1010.8739 | C25: ='[3]Inflow Cement results'!CS118 -> 1025.391 | D25: ='[3]Inflow Cement results'!CT118 -> 1039.5076 | E25: ='[3]Inflow Cement results'!CU118 -> 1053.4778 | F25: ='[3]Inflow Cement results'!CV118 -> 1066.9978 | G25: ='[3]Inflow Cement results'!CW118 -> 1080.3327 | H25: ='[3]Inflow Cement results'!CX118 -> 1092.9913 | I25: ='[3]Inflow Cement results'!CY118 -> 1105.4249 | ... AA25: ='[3]Inflow Cement results'!DQ118 -> 1490.6194
A26: Michigan | B26: ='[3]Inflow Cement results'!CR123 -> 2753.6055 | C26: ='[3]Inflow Cement results'!CS123 -> 2780.6912 | D26: ='[3]Inflow Cement results'!CT123 -> 2806.1404 | E26: ='[3]Inflow Cement results'!CU123 -> 2830.5111 | F26: ='[3]Inflow Cement results'!CV123 -> 2853.011 | G26: ='[3]Inflow Cement results'!CW123 -> 2874.2045 | H26: ='[3]Inflow Cement results'!CX123 -> 2892.8288 | I26: ='[3]Inflow Cement results'!CY123 -> 2909.8809 | ... AA26: ='[3]Inflow Cement results'!DQ123 -> 3308.2579
A27: Minnesota | B27: ='[3]Inflow Cement results'!CR128 -> 1602.0219 | C27: ='[3]Inflow Cement results'!CS128 -> 1618.3883 | D27: ='[3]Inflow Cement results'!CT128 -> 1634.0823 | E27: ='[3]Inflow Cement results'!CU128 -> 1649.4631 | F27: ='[3]Inflow Cement results'!CV128 -> 1664.0539 | G27: ='[3]Inflow Cement results'!CW128 -> 1678.2125 | H27: ='[3]Inflow Cement results'!CX128 -> 1691.1719 | I27: ='[3]Inflow Cement results'!CY128 -> 1703.5572 | ... AA27: ='[3]Inflow Cement results'!DQ128 -> 2087.2437
A28: Mississippi | B28: ='[3]Inflow Cement results'!CR133 -> 866.44659 | C28: ='[3]Inflow Cement results'!CS133 -> 873.71029 | D28: ='[3]Inflow Cement results'!CT133 -> 880.42548 | E28: ='[3]Inflow Cement results'!CU133 -> 886.77516 | F28: ='[3]Inflow Cement results'!CV133 -> 892.49372 | G28: ='[3]Inflow Cement results'!CW133 -> 897.76442 | H28: ='[3]Inflow Cement results'!CX133 -> 902.16847 | I28: ='[3]Inflow Cement results'!CY133 -> 906.03708 | ... AA28: ='[3]Inflow Cement results'!DQ133 -> 1044.5539
A29: Missouri | B29: ='[3]Inflow Cement results'!CR138 -> 1717.383 | C29: ='[3]Inflow Cement results'!CS138 -> 1750.6823 | D29: ='[3]Inflow Cement results'!CT138 -> 1782.215 | E29: ='[3]Inflow Cement results'!CU138 -> 1812.4906 | F29: ='[3]Inflow Cement results'!CV138 -> 1840.9448 | G29: ='[3]Inflow Cement results'!CW138 -> 1868.0751 | H29: ='[3]Inflow Cement results'!CX138 -> 1892.9543 | I29: ='[3]Inflow Cement results'!CY138 -> 1916.4178 | ... AA29: ='[3]Inflow Cement results'!DQ138 -> 2405.9851
A30: Montana | B30: ='[3]Inflow Cement results'!CR143 -> 330.10497 | C30: ='[3]Inflow Cement results'!CS143 -> 336.14505 | D30: ='[3]Inflow Cement results'!CT143 -> 342.52004 | E30: ='[3]Inflow Cement results'!CU143 -> 349.35539 | F30: ='[3]Inflow Cement results'!CV143 -> 356.62478 | G30: ='[3]Inflow Cement results'!CW143 -> 364.46578 | H30: ='[3]Inflow Cement results'!CX143 -> 372.80865 | I30: ='[3]Inflow Cement results'!CY143 -> 381.85457 | ... AA30: ='[3]Inflow Cement results'!DQ143 -> 736.03786
A31: Nebraska | B31: ='[3]Inflow Cement results'!CR148 -> 954.45466 | C31: ='[3]Inflow Cement results'!CS148 -> 960.62931 | D31: ='[3]Inflow Cement results'!CT148 -> 966.2287 | E31: ='[3]Inflow Cement results'!CU148 -> 971.48941 | F31: ='[3]Inflow Cement results'!CV148 -> 976.10672 | G31: ='[3]Inflow Cement results'!CW148 -> 980.32298 | H31: ='[3]Inflow Cement results'!CX148 -> 983.65786 | I31: ='[3]Inflow Cement results'!CY148 -> 986.54167 | ... AA31: ='[3]Inflow Cement results'!DQ148 -> 1177.4845
A32: Nevada | B32: ='[3]Inflow Cement results'!CR153 -> 1314.5079 | C32: ='[3]Inflow Cement results'!CS153 -> 1326.3226 | D32: ='[3]Inflow Cement results'!CT153 -> 1337.045 | E32: ='[3]Inflow Cement results'!CU153 -> 1347.0097 | F32: ='[3]Inflow Cement results'!CV153 -> 1355.7307 | G32: ='[3]Inflow Cement results'!CW153 -> 1363.5599 | H32: ='[3]Inflow Cement results'!CX153 -> 1369.748 | I32: ='[3]Inflow Cement results'!CY153 -> 1374.9327 | ... AA32: ='[3]Inflow Cement results'!DQ153 -> 1577.2761
A33: New Hampshire | B33: ='[3]Inflow Cement results'!CR158 -> 244.32164 | C33: ='[3]Inflow Cement results'!CS158 -> 247.21204 | D33: ='[3]Inflow Cement results'!CT158 -> 249.95776 | E33: ='[3]Inflow Cement results'!CU158 -> 252.60372 | F33: ='[3]Inflow Cement results'!CV158 -> 255.06586 | G33: ='[3]Inflow Cement results'!CW158 -> 257.38542 | H33: ='[3]Inflow Cement results'!CX158 -> 259.43141 | I33: ='[3]Inflow Cement results'!CY158 -> 261.28411 | ... AA33: ='[3]Inflow Cement results'!DQ158 -> 305.84558
A34: New Jersey | B34: ='[3]Inflow Cement results'!CR163 -> 1391.5156 | C34: ='[3]Inflow Cement results'!CS163 -> 1410.1015 | D34: ='[3]Inflow Cement results'!CT163 -> 1428.0525 | E34: ='[3]Inflow Cement results'!CU163 -> 1445.6959 | F34: ='[3]Inflow Cement results'!CV163 -> 1462.5827 | G34: ='[3]Inflow Cement results'!CW163 -> 1479.0505 | H34: ='[3]Inflow Cement results'!CX163 -> 1494.3912 | I34: ='[3]Inflow Cement results'!CY163 -> 1509.2053 | ... AA34: ='[3]Inflow Cement results'!DQ163 -> 1990.6657
A35: New Mexico | B35: ='[3]Inflow Cement results'!CR168 -> 733.28451 | C35: ='[3]Inflow Cement results'!CS168 -> 740.04874 | D35: ='[3]Inflow Cement results'!CT168 -> 746.34449 | E35: ='[3]Inflow Cement results'!CU168 -> 752.31923 | F35: ='[3]Inflow Cement results'!CV168 -> 757.75354 | G35: ='[3]Inflow Cement results'!CW168 -> 762.79403 | H35: ='[3]Inflow Cement results'!CX168 -> 767.09312 | I35: ='[3]Inflow Cement results'!CY168 -> 770.91534 | ... AA35: ='[3]Inflow Cement results'!DQ168 -> 871.71721
A36: New York | B36: ='[3]Inflow Cement results'!CR173 -> 2457.7321 | C36: ='[3]Inflow Cement results'!CS173 -> 2490.7938 | D36: ='[3]Inflow Cement results'!CT173 -> 2523.2358 | E36: ='[3]Inflow Cement results'!CU173 -> 2555.6518 | F36: ='[3]Inflow Cement results'!CV173 -> 2587.3349 | G36: ='[3]Inflow Cement results'!CW173 -> 2618.894 | H36: ='[3]Inflow Cement results'!CX173 -> 2649.186 | I36: ='[3]Inflow Cement results'!CY173 -> 2679.2619 | ... AA36: ='[3]Inflow Cement results'!DQ173 -> 3765.6244
A37: North Carolina | B37: ='[3]Inflow Cement results'!CR178 -> 2782.4329 | C37: ='[3]Inflow Cement results'!CS178 -> 2817.5132 | D37: ='[3]Inflow Cement results'!CT178 -> 2850.935 | E37: ='[3]Inflow Cement results'!CU178 -> 2883.1666 | F37: ='[3]Inflow Cement results'!CV178 -> 2913.3848 | G37: ='[3]Inflow Cement results'!CW178 -> 2942.051 | H37: ='[3]Inflow Cement results'!CX178 -> 2967.8748 | I37: ='[3]Inflow Cement results'!CY178 -> 2991.7332 | ... AA37: ='[3]Inflow Cement results'!DQ178 -> 3539.3686
A38: North Dakota | B38: ='[3]Inflow Cement results'!CR183 -> 322.94577 | C38: ='[3]Inflow Cement results'!CS183 -> 324.67718 | D38: ='[3]Inflow Cement results'!CT183 -> 326.21186 | E38: ='[3]Inflow Cement results'!CU183 -> 327.63161 | F38: ='[3]Inflow Cement results'!CV183 -> 328.81491 | G38: ='[3]Inflow Cement results'!CW183 -> 329.84262 | H38: ='[3]Inflow Cement results'!CX183 -> 330.5246 | I38: ='[3]Inflow Cement results'!CY183 -> 331.00928 | ... AA38: ='[3]Inflow Cement results'!DQ183 -> 411.36937
A39: Ohio | B39: ='[3]Inflow Cement results'!CR188 -> 3554.0395 | C39: ='[3]Inflow Cement results'!CS188 -> 3585.5184 | D39: ='[3]Inflow Cement results'!CT188 -> 3614.7951 | E39: ='[3]Inflow Cement results'!CU188 -> 3642.5698 | F39: ='[3]Inflow Cement results'!CV188 -> 3667.7381 | G39: ='[3]Inflow Cement results'!CW188 -> 3690.9889 | H39: ='[3]Inflow Cement results'!CX188 -> 3710.5886 | I39: ='[3]Inflow Cement results'!CY188 -> 3727.8056 | ... AA39: ='[3]Inflow Cement results'!DQ188 -> 4207.6664
A40: Oklahoma | B40: ='[3]Inflow Cement results'!CR193 -> 1258.0567 | C40: ='[3]Inflow Cement results'!CS193 -> 1270.1331 | D40: ='[3]Inflow Cement results'!CT193 -> 1281.5401 | E40: ='[3]Inflow Cement results'!CU193 -> 1292.5637 | F40: ='[3]Inflow Cement results'!CV193 -> 1302.8119 | G40: ='[3]Inflow Cement results'!CW193 -> 1312.5776 | H40: ='[3]Inflow Cement results'!CX193 -> 1321.2413 | I40: ='[3]Inflow Cement results'!CY193 -> 1329.328 | ... AA40: ='[3]Inflow Cement results'!DQ193 -> 1677.804
A41: Oregon | B41: ='[3]Inflow Cement results'!CR198 -> 948.79443 | C41: ='[3]Inflow Cement results'!CS198 -> 960.28051 | D41: ='[3]Inflow Cement results'!CT198 -> 971.13271 | E41: ='[3]Inflow Cement results'!CU198 -> 981.53911 | F41: ='[3]Inflow Cement results'!CV198 -> 991.1666 | G41: ='[3]Inflow Cement results'!CW198 -> 1000.2023 | H41: ='[3]Inflow Cement results'!CX198 -> 1008.1369 | I41: ='[3]Inflow Cement results'!CY198 -> 1015.3315 | ... AA41: ='[3]Inflow Cement results'!DQ198 -> 1191.3021
...

Sheet 2. Concrete demand
A1: Projected concrete demand per US state (m3) - based on regional concrete mixture designs by NRMCA
B3: 2025 | C3: 2026 | D3: 2027 | E3: 2028 | F3: 2029 | G3: 2030 | H3: 2031 | I3: 2032 | J3: 2033 | K3: 2034 | L3: 2035 | M3: 2036 | N3: 2037 | O3: 2038 | P3: 2039 | Q3: 2040 | R3: 2041 | S3: 2042 | T3: 2043 | U3: 2044 | V3: 2045 | W3: 2046 | X3: 2047 | Y3: 2048 | Z3: 2049 | AA3: 2050
A4: USA | B4: =SUM(B5:B54) -> 3.7468625e+08 | C4: =SUM(C5:C54) -> 3.8007553e+08 | D4: =SUM(D5:D54) -> 3.8540639e+08 | E4: =SUM(E5:E54) -> 3.9076879e+08 | F4: =SUM(F5:F54) -> 3.9606285e+08 | G4: =SUM(G5:G54) -> 4.0138067e+08 | H4: =SUM(H5:H54) -> 4.0655752e+08 | I4: =SUM(I5:I54) -> 4.1174937e+08 | ... AA4: =SUM(AA5:AA54) -> 5.5267833e+08
A5: Alabama | B5: ='[3]State Cement Inflow'!BY2*'[3]States conc cem ratio'!$BS2/'[3]States conc density'!$BS2*1000000 -> 6530442 | C5: ='[3]State Cement Inflow'!BZ2*'[3]States conc cem ratio'!$BS2/'[3]States conc density'!$BS2*1000000 -> 6596050.2 | D5: ='[3]State Cement Inflow'!CA2*'[3]States conc cem ratio'!$BS2/'[3]States conc density'!$BS2*1000000 -> 6657241.2 | E5: ='[3]State Cement Inflow'!CB2*'[3]States conc cem ratio'!$BS2/'[3]States conc density'!$BS2*1000000 -> 6715237.1 | F5: ='[3]State Cement Inflow'!CC2*'[3]States conc cem ratio'!$BS2/'[3]States conc density'!$BS2*1000000 -> 6768026.7 | G5: ='[3]State Cement Inflow'!CD2*'[3]States conc cem ratio'!$BS2/'[3]States conc density'!$BS2*1000000 -> 6816866.3 | H5: ='[3]State Cement Inflow'!CE2*'[3]States conc cem ratio'!$BS2/'[3]States conc density'!$BS2*1000000 -> 6858652.6 | I5: ='[3]State Cement Inflow'!CF2*'[3]States conc cem ratio'!$BS2/'[3]States conc density'!$BS2*1000000 -> 6895754.6 | ... AA5: ='[3]State Cement Inflow'!CX2*'[3]States conc cem ratio'!$BS2/'[3]States conc density'!$BS2*1000000 -> 7932803.6
A6: Alaska | B6: ='[3]State Cement Inflow'!BY3*'[3]States conc cem ratio'!$BS3/'[3]States conc density'!$BS3*1000000 -> 1618882.8 | C6: ='[3]State Cement Inflow'!BZ3*'[3]States conc cem ratio'!$BS3/'[3]States conc density'!$BS3*1000000 -> 1635091.7 | D6: ='[3]State Cement Inflow'!CA3*'[3]States conc cem ratio'!$BS3/'[3]States conc density'!$BS3*1000000 -> 1649942.4 | E6: ='[3]State Cement Inflow'!CB3*'[3]States conc cem ratio'!$BS3/'[3]States conc density'!$BS3*1000000 -> 1663837.5 | F6: ='[3]State Cement Inflow'!CC3*'[3]States conc cem ratio'!$BS3/'[3]States conc density'!$BS3*1000000 -> 1676120.1 | G6: ='[3]State Cement Inflow'!CD3*'[3]States conc cem ratio'!$BS3/'[3]States conc density'!$BS3*1000000 -> 1687218.7 | H6: ='[3]State Cement Inflow'!CE3*'[3]States conc cem ratio'!$BS3/'[3]States conc density'!$BS3*1000000 -> 1696143.8 | I6: ='[3]State Cement Inflow'!CF3*'[3]States conc cem ratio'!$BS3/'[3]States conc density'!$BS3*1000000 -> 1703704.9 | ... AA6: ='[3]State Cement Inflow'!CX3*'[3]States conc cem ratio'!$BS3/'[3]States conc density'!$BS3*1000000 -> 2010603.6
A7: Arizona | B7: ='[3]State Cement Inflow'!BY4*'[3]States conc cem ratio'!$BS4/'[3]States conc density'!$BS4*1000000 -> 10502600 | C7: ='[3]State Cement Inflow'!BZ4*'[3]States conc cem ratio'!$BS4/'[3]States conc density'!$BS4*1000000 -> 10768898 | D7: ='[3]State Cement Inflow'!CA4*'[3]States conc cem ratio'!$BS4/'[3]States conc density'!$BS4*1000000 -> 11039299 | E7: ='[3]State Cement Inflow'!CB4*'[3]States conc cem ratio'!$BS4/'[3]States conc density'!$BS4*1000000 -> 11316002 | F7: ='[3]State Cement Inflow'!CC4*'[3]States conc cem ratio'!$BS4/'[3]States conc density'!$BS4*1000000 -> 11595881 | G7: ='[3]State Cement Inflow'!CD4*'[3]States conc cem ratio'!$BS4/'[3]States conc density'!$BS4*1000000 -> 11880970 | H7: ='[3]State Cement Inflow'!CE4*'[3]States conc cem ratio'!$BS4/'[3]States conc density'!$BS4*1000000 -> 12166036 | I7: ='[3]State Cement Inflow'!CF4*'[3]States conc cem ratio'!$BS4/'[3]States conc density'!$BS4*1000000 -> 12454509 | ... AA7: ='[3]State Cement Inflow'!CX4*'[3]States conc cem ratio'!$BS4/'[3]States conc density'!$BS4*1000000 -> 16220768
A8: Arkansas | B8: ='[3]State Cement Inflow'!BY5*'[3]States conc cem ratio'!$BS5/'[3]States conc density'!$BS5*1000000 -> 4151428.1 | C8: ='[3]State Cement Inflow'!BZ5*'[3]States conc cem ratio'!$BS5/'[3]States conc density'!$BS5*1000000 -> 4196137.3 | D8: ='[3]State Cement Inflow'!CA5*'[3]States conc cem ratio'!$BS5/'[3]States conc density'!$BS5*1000000 -> 4239665.5 | E8: ='[3]State Cement Inflow'!CB5*'[3]States conc cem ratio'!$BS5/'[3]States conc density'!$BS5*1000000 -> 4282892.2 | F8: ='[3]State Cement Inflow'!CC5*'[3]States conc cem ratio'!$BS5/'[3]States conc density'!$BS5*1000000 -> 4324746.2 | G8: ='[3]State Cement Inflow'!CD5*'[3]States conc cem ratio'!$BS5/'[3]States conc density'!$BS5*1000000 -> 4366089.4 | H8: ='[3]State Cement Inflow'!CE5*'[3]States conc cem ratio'!$BS5/'[3]States conc density'!$BS5*1000000 -> 4405159.2 | I8: ='[3]State Cement Inflow'!CF5*'[3]States conc cem ratio'!$BS5/'[3]States conc density'!$BS5*1000000 -> 4443438.6 | ... AA8: ='[3]State Cement Inflow'!CX5*'[3]States conc cem ratio'!$BS5/'[3]States conc density'!$BS5*1000000 -> 5735592.8
A9: California | B9: ='[3]State Cement Inflow'!BY6*'[3]States conc cem ratio'!$BS6/'[3]States conc density'!$BS6*1000000 -> 37520304 | C9: ='[3]State Cement Inflow'!BZ6*'[3]States conc cem ratio'!$BS6/'[3]States conc density'!$BS6*1000000 -> 37870802 | D9: ='[3]State Cement Inflow'!CA6*'[3]States conc cem ratio'!$BS6/'[3]States conc density'!$BS6*1000000 -> 38208120 | E9: ='[3]State Cement Inflow'!CB6*'[3]States conc cem ratio'!$BS6/'[3]States conc density'!$BS6*1000000 -> 38540412 | F9: ='[3]State Cement Inflow'!CC6*'[3]States conc cem ratio'!$BS6/'[3]States conc density'!$BS6*1000000 -> 38857947 | G9: ='[3]State Cement Inflow'!CD6*'[3]States conc cem ratio'!$BS6/'[3]States conc density'!$BS6*1000000 -> 39169186 | H9: ='[3]State Cement Inflow'!CE6*'[3]States conc cem ratio'!$BS6/'[3]States conc density'!$BS6*1000000 -> 39458376 | I9: ='[3]State Cement Inflow'!CF6*'[3]States conc cem ratio'!$BS6/'[3]States conc density'!$BS6*1000000 -> 39740199 | ... AA9: ='[3]State Cement Inflow'!CX6*'[3]States conc cem ratio'!$BS6/'[3]States conc density'!$BS6*1000000 -> 50965834
A10: Colorado | B10: ='[3]State Cement Inflow'!BY7*'[3]States conc cem ratio'!$BS7/'[3]States conc density'!$BS7*1000000 -> 7848998.8 | C10: ='[3]State Cement Inflow'!BZ7*'[3]States conc cem ratio'!$BS7/'[3]States conc density'!$BS7*1000000 -> 7954160.4 | D10: ='[3]State Cement Inflow'!CA7*'[3]States conc cem ratio'!$BS7/'[3]States conc density'!$BS7*1000000 -> 8054406.1 | E10: ='[3]State Cement Inflow'!CB7*'[3]States conc cem ratio'!$BS7/'[3]States conc density'!$BS7*1000000 -> 8151244 | F10: ='[3]State Cement Inflow'!CC7*'[3]States conc cem ratio'!$BS7/'[3]States conc density'!$BS7*1000000 -> 8242170.7 | G10: ='[3]State Cement Inflow'!CD7*'[3]States conc cem ratio'!$BS7/'[3]States conc density'!$BS7*1000000 -> 8328773.9 | H10: ='[3]State Cement Inflow'!CE7*'[3]States conc cem ratio'!$BS7/'[3]States conc density'!$BS7*1000000 -> 8407210.3 | I10: ='[3]State Cement Inflow'!CF7*'[3]States conc cem ratio'!$BS7/'[3]States conc density'!$BS7*1000000 -> 8480486.6 | ... AA10: ='[3]State Cement Inflow'!CX7*'[3]States conc cem ratio'!$BS7/'[3]States conc density'!$BS7*1000000 -> 10516771
A11: Connecticut | B11: ='[3]State Cement Inflow'!BY8*'[3]States conc cem ratio'!$BS8/'[3]States conc density'!$BS8*1000000 -> 2287773.4 | C11: ='[3]State Cement Inflow'!BZ8*'[3]States conc cem ratio'!$BS8/'[3]States conc density'!$BS8*1000000 -> 2314948.5 | D11: ='[3]State Cement Inflow'!CA8*'[3]States conc cem ratio'!$BS8/'[3]States conc density'!$BS8*1000000 -> 2340551.8 | E11: ='[3]State Cement Inflow'!CB8*'[3]States conc cem ratio'!$BS8/'[3]States conc density'!$BS8*1000000 -> 2365102.9 | F11: ='[3]State Cement Inflow'!CC8*'[3]States conc cem ratio'!$BS8/'[3]States conc density'!$BS8*1000000 -> 2387804.2 | G11: ='[3]State Cement Inflow'!CD8*'[3]States conc cem ratio'!$BS8/'[3]States conc density'!$BS8*1000000 -> 2409185.9 | H11: ='[3]State Cement Inflow'!CE8*'[3]States conc cem ratio'!$BS8/'[3]States conc density'!$BS8*1000000 -> 2428011.4 | I11: ='[3]State Cement Inflow'!CF8*'[3]States conc cem ratio'!$BS8/'[3]States conc density'!$BS8*1000000 -> 2445255.2 | ... AA11: ='[3]State Cement Inflow'!CX8*'[3]States conc cem ratio'!$BS8/'[3]States conc density'!$BS8*1000000 -> 3030427.9
A12: Delaware | B12: ='[3]State Cement Inflow'!BY9*'[3]States conc cem ratio'!$BS9/'[3]States conc density'!$BS9*1000000 -> 851148.51 | C12: ='[3]State Cement Inflow'!BZ9*'[3]States conc cem ratio'!$BS9/'[3]States conc density'!$BS9*1000000 -> 862050.95 | D12: ='[3]State Cement Inflow'!CA9*'[3]States conc cem ratio'!$BS9/'[3]States conc density'!$BS9*1000000 -> 872495.21 | E12: ='[3]State Cement Inflow'!CB9*'[3]States conc cem ratio'!$BS9/'[3]States conc density'!$BS9*1000000 -> 882641.94 | F12: ='[3]State Cement Inflow'!CC9*'[3]States conc cem ratio'!$BS9/'[3]States conc density'!$BS9*1000000 -> 892186.45 | G12: ='[3]State Cement Inflow'!CD9*'[3]States conc cem ratio'!$BS9/'[3]States conc density'!$BS9*1000000 -> 901269.87 | H12: ='[3]State Cement Inflow'!CE9*'[3]States conc cem ratio'!$BS9/'[3]States conc density'!$BS9*1000000 -> 909410.25 | I12: ='[3]State Cement Inflow'!CF9*'[3]States conc cem ratio'!$BS9/'[3]States conc density'!$BS9*1000000 -> 916878.1 | ... AA12: ='[3]State Cement Inflow'!CX9*'[3]States conc cem ratio'!$BS9/'[3]States conc density'!$BS9*1000000 -> 1055902.5
A13: Florida | B13: ='[3]State Cement Inflow'!BY10*'[3]States conc cem ratio'!$BS11/'[3]States conc density'!$BS11*1000000 -> 31721138 | C13: ='[3]State Cement Inflow'!BZ10*'[3]States conc cem ratio'!$BS11/'[3]States conc density'!$BS11*1000000 -> 32757301 | D13: ='[3]State Cement Inflow'!CA10*'[3]States conc cem ratio'!$BS11/'[3]States conc density'!$BS11*1000000 -> 33837792 | E13: ='[3]State Cement Inflow'!CB10*'[3]States conc cem ratio'!$BS11/'[3]States conc density'!$BS11*1000000 -> 34972474 | F13: ='[3]State Cement Inflow'!CC10*'[3]States conc cem ratio'!$BS11/'[3]States conc density'!$BS11*1000000 -> 36155884 | G13: ='[3]State Cement Inflow'!CD10*'[3]States conc cem ratio'!$BS11/'[3]States conc density'!$BS11*1000000 -> 37398002 | H13: ='[3]State Cement Inflow'!CE10*'[3]States conc cem ratio'!$BS11/'[3]States conc density'!$BS11*1000000 -> 38687722 | I13: ='[3]State Cement Inflow'!CF10*'[3]States conc cem ratio'!$BS11/'[3]States conc density'!$BS11*1000000 -> 40039778 | ... AA13: ='[3]State Cement Inflow'!CX10*'[3]States conc cem ratio'!$BS11/'[3]States conc density'!$BS11*1000000 -> 68813086
A14: Georgia | B14: ='[3]State Cement Inflow'!BY11*'[3]States conc cem ratio'!$BS12/'[3]States conc density'!$BS12*1000000 -> 16157754 | C14: ='[3]State Cement Inflow'!BZ11*'[3]States conc cem ratio'!$BS12/'[3]States conc density'!$BS12*1000000 -> 16316903 | D14: ='[3]State Cement Inflow'!CA11*'[3]States conc cem ratio'!$BS12/'[3]States conc density'!$BS12*1000000 -> 16465864 | E14: ='[3]State Cement Inflow'!CB11*'[3]States conc cem ratio'!$BS12/'[3]States conc density'!$BS12*1000000 -> 16607821 | F14: ='[3]State Cement Inflow'!CC11*'[3]States conc cem ratio'!$BS12/'[3]States conc density'!$BS12*1000000 -> 16738568 | G14: ='[3]State Cement Inflow'!CD11*'[3]States conc cem ratio'!$BS12/'[3]States conc density'!$BS12*1000000 -> 16861275 | H14: ='[3]State Cement Inflow'!CE11*'[3]States conc cem ratio'!$BS12/'[3]States conc density'!$BS12*1000000 -> 16969074 | I14: ='[3]State Cement Inflow'!CF11*'[3]States conc cem ratio'!$BS12/'[3]States conc density'!$BS12*1000000 -> 17067495 | ... AA14: ='[3]State Cement Inflow'!CX11*'[3]States conc cem ratio'!$BS12/'[3]States conc density'!$BS12*1000000 -> 18309099
A15: Hawaii | B15: ='[3]State Cement Inflow'!BY12*'[3]States conc cem ratio'!$BS13/'[3]States conc density'!$BS13*1000000 -> 1494049.1 | C15: ='[3]State Cement Inflow'!BZ12*'[3]States conc cem ratio'!$BS13/'[3]States conc density'!$BS13*1000000 -> 1507521.4 | D15: ='[3]State Cement Inflow'!CA12*'[3]States conc cem ratio'!$BS13/'[3]States conc density'!$BS13*1000000 -> 1519854.7 | E15: ='[3]State Cement Inflow'!CB12*'[3]States conc cem ratio'!$BS13/'[3]States conc density'!$BS13*1000000 -> 1531337.4 | F15: ='[3]State Cement Inflow'!CC12*'[3]States conc cem ratio'!$BS13/'[3]States conc density'!$BS13*1000000 -> 1541531.6 | G15: ='[3]State Cement Inflow'!CD12*'[3]States conc cem ratio'!$BS13/'[3]States conc density'!$BS13*1000000 -> 1550743.7 | H15: ='[3]State Cement Inflow'!CE12*'[3]States conc cem ratio'!$BS13/'[3]States conc density'!$BS13*1000000 -> 1558299.7 | I15: ='[3]State Cement Inflow'!CF12*'[3]States conc cem ratio'!$BS13/'[3]States conc density'!$BS13*1000000 -> 1564767.3 | ... AA15: ='[3]State Cement Inflow'!CX12*'[3]States conc cem ratio'!$BS13/'[3]States conc density'!$BS13*1000000 -> 1781217.9
A16: Idaho | B16: ='[3]State Cement Inflow'!BY13*'[3]States conc cem ratio'!$BS14/'[3]States conc density'!$BS14*1000000 -> 2377371.9 | C16: ='[3]State Cement Inflow'!BZ13*'[3]States conc cem ratio'!$BS14/'[3]States conc density'!$BS14*1000000 -> 2455288.4 | D16: ='[3]State Cement Inflow'!CA13*'[3]States conc cem ratio'!$BS14/'[3]States conc density'!$BS14*1000000 -> 2536590.3 | E16: ='[3]State Cement Inflow'!CB13*'[3]States conc cem ratio'!$BS14/'[3]States conc density'!$BS14*1000000 -> 2622045.8 | F16: ='[3]State Cement Inflow'!CC13*'[3]States conc cem ratio'!$BS14/'[3]States conc density'!$BS14*1000000 -> 2711371.3 | G16: ='[3]State Cement Inflow'!CD13*'[3]States conc cem ratio'!$BS14/'[3]States conc density'!$BS14*1000000 -> 2805416 | H16: ='[3]State Cement Inflow'!CE13*'[3]States conc cem ratio'!$BS14/'[3]States conc density'!$BS14*1000000 -> 2903585.2 | I16: ='[3]State Cement Inflow'!CF13*'[3]States conc cem ratio'!$BS14/'[3]States conc density'!$BS14*1000000 -> 3007179.5 | ... AA16: ='[3]State Cement Inflow'!CX13*'[3]States conc cem ratio'!$BS14/'[3]States conc density'!$BS14*1000000 -> 6326207.1
A17: Illinois | B17: ='[3]State Cement Inflow'!BY14*'[3]States conc cem ratio'!$BS15/'[3]States conc density'!$BS15*1000000 -> 14540723 | C17: ='[3]State Cement Inflow'!BZ14*'[3]States conc cem ratio'!$BS15/'[3]States conc density'!$BS15*1000000 -> 14683535 | D17: ='[3]State Cement Inflow'!CA14*'[3]States conc cem ratio'!$BS15/'[3]States conc density'!$BS15*1000000 -> 14819428 | E17: ='[3]State Cement Inflow'!CB14*'[3]States conc cem ratio'!$BS15/'[3]States conc density'!$BS15*1000000 -> 14951182 | F17: ='[3]State Cement Inflow'!CC14*'[3]States conc cem ratio'!$BS15/'[3]States conc density'!$BS15*1000000 -> 15074580 | G17: ='[3]State Cement Inflow'!CD14*'[3]States conc cem ratio'!$BS15/'[3]States conc density'!$BS15*1000000 -> 15192383 | H17: ='[3]State Cement Inflow'!CE14*'[3]States conc cem ratio'!$BS15/'[3]States conc density'!$BS15*1000000 -> 15297944 | I17: ='[3]State Cement Inflow'!CF14*'[3]States conc cem ratio'!$BS15/'[3]States conc density'!$BS15*1000000 -> 15396341 | ... AA17: ='[3]State Cement Inflow'!CX14*'[3]States conc cem ratio'!$BS15/'[3]States conc density'!$BS15*1000000 -> 18550970
A18: Indiana | B18: ='[3]State Cement Inflow'!BY15*'[3]States conc cem ratio'!$BS16/'[3]States conc density'!$BS16*1000000 -> 8209416.4 | C18: ='[3]State Cement Inflow'!BZ15*'[3]States conc cem ratio'!$BS16/'[3]States conc density'!$BS16*1000000 -> 8284545.7 | D18: ='[3]State Cement Inflow'!CA15*'[3]States conc cem ratio'!$BS16/'[3]States conc density'!$BS16*1000000 -> 8353907.8 | E18: ='[3]State Cement Inflow'!CB15*'[3]States conc cem ratio'!$BS16/'[3]States conc density'!$BS16*1000000 -> 8419105.4 | F18: ='[3]State Cement Inflow'!CC15*'[3]States conc cem ratio'!$BS16/'[3]States conc density'!$BS16*1000000 -> 8477578.3 | G18: ='[3]State Cement Inflow'!CD15*'[3]States conc cem ratio'!$BS16/'[3]States conc density'!$BS16*1000000 -> 8530948.9 | H18: ='[3]State Cement Inflow'!CE15*'[3]States conc cem ratio'!$BS16/'[3]States conc density'!$BS16*1000000 -> 8575225 | I18: ='[3]State Cement Inflow'!CF15*'[3]States conc cem ratio'!$BS16/'[3]States conc density'!$BS16*1000000 -> 8613415.4 | ... AA18: ='[3]State Cement Inflow'!CX15*'[3]States conc cem ratio'!$BS16/'[3]States conc density'!$BS16*1000000 -> 9758407.3
A19: Iowa | B19: ='[3]State Cement Inflow'!BY16*'[3]States conc cem ratio'!$BS17/'[3]States conc density'!$BS17*1000000 -> 5623651.3 | C19: ='[3]State Cement Inflow'!BZ16*'[3]States conc cem ratio'!$BS17/'[3]States conc density'!$BS17*1000000 -> 5661037.8 | D19: ='[3]State Cement Inflow'!CA16*'[3]States conc cem ratio'!$BS17/'[3]States conc density'!$BS17*1000000 -> 5695359.9 | E19: ='[3]State Cement Inflow'!CB16*'[3]States conc cem ratio'!$BS17/'[3]States conc density'!$BS17*1000000 -> 5728069.3 | F19: ='[3]State Cement Inflow'!CC16*'[3]States conc cem ratio'!$BS17/'[3]States conc density'!$BS17*1000000 -> 5757443.2 | G19: ='[3]State Cement Inflow'!CD16*'[3]States conc cem ratio'!$BS17/'[3]States conc density'!$BS17*1000000 -> 5784945.1 | H19: ='[3]State Cement Inflow'!CE16*'[3]States conc cem ratio'!$BS17/'[3]States conc density'!$BS17*1000000 -> 5807781.8 | I19: ='[3]State Cement Inflow'!CF16*'[3]States conc cem ratio'!$BS17/'[3]States conc density'!$BS17*1000000 -> 5828457.2 | ... AA19: ='[3]State Cement Inflow'!CX16*'[3]States conc cem ratio'!$BS17/'[3]States conc density'!$BS17*1000000 -> 6949223.6
A20: Kansas | B20: ='[3]State Cement Inflow'!BY17*'[3]States conc cem ratio'!$BS18/'[3]States conc density'!$BS18*1000000 -> 5041910.8 | C20: ='[3]State Cement Inflow'!BZ17*'[3]States conc cem ratio'!$BS18/'[3]States conc density'!$BS18*1000000 -> 5079532.6 | D20: ='[3]State Cement Inflow'!CA17*'[3]States conc cem ratio'!$BS18/'[3]States conc density'!$BS18*1000000 -> 5113720.8 | E20: ='[3]State Cement Inflow'!CB17*'[3]States conc cem ratio'!$BS18/'[3]States conc density'!$BS18*1000000 -> 5145646.8 | F20: ='[3]State Cement Inflow'!CC17*'[3]States conc cem ratio'!$BS18/'[3]States conc density'!$BS18*1000000 -> 5173698.4 | G20: ='[3]State Cement Inflow'!CD17*'[3]States conc cem ratio'!$BS18/'[3]States conc density'!$BS18*1000000 -> 5199057.4 | H20: ='[3]State Cement Inflow'!CE17*'[3]States conc cem ratio'!$BS18/'[3]States conc density'!$BS18*1000000 -> 5219186.2 | I20: ='[3]State Cement Inflow'!CF17*'[3]States conc cem ratio'!$BS18/'[3]States conc density'!$BS18*1000000 -> 5236199.5 | ... AA20: ='[3]State Cement Inflow'!CX17*'[3]States conc cem ratio'!$BS18/'[3]States conc density'!$BS18*1000000 -> 5950848
A21: Kentucky | B21: ='[3]State Cement Inflow'!BY18*'[3]States conc cem ratio'!$BS19/'[3]States conc density'!$BS19*1000000 -> 5608668.2 | C21: ='[3]State Cement Inflow'!BZ18*'[3]States conc cem ratio'!$BS19/'[3]States conc density'!$BS19*1000000 -> 5665065.2 | D21: ='[3]State Cement Inflow'!CA18*'[3]States conc cem ratio'!$BS19/'[3]States conc density'!$BS19*1000000 -> 5718541.5 | E21: ='[3]State Cement Inflow'!CB18*'[3]States conc cem ratio'!$BS19/'[3]States conc density'!$BS19*1000000 -> 5770182.8 | F21: ='[3]State Cement Inflow'!CC18*'[3]States conc cem ratio'!$BS19/'[3]States conc density'!$BS19*1000000 -> 5818355.8 | G21: ='[3]State Cement Inflow'!CD18*'[3]States conc cem ratio'!$BS19/'[3]States conc density'!$BS19*1000000 -> 5864148 | H21: ='[3]State Cement Inflow'!CE18*'[3]States conc cem ratio'!$BS19/'[3]States conc density'!$BS19*1000000 -> 5904980.4 | I21: ='[3]State Cement Inflow'!CF18*'[3]States conc cem ratio'!$BS19/'[3]States conc density'!$BS19*1000000 -> 5942835.4 | ... AA21: ='[3]State Cement Inflow'!CX18*'[3]States conc cem ratio'!$BS19/'[3]States conc density'!$BS19*1000000 -> 7080293.5
A22: Louisiana | B22: ='[3]State Cement Inflow'!BY19*'[3]States conc cem ratio'!$BS20/'[3]States conc density'!$BS20*1000000 -> 7152004.6 | C22: ='[3]State Cement Inflow'!BZ19*'[3]States conc cem ratio'!$BS20/'[3]States conc density'!$BS20*1000000 -> 7203706.9 | D22: ='[3]State Cement Inflow'!CA19*'[3]States conc cem ratio'!$BS20/'[3]States conc density'!$BS20*1000000 -> 7252393.8 | E22: ='[3]State Cement Inflow'!CB19*'[3]States conc cem ratio'!$BS20/'[3]States conc density'!$BS20*1000000 -> 7299629.3 | F22: ='[3]State Cement Inflow'!CC19*'[3]States conc cem ratio'!$BS20/'[3]States conc density'!$BS20*1000000 -> 7343278.6 | G22: ='[3]State Cement Inflow'!CD19*'[3]States conc cem ratio'!$BS20/'[3]States conc density'!$BS20*1000000 -> 7384824 | H22: ='[3]State Cement Inflow'!CE19*'[3]States conc cem ratio'!$BS20/'[3]States conc density'!$BS20*1000000 -> 7420820.2 | I22: ='[3]State Cement Inflow'!CF19*'[3]States conc cem ratio'!$BS20/'[3]States conc density'!$BS20*1000000 -> 7453909.6 | ... AA22: ='[3]State Cement Inflow'!CX19*'[3]States conc cem ratio'!$BS20/'[3]States conc density'!$BS20*1000000 -> 9028472.4
A23: Maine | B23: ='[3]State Cement Inflow'!BY20*'[3]States conc cem ratio'!$BS21/'[3]States conc density'!$BS21*1000000 -> 834334.86 | C23: ='[3]State Cement Inflow'!BZ20*'[3]States conc cem ratio'!$BS21/'[3]States conc density'!$BS21*1000000 -> 849024.88 | D23: ='[3]State Cement Inflow'!CA20*'[3]States conc cem ratio'!$BS21/'[3]States conc density'!$BS21*1000000 -> 863558.97 | E23: ='[3]State Cement Inflow'!CB20*'[3]States conc cem ratio'!$BS21/'[3]States conc density'!$BS21*1000000 -> 878067.63 | F23: ='[3]State Cement Inflow'!CC20*'[3]States conc cem ratio'!$BS21/'[3]States conc density'!$BS21*1000000 -> 892325.97 | G23: ='[3]State Cement Inflow'!CD20*'[3]States conc cem ratio'!$BS21/'[3]States conc density'!$BS21*1000000 -> 906453.29 | H23: ='[3]State Cement Inflow'!CE20*'[3]States conc cem ratio'!$BS21/'[3]States conc density'!$BS21*1000000 -> 920092.09 | I23: ='[3]State Cement Inflow'!CF20*'[3]States conc cem ratio'!$BS21/'[3]States conc density'!$BS21*1000000 -> 933469.26 | ... AA23: ='[3]State Cement Inflow'!CX20*'[3]States conc cem ratio'!$BS21/'[3]States conc density'!$BS21*1000000 -> 1282339
A24: Maryland | B24: ='[3]State Cement Inflow'!BY21*'[3]States conc cem ratio'!$BS22/'[3]States conc density'!$BS22*1000000 -> 5664408.8 | C24: ='[3]State Cement Inflow'!BZ21*'[3]States conc cem ratio'!$BS22/'[3]States conc density'!$BS22*1000000 -> 5752720.4 | D24: ='[3]State Cement Inflow'!CA21*'[3]States conc cem ratio'!$BS22/'[3]States conc density'!$BS22*1000000 -> 5838251.5 | E24: ='[3]State Cement Inflow'!CB21*'[3]States conc cem ratio'!$BS22/'[3]States conc density'!$BS22*1000000 -> 5921894.8 | F24: ='[3]State Cement Inflow'!CC21*'[3]States conc cem ratio'!$BS22/'[3]States conc density'!$BS22*1000000 -> 6002001.3 | G24: ='[3]State Cement Inflow'!CD21*'[3]States conc cem ratio'!$BS22/'[3]States conc density'!$BS22*1000000 -> 6079477.4 | H24: ='[3]State Cement Inflow'!CE21*'[3]States conc cem ratio'!$BS22/'[3]States conc density'!$BS22*1000000 -> 6151781.8 | I24: ='[3]State Cement Inflow'!CF21*'[3]States conc cem ratio'!$BS22/'[3]States conc density'!$BS22*1000000 -> 6220695.1 | ... AA24: ='[3]State Cement Inflow'!CX21*'[3]States conc cem ratio'!$BS22/'[3]States conc density'!$BS22*1000000 -> 7999774.5
... A54: Wyoming | B54: ='[3]State Cement Inflow'!BY51*'[3]States conc cem ratio'!$BS52/'[3]States conc density'!$BS52*1000000 -> 891643.13 | C54: ='[3]State Cement Inflow'!BZ51*'[3]States conc cem ratio'!$BS52/'[3]States conc density'!$BS52*1000000 -> 896567.68 | D54: ='[3]State Cement Inflow'!CA51*'[3]States conc cem ratio'!$BS52/'[3]States conc density'!$BS52*1000000 -> 901102.75 | E54: ='[3]State Cement Inflow'!CB51*'[3]States conc cem ratio'!$BS52/'[3]States conc density'!$BS52*1000000 -> 905510.18 | F54: ='[3]State Cement Inflow'!CC51*'[3]States conc cem ratio'!$BS52/'[3]States conc density'!$BS52*1000000 -> 909547.44 | G54: ='[3]State Cement Inflow'!CD51*'[3]States conc cem ratio'!$BS52/'[3]States conc density'!$BS52*1000000 -> 913511.14 | H54: ='[3]State Cement Inflow'!CE51*'[3]States conc cem ratio'!$BS52/'[3]States conc density'!$BS52*1000000 -> 917023.54 | I54: ='[3]State Cement Inflow'!CF51*'[3]States conc cem ratio'!$BS52/'[3]States conc density'!$BS52*1000000 -> 920596.29 | ... AA54: ='[3]State Cement Inflow'!CX51*'[3]States conc cem ratio'!$BS52/'[3]States conc density'!$BS52*1000000 -> 1271314.1

Sheet 3. Aggregate demand
A1: Projected aggregate demand per US state (thousand metric tons)
A3: Natural fine aggs | B3: 2025 | C3: 2026 | D3: 2027 | E3: 2028 | F3: 2029 | G3: 2030 | H3: 2031 | I3: 2032 | J3: 2033 | K3: 2034 | L3: 2035 | M3: 2036 | N3: 2037 | O3: 2038 | P3: 2039 | Q3: 2040 | R3: 2041 | S3: 2042 | T3: 2043 | U3: 2044 | V3: 2045 | W3: 2046 | X3: 2047 | Y3: 2048 | Z3: 2049 | AA3: 2050
A4: USA | B4: =SUM(B5:B54) -> 294860.88 | C4: =SUM(C5:C54) -> 299093.64 | D4: =SUM(D5:D54) -> 303276.05 | E4: =SUM(E5:E54) -> 307477.61 | F4: =SUM(F5:F54) -> 311619.22 | G4: =SUM(G5:G54) -> 315771.87 | H4: =SUM(H5:H54) -> 319805.55 | I4: =SUM(I5:I54) -> 323840.97 | ... AA4: =SUM(AA5:AA54) -> 431701.83
A5: Alabama | B5: ='[4]Inflow Natural Fine agg'!AK$13 -> 5605.8898 | C5: ='[4]Inflow Natural Fine agg'!AL$13 -> 5662.2094 | D5: ='[4]Inflow Natural Fine agg'!AM$13 -> 5714.7373 | E5: ='[4]Inflow Natural Fine agg'!AN$13 -> 5764.5224 | F5: ='[4]Inflow Natural Fine agg'!AO$13 -> 5809.8383 | G5: ='[4]Inflow Natural Fine agg'!AP$13 -> 5851.7633 | H5: ='[4]Inflow Natural Fine agg'!AQ$13 -> 5887.6338 | I5: ='[4]Inflow Natural Fine agg'!AR$13 -> 5919.483 | ... AA5: ='[4]Inflow Natural Fine agg'!BJ$13 -> 6809.711
A6: Alaska | B6: ='[4]Inflow Natural Fine agg'!AK$18 -> 1252.3442 | C6: ='[4]Inflow Natural Fine agg'!AL$18 -> 1264.8831 | D6: ='[4]Inflow Natural Fine agg'!AM$18 -> 1276.3714 | E6: ='[4]Inflow Natural Fine agg'!AN$18 -> 1287.1204 | F6: ='[4]Inflow Natural Fine agg'!AO$18 -> 1296.6221 | G6: ='[4]Inflow Natural Fine agg'!AP$18 -> 1305.2078 | H6: ='[4]Inflow Natural Fine agg'!AQ$18 -> 1312.1121 | I6: ='[4]Inflow Natural Fine agg'!AR$18 -> 1317.9613 | ... AA6: ='[4]Inflow Natural Fine agg'!BJ$18 -> 1555.3736
A7: Arizona | B7: ='[4]Inflow Natural Fine agg'!AK$23 -> 8315.915 | C7: ='[4]Inflow Natural Fine agg'!AL$23 -> 8526.7685 | D7: ='[4]Inflow Natural Fine agg'!AM$23 -> 8740.8713 | E7: ='[4]Inflow Natural Fine agg'!AN$23 -> 8959.9631 | F7: ='[4]Inflow Natural Fine agg'!AO$23 -> 9181.5705 | G7: ='[4]Inflow Natural Fine agg'!AP$23 -> 9407.3027 | H7: ='[4]Inflow Natural Fine agg'!AQ$23 -> 9633.0167 | I7: ='[4]Inflow Natural Fine agg'!AR$23 -> 9861.4282 | ... AA7: ='[4]Inflow Natural Fine agg'!BJ$23 -> 12843.537
A8: Arkansas | B8: ='[4]Inflow Natural Fine agg'!AK$28 -> 2593.0566 | C8: ='[4]Inflow Natural Fine agg'!AL$28 -> 2620.9827 | D8: ='[4]Inflow Natural Fine agg'!AM$28 -> 2648.1712 | E8: ='[4]Inflow Natural Fine agg'!AN$28 -> 2675.1714 | F8: ='[4]Inflow Natural Fine agg'!AO$28 -> 2701.3142 | G8: ='[4]Inflow Natural Fine agg'!AP$28 -> 2727.1378 | H8: ='[4]Inflow Natural Fine agg'!AQ$28 -> 2751.5415 | I8: ='[4]Inflow Natural Fine agg'!AR$28 -> 2775.4515 | ... AA8: ='[4]Inflow Natural Fine agg'!BJ$28 -> 3582.5543
A9: California | B9: ='[4]Inflow Natural Fine agg'!AK$33 -> 29708.421 | C9: ='[4]Inflow Natural Fine agg'!AL$33 -> 29985.944 | D9: ='[4]Inflow Natural Fine agg'!AM$33 -> 30253.031 | E9: ='[4]Inflow Natural Fine agg'!AN$33 -> 30516.138 | F9: ='[4]Inflow Natural Fine agg'!AO$33 -> 30767.561 | G9: ='[4]Inflow Natural Fine agg'!AP$33 -> 31013.999 | H9: ='[4]Inflow Natural Fine agg'!AQ$33 -> 31242.978 | I9: ='[4]Inflow Natural Fine agg'!AR$33 -> 31466.125 | ... AA9: ='[4]Inflow Natural Fine agg'!BJ$33 -> 40354.536
A10: Colorado | B10: ='[4]Inflow Natural Fine agg'!AK$38 -> 6484.0108 | C10: ='[4]Inflow Natural Fine agg'!AL$38 -> 6570.8841 | D10: ='[4]Inflow Natural Fine agg'!AM$38 -> 6653.6965 | E10: ='[4]Inflow Natural Fine agg'!AN$38 -> 6733.6937 | F10: ='[4]Inflow Natural Fine agg'!AO$38 -> 6808.8077 | G10: ='[4]Inflow Natural Fine agg'!AP$38 -> 6880.3501 | H10: ='[4]Inflow Natural Fine agg'!AQ$38 -> 6945.1459 | I10: ='[4]Inflow Natural Fine agg'!AR$38 -> 7005.6791 | ... AA10: ='[4]Inflow Natural Fine agg'!BJ$38 -> 8687.8413
A11: Connecticut | B11: ='[4]Inflow Natural Fine agg'!AK$43 -> 1713.755 | C11: ='[4]Inflow Natural Fine agg'!AL$43 -> 1734.1116 | D11: ='[4]Inflow Natural Fine agg'!AM$43 -> 1753.2909 | E11: ='[4]Inflow Natural Fine agg'!AN$43 -> 1771.682 | F11: ='[4]Inflow Natural Fine agg'!AO$43 -> 1788.6873 | G11: ='[4]Inflow Natural Fine agg'!AP$43 -> 1804.7042 | H11: ='[4]Inflow Natural Fine agg'!AQ$43 -> 1818.8063 | I11: ='[4]Inflow Natural Fine agg'!AR$43 -> 1831.7235 | ... AA11: ='[4]Inflow Natural Fine agg'!BJ$43 -> 2270.0722
A12: Delaware | B12: ='[4]Inflow Natural Fine agg'!AK$48 -> 637.58936 | C12: ='[4]Inflow Natural Fine agg'!AL$48 -> 645.75631 | D12: ='[4]Inflow Natural Fine agg'!AM$48 -> 653.58002 | E12: ='[4]Inflow Natural Fine agg'!AN$48 -> 661.18087 | F12: ='[4]Inflow Natural Fine agg'!AO$48 -> 668.33059 | G12: ='[4]Inflow Natural Fine agg'!AP$48 -> 675.13492 | H12: ='[4]Inflow Natural Fine agg'!AQ$48 -> 681.23282 | I12: ='[4]Inflow Natural Fine agg'!AR$48 -> 686.82694 | ... AA12: ='[4]Inflow Natural Fine agg'!BJ$48 -> 790.96912
A13: Florida | B13: ='[4]Inflow Natural Fine agg'!AK$58 -> 27407.385 | C13: ='[4]Inflow Natural Fine agg'!AL$58 -> 28302.641 | D13: ='[4]Inflow Natural Fine agg'!AM$58 -> 29236.196 | E13: ='[4]Inflow Natural Fine agg'!AN$58 -> 30216.573 | F13: ='[4]Inflow Natural Fine agg'!AO$58 -> 31239.052 | G13: ='[4]Inflow Natural Fine agg'!AP$58 -> 32312.254 | H13: ='[4]Inflow Natural Fine agg'!AQ$58 -> 33426.585 | I13: ='[4]Inflow Natural Fine agg'!AR$58 -> 34594.775 | ... AA13: ='[4]Inflow Natural Fine agg'!BJ$58 -> 59455.206
A14: Georgia | B14: ='[4]Inflow Natural Fine agg'!AK$63 -> 13870.208 | C14: ='[4]Inflow Natural Fine agg'!AL$63 -> 14006.825 | D14: ='[4]Inflow Natural Fine agg'!AM$63 -> 14134.697 | E14: ='[4]Inflow Natural Fine agg'!AN$63 -> 14256.556 | F14: ='[4]Inflow Natural Fine agg'!AO$63 -> 14368.793 | G14: ='[4]Inflow Natural Fine agg'!AP$63 -> 14474.127 | H14: ='[4]Inflow Natural Fine agg'!AQ$63 -> 14566.665 | I14: ='[4]Inflow Natural Fine agg'!AR$63 -> 14651.152 | ... AA14: ='[4]Inflow Natural Fine agg'!BJ$63 -> 15716.975
A15: Hawaii | B15: ='[4]Inflow Natural Fine agg'!AK$68 -> 1155.7746 | C15: ='[4]Inflow Natural Fine agg'!AL$68 -> 1166.1966 | D15: ='[4]Inflow Natural Fine agg'!AM$68 -> 1175.7375 | E15: ='[4]Inflow Natural Fine agg'!AN$68 -> 1184.6203 | F15: ='[4]Inflow Natural Fine agg'!AO$68 -> 1192.5064 | G15: ='[4]Inflow Natural Fine agg'!AP$68 -> 1199.6328 | H15: ='[4]Inflow Natural Fine agg'!AQ$68 -> 1205.4779 | I15: ='[4]Inflow Natural Fine agg'!AR$68 -> 1210.4812 | ... AA15: ='[4]Inflow Natural Fine agg'!BJ$68 -> 1377.9242
A16: Idaho | B16: ='[4]Inflow Natural Fine agg'!AK$73 -> 1937.2872 | C16: ='[4]Inflow Natural Fine agg'!AL$73 -> 2000.7804 | D16: ='[4]Inflow Natural Fine agg'!AM$73 -> 2067.0322 | E16: ='[4]Inflow Natural Fine agg'!AN$73 -> 2136.6686 | F16: ='[4]Inflow Natural Fine agg'!AO$73 -> 2209.4587 | G16: ='[4]Inflow Natural Fine agg'!AP$73 -> 2286.0945 | H16: ='[4]Inflow Natural Fine agg'!AQ$73 -> 2366.0912 | I16: ='[4]Inflow Natural Fine agg'!AR$73 -> 2450.5087 | ... AA16: ='[4]Inflow Natural Fine agg'!BJ$73 -> 5155.1382
A17: Illinois | B17: ='[4]Inflow Natural Fine agg'!AK$78 -> 12904.361 | C17: ='[4]Inflow Natural Fine agg'!AL$78 -> 13031.101 | D17: ='[4]Inflow Natural Fine agg'!AM$78 -> 13151.701 | E17: ='[4]Inflow Natural Fine agg'!AN$78 -> 13268.628 | F17: ='[4]Inflow Natural Fine agg'!AO$78 -> 13378.139 | G17: ='[4]Inflow Natural Fine agg'!AP$78 -> 13482.685 | H17: ='[4]Inflow Natural Fine agg'!AQ$78 -> 13576.367 | I17: ='[4]Inflow Natural Fine agg'!AR$78 -> 13663.69 | ... AA17: ='[4]Inflow Natural Fine agg'!BJ$78 -> 16463.308
A18: Indiana | B18: ='[4]Inflow Natural Fine agg'!AK$83 -> 7285.5571 | C18: ='[4]Inflow Natural Fine agg'!AL$83 -> 7352.2317 | D18: ='[4]Inflow Natural Fine agg'!AM$83 -> 7413.788 | E18: ='[4]Inflow Natural Fine agg'!AN$83 -> 7471.6485 | F18: ='[4]Inflow Natural Fine agg'!AO$83 -> 7523.5411 | G18: ='[4]Inflow Natural Fine agg'!AP$83 -> 7570.9056 | H18: ='[4]Inflow Natural Fine agg'!AQ$83 -> 7610.199 | I18: ='[4]Inflow Natural Fine agg'!AR$83 -> 7644.0916 | ... AA18: ='[4]Inflow Natural Fine agg'!BJ$83 -> 8660.23
A19: Iowa | B19: ='[4]Inflow Natural Fine agg'!AK$88 -> 4123.2263 | C19: ='[4]Inflow Natural Fine agg'!AL$88 -> 4150.6378 | D19: ='[4]Inflow Natural Fine agg'!AM$88 -> 4175.8026 | E19: ='[4]Inflow Natural Fine agg'!AN$88 -> 4199.7849 | F19: ='[4]Inflow Natural Fine agg'!AO$88 -> 4221.3217 | G19: ='[4]Inflow Natural Fine agg'!AP$88 -> 4241.4859 | H19: ='[4]Inflow Natural Fine agg'!AQ$88 -> 4258.2296 | I19: ='[4]Inflow Natural Fine agg'!AR$88 -> 4273.3887 | ... AA19: ='[4]Inflow Natural Fine agg'!BJ$88 -> 5095.1277
A20: Kansas | B20: ='[4]Inflow Natural Fine agg'!AK$93 -> 3163.3787 | C20: ='[4]Inflow Natural Fine agg'!AL$93 -> 3186.9833 | D20: ='[4]Inflow Natural Fine agg'!AM$93 -> 3208.4335 | E20: ='[4]Inflow Natural Fine agg'!AN$93 -> 3228.4644 | F20: ='[4]Inflow Natural Fine agg'!AO$93 -> 3246.0644 | G20: ='[4]Inflow Natural Fine agg'!AP$93 -> 3261.9751 | H20: ='[4]Inflow Natural Fine agg'!AQ$93 -> 3274.6042 | I20: ='[4]Inflow Natural Fine agg'!AR$93 -> 3285.2786 | ... AA20: ='[4]Inflow Natural Fine agg'!BJ$93 -> 3733.661
A21: Kentucky | B21: ='[4]Inflow Natural Fine agg'!AK$98 -> 4845.9463 | C21: ='[4]Inflow Natural Fine agg'!AL$98 -> 4894.6739 | D21: ='[4]Inflow Natural Fine agg'!AM$98 -> 4940.878 | E21: ='[4]Inflow Natural Fine agg'!AN$98 -> 4985.4966 | F21: ='[4]Inflow Natural Fine agg'!AO$98 -> 5027.1186 | G21: ='[4]Inflow Natural Fine agg'!AP$98 -> 5066.6835 | H21: ='[4]Inflow Natural Fine agg'!AQ$98 -> 5101.9631 | I21: ='[4]Inflow Natural Fine agg'!AR$98 -> 5134.6702 | ... AA21: ='[4]Inflow Natural Fine agg'!BJ$98 -> 6117.4456
