Workbook
Name Absc_graph: INDIRECT(#REF!)
Name Absc_graph: INDIRECT(#REF!)
Name Absc_graph: INDIRECT(#REF!)
Name Absc_graph: INDIRECT(#REF!)
Name Absc_graph: INDIRECT(#REF!)
Name Absc_graph: INDIRECT(#REF!)
Name Absc_graph: INDIRECT(#REF!)
Name Absc_graph: INDIRECT(#REF!)
Name Absc_graph: INDIRECT('[1]33'!$R$57)
Name Companies: [1]MD!$D$2:$D$66
Name Countries: [1]MD!#REF!
Name Indicators: [1]MD!$F$2:$F$3
Name IQ_CH: 110000
Name IQ_CQ: 5000
Name IQ_CY: 10000
Name IQ_DAILY: 500000
Name IQ_FH: 100000
Name IQ_FQ: 500
Name IQ_FWD_CY: 10001
Name IQ_FWD_CY1: 10002
Name IQ_FWD_CY2: 10003
Name IQ_FWD_FY: 1001
Name IQ_FWD_FY1: 1002
Name IQ_FWD_FY2: 1003
Name IQ_FWD_Q: 501
Name IQ_FWD_Q1: 502
Name IQ_FWD_Q2: 503
Name IQ_FY: 1000
Name IQ_LATESTK: 1000
Name IQ_LATESTQ: 500
Name IQ_LTM: 2000
Name IQ_LTMMONTH: 120000
Name IQ_MONTH: 15000
Name IQ_NTM: 6000
Name IQ_TODAY: 0
Name IQ_WEEK: 50000
Name IQ_YTD: 3000
Name IQ_YTDMONTH: 130000
Name Ord_graph: INDIRECT(#REF!)
Name Ord_graph: INDIRECT(#REF!)
Name Ord_graph: INDIRECT(#REF!)
Name Ord_graph: INDIRECT(#REF!)
Name Ord_graph: INDIRECT(#REF!)
Name Ord_graph: INDIRECT(#REF!)
Name Ord_graph: INDIRECT(#REF!)
Name Ord_graph: INDIRECT(#REF!)
Name Ord_graph: INDIRECT('[1]33'!$R$56)
Name Region: [1]MD!$A$2:$A$71
Name Type: [2]MD!$D$2:$D$57
Name Net_Generation_by_State__Type_1: #REF!
Name Indicators: #REF!
Name Companies: #REF!
Name Net_Generation_by_State__Type_1: #REF!
Name Countries: #REF!
Name Region: #REF!
Name Region: #REF!
Name Net_Generation_by_State__Type_1: #REF!
Name Region: #REF!
Name Companies: #REF!
Name Indicators: #REF!

Sheet Cover Sheet
A1: Supplementary Data for
A2: Chapter 5: Mapping supplementary cementitious material resource potential for concrete decarbonization in the United States
A5: This spreadsheet includes:
A6: SD1 | B6: Cement stock per capita per state
A7: SD2 | B7: Future cement demand per state (for RMC only)
A8: SD3.1 | B8: Electricity generation by coal per state
A9: SD3.2 | B9: Coal consumption for electricity generation per state
A10: SD3.3 | B10: Fly ash production from coal electricity generation per state
A11: SD3.4 | B11: Bottom ash production from coal electricity generation per state
A12: SD4.1 | B12: Blast furnace capacity
A13: SD4.2 | B13: Pig iron production per state
A14: SD4.3 | B14: Blast furnace slag production per state
A15: SD5 | B15: Silica fume production per state
A16: SD6.1 | B16: Agricultural yield distribution between states
A17: SD6.2 | B17: Agricultural ash and byproduct ratios
... A21: SD7.1 | B21: Bauxite residue production per state
A22: SD8.1 | B22: Estimated recovered coal ash from landfill | C22: Alt material
A23: SD8.2 | B23: Estimated recovered coal ash from ponds | C23: Alt material
A24: SD9 | B24: GHG emission factors per state (40% SCMs in 2050)
A25: SD10 | B25: NOx emission factors per state (40% SCMs in 2050)
A26: SD11 | B26: Pb emission factors per state (40% SCMs in 2050)
A27: SD12 | B27: CO emission factors per state (40% SCMs in 2050)
A28: SD13 | B28: VOC emission factors per state (40% SCMs in 2050)
A29: SD14 | B29: PM5 emission factors per state (40% SCMs in 2050)
A30: SD15 | B30: PM10 emission factors per state (40% SCMs in 2050)
A31: SD16 | B31: SOx emission factors per state (40% SCMs in 2050)

Sheet SD1
A1: Cement stock per capita per state and application in the US between 1950 and 2050.
A2: 1950-2024: Historical, 2025-2050: Projected
A3: thousand metric tons / capita
A5: State | B5: Application | C5: 1950 | D5: 1951 | E5: 1952 | F5: 1953 | G5: 1954 | H5: 1955 | I5: 1956 | J5: 1957 | K5: 1958 | L5: 1959 | M5: 1960 | N5: 1961 | O5: 1962 | P5: 1963 | Q5: 1964 | R5: 1965 | S5: 1966 | T5: 1967 | U5: 1968 | V5: 1969 | W5: 1970 | X5: 1971 | Y5: 1972 | Z5: 1973 | AA5: 1974 | AB5: 1975 | AC5: 1976 | AD5: 1977 | AE5: 1978 | AF5: 1979 | AG5: 1980 | AH5: 1981 | AI5: 1982 | AJ5: 1983 | AK5: 1984 | AL5: 1985 | AM5: 1986 | AN5: 1987 | AO5: 1988 | AP5: 1989 | AQ5: 1990 | AR5: 1991 | AS5: 1992 | AT5: 1993 | AU5: 1994 | AV5: 1995 | AW5: 1996 | AX5: 1997 | AY5: 1998 | AZ5: 1999 | BA5: 2000 | BB5: 2001 | BC5: 2002 | BD5: 2003 | BE5: 2004 | BF5: 2005 | BG5: 2006 | BH5: 2007 | BI5: 2008 | BJ5: 2009 | BK5: 2010 | BL5: 2011 | BM5: 2012 | BN5: 2013 | BO5: 2014 | BP5: 2015 | BQ5: 2016 | BR5: 2017 | BS5: 2018 | BT5: 2019 | BU5: 2020 | BV5: 2021 | BW5: 2022 | BX5: 2023 | BY5: 2024 | BZ5: 2025 | CA5: 2026 | CB5: 2027 | CC5: 2028 | CD5: 2029 | CE5: 2030 | CF5: 2031 | CG5: 2032 | CH5: 2033 | CI5: 2034 | CJ5: 2035 | CK5: 2036 | CL5: 2037 | CM5: 2038 | CN5: 2039 | CO5: 2040 | CP5: 2041 | CQ5: 2042 | CR5: 2043 | CS5: 2044 | CT5: 2045 | CU5: 2046 | CV5: 2047 | CW5: 2048 | CX5: 2049 | CY5: 2050 | DA5: Growth pattern assumption
A6: Alabama | B6: Residential | C6: 0.88814149 | D6: 0.96588936 | E6: 1.045802 | F6: 1.127976 | G6: 1.2145532 | H6: 1.3089638 | I6: 1.4052612 | J6: 1.4935684 | K6: 1.58619 | L6: 1.6876079 | M6: 1.7796685 | N6: 1.8745415 | O6: 1.9723398 | P6: 2.0775786 | Q6: 2.1862236 | R6: 2.2963111 | S6: 2.406853 | T6: 2.514401 | U6: 2.6274913 | V6: 2.7391983 | W6: 2.8433943 | X6: 2.9328097 | Y6: 3.0266505 | Z6: 3.1268509 | AA6: 3.2127228 | AB6: 3.2779749 | AC6: 3.3479632 | AD6: 3.4257497 | AE6: 3.5109572 | AF6: 3.5936084 | AG6: 3.6606455 | AH6: 3.7486472 | AI6: 3.8258477 | AJ6: 3.9119541 | AK6: 4.013079 | AL6: 4.1173092 | AM6: 4.2266284 | AN6: 4.3369665 | AO6: 4.4456862 | AP6: 4.5511399 | AQ6: 4.6533018 | AR6: 4.7104962 | AS6: 4.7725229 | AT6: 4.8379784 | AU6: 4.9113738 | AV6: 4.9775992 | AW6: 5.0450545 | AX6: 5.102282 | AY6: 5.152576 | AZ6: 5.2028947 | BA6: 5.2620236 | BB6: 5.3369078 | BC6: 5.3884499 | BD6: 5.4488915 | BE6: 5.5202134 | BF6: 5.6089867 | BG6: 5.6868028 | BH6: 5.7539812 | BI6: 5.7597655 | BJ6: 5.7543835 | BK6: 5.7348545 | BL6: 5.7454988 | BM6: 5.7536789 | BN6: 5.7640504 | BO6: 5.7776253 | BP6: 5.7957867 | BQ6: 5.8178933 | BR6: 5.841936 | BS6: 5.8761847 | BT6: 5.9051538 | BU6: 5.8195509 | BV6: 5.865207 | BW6: 5.8698731 | BX6: 5.8747772 | BY6: 5.8799305 | BZ6: 5.8853445 | CA6: 5.8910312 | CB6: 5.897003 | CC6: 5.9032726 | CD6: 5.9098531 | CE6: 5.9167581 | CF6: 5.9240015 | CG6: 5.9315976 | CH6: 5.9395608 | CI6: 5.947906 | CJ6: 5.9566484 | CK6: 5.9658032 | CL6: 5.9753861 | CM6: 5.9854124 | CN6: 5.995898 | CO6: 6.0068583 | CP6: 6.0183089 | CQ6: 6.030265 | CR6: 6.0427414 | CS6: 6.0557526 | CT6: 6.0693124 | CU6: 6.0834338 | CV6: 6.0981289 | CW6: 6.1134086 | CX6: 6.1292825 | CY6: 6.1457585 | DA6: North America medium-moderate
A7: Alabama | B7: Non-residential | C7: 0.85223522 | D7: 0.92683986 | E7: 1.0035217 | F7: 1.0823736 | G7: 1.1654506 | H7: 1.2560443 | I7: 1.3484486 | J7: 1.4331856 | K7: 1.5220626 | L7: 1.6193802 | M7: 1.7077187 | N7: 1.7987556 | O7: 1.8925991 | P7: 1.9935814 | Q7: 2.0978309 | R7: 2.2034623 | S7: 2.3095262 | T7: 2.4127117 | U7: 2.5212075 | V7: 2.6283643 | W7: 2.7282977 | X7: 2.8140276 | Y7: 2.9039761 | Z7: 2.9999908 | AA7: 3.0822104 | AB7: 3.1445867 | AC7: 3.2114377 | AD7: 3.2856878 | AE7: 3.3669594 | AF7: 3.4456623 | AG7: 3.5092494 | AH7: 3.5927696 | AI7: 3.6657407 | AJ7: 3.7470513 | AK7: 3.8425454 | AL7: 3.9407698 | AM7: 4.0436077 | AN7: 4.1471336 | AO7: 4.2487983 | AP7: 4.3470036 | AQ7: 4.4417089 | AR7: 4.4930816 | AS7: 4.54877 | AT7: 4.6074213 | AU7: 4.6733593 | AV7: 4.7320818 | AW7: 4.7978633 | AX7: 4.8637382 | AY7: 4.9506551 | AZ7: 5.0292295 | BA7: 5.0979988 | BB7: 5.1598606 | BC7: 5.2116895 | BD7: 5.2519018 | BE7: 5.2929728 | BF7: 5.3401 | BG7: 5.4043117 | BH7: 5.464316 | BI7: 5.5339936 | BJ7: 5.5531279 | BK7: 5.5317433 | BL7: 5.5338204 | BM7: 5.5405114 | BN7: 5.5363412 | BO7: 5.5264695 | BP7: 5.5108655 | BQ7: 5.4984162 | BR7: 5.4851856 | BS7: 5.4651999 | BT7: 5.4604249 | BU7: 5.3317749 | BV7: 5.3313004 | BW7: 5.3391078 | BX7: 5.347368 | BY7: 5.3561054 | BZ7: 5.3653453 | CA7: 5.3751142 | CB7: 5.3854395 | CC7: 5.3963498 | CD7: 5.4078745 | CE7: 5.4200444 | CF7: 5.4328908 | CG7: 5.4464461 | CH7: 5.4607435 | CI7: 5.475817 | CJ7: 5.4917012 | CK7: 5.5084309 | CL7: 5.5260415 | CM7: 5.5445684 | CN7: 5.5640467 | CO7: 5.5845112 | CP7: 5.6059958 | CQ7: 5.6285333 | CR7: 5.6521548 | CS7: 5.6768893 | CT7: 5.7027633 | CU7: 5.7297997 | CV7: 5.7580177 | CW7: 5.7874314 | CX7: 5.8180496 | CY7: 5.8498743 | DA7: North America medium-moderate
A8: Alabama | B8: Infrastructure | C8: 0.72933404 | D8: 0.79317985 | E8: 0.8588032 | F8: 0.9262832 | G8: 0.9973783 | H8: 1.0749043 | I8: 1.1539765 | J8: 1.2264808 | K8: 1.3025173 | L8: 1.3857591 | M8: 1.4612884 | N8: 1.5390839 | O8: 1.6192185 | P8: 1.7053745 | Q8: 1.7942067 | R8: 1.8840633 | S8: 1.9740867 | T8: 2.061392 | U8: 2.1529296 | V8: 2.2429474 | W8: 2.3263443 | X8: 2.3971668 | Y8: 2.471074 | Z8: 2.5495953 | AA8: 2.6156866 | AB8: 2.6641315 | AC8: 2.7157076 | AD8: 2.7728919 | AE8: 2.8353432 | AF8: 2.8948433 | AG8: 2.9406502 | AH8: 3.0022014 | AI8: 3.0538207 | AJ8: 3.1116648 | AK8: 3.1807287 | AL8: 3.2512066 | AM8: 3.3247055 | AN8: 3.3978622 | AO8: 3.4684915 | AP8: 3.5352222 | AQ8: 3.5980174 | AR8: 3.624204 | AS8: 3.6533714 | AT8: 3.6843785 | AU8: 3.7209461 | AV8: 3.7506876 | AW8: 3.7848109 | AX8: 3.8111745 | AY8: 3.8347509 | AZ8: 3.8716132 | BA8: 3.904275 | BB8: 3.9466047 | BC8: 3.9950846 | BD8: 4.0593332 | BE8: 4.1217083 | BF8: 4.1740263 | BG8: 4.2262953 | BH8: 4.2806498 | BI8: 4.3342627 | BJ8: 4.3540916 | BK8: 4.3772366 | BL8: 4.4243293 | BM8: 4.4597776 | BN8: 4.4990786 | BO8: 4.5387249 | BP8: 4.5854393 | BQ8: 4.6425549 | BR8: 4.7039983 | BS8: 4.7657187 | BT8: 4.8256911 | BU8: 4.752622 | BV8: 4.8098359 | BW8: 4.8550184 | BX8: 4.8996825 | BY8: 4.9438171 | BZ8: 4.9874118 | CA8: 5.0304569 | CB8: 5.0729434 | CC8: 5.1148632 | CD8: 5.1562087 | CE8: 5.1969732 | CF8: 5.2371505 | CG8: 5.2767354 | CH8: 5.3157231 | CI8: 5.3541096 | CJ8: 5.3918916 | CK8: 5.4290663 | CL8: 5.4656316 | CM8: 5.5015862 | CN8: 5.536929 | CO8: 5.5716599 | CP8: 5.6057789 | CQ8: 5.6392871 | CR8: 5.6721856 | CS8: 5.7044762 | CT8: 5.7361613 | CU8: 5.7672436 | CV8: 5.7977262 | CW8: 5.8276128 | CX8: 5.8569072 | CY8: 5.885614 | DA8: North America medium-moderate
A9: Alabama | B9: Total | C9: =SUM(C6:C8) -> 2.4697107 | D9: =SUM(D6:D8) -> 2.6859091 | E9: =SUM(E6:E8) -> 2.9081269 | F9: =SUM(F6:F8) -> 3.1366328 | G9: =SUM(G6:G8) -> 3.3773822 | H9: =SUM(H6:H8) -> 3.6399124 | I9: =SUM(I6:I8) -> 3.9076863 | J9: =SUM(J6:J8) -> 4.1532348 | ... CY9: =SUM(CY6:CY8) -> 17.881247
A10: Arizona | B10: Residential | C10: 6.130244 | D10: 6.2507367 | E10: 6.3752064 | F10: 6.5037355 | G10: 6.6475962 | H10: 6.8226351 | I10: 6.9952244 | J10: 7.118816 | K10: 7.2558157 | L10: 7.4245177 | M10: 7.5446296 | N10: 7.7123681 | O10: 7.884611 | P10: 8.078659 | Q10: 8.2776284 | R10: 8.4740212 | S10: 8.6645913 | T10: 8.8377456 | U10: 9.0241012 | V10: 9.1996109 | W10: 9.3449272 | X10: 9.2688316 | Y10: 9.220505 | Z10: 9.2022903 | AA10: 9.1519481 | AB10: 9.0547123 | AC10: 8.9822982 | AD10: 8.9402426 | AE10: 8.9248773 | AF10: 8.9092209 | AG10: 8.8614797 | AH10: 8.8020378 | AI10: 8.7233407 | AJ10: 8.6706225 | AK10: 8.6548968 | AL10: 8.6481977 | AM10: 8.6538767 | AN10: 8.6628759 | AO10: 8.6698024 | AP10: 8.671648 | AQ10: 8.6686926 | AR10: 8.522775 | AS10: 8.3981499 | AT10: 8.2903745 | AU10: 8.2054092 | AV10: 8.1167074 | AW10: 8.0375929 | AX10: 7.9762429 | AY10: 7.9416971 | AZ10: 7.9164113 | BA10: 7.8992927 | BB10: 7.9530917 | BC10: 8.0254253 | BD10: 8.0983227 | BE10: 8.2182975 | BF10: 8.3765584 | BG10: 8.5135089 | BH10: 8.4843044 | BI10: 8.4131108 | BJ10: 8.2890978 | BK10: 8.1390264 | BL10: 8.0994342 | BM10: 8.0701282 | BN10: 8.0411145 | BO10: 8.0065438 | BP10: 7.9913582 | BQ10: 7.9727378 | BR10: 7.9743971 | BS10: 7.9668487 | BT10: 7.9136682 | BU10: 8.1322733 | BV10: 8.1622983 | BW10: 8.1669751 | BX10: 8.1722011 | BY10: 8.1780369 | BZ10: 8.1845489 | CA10: 8.1918093 | CB10: 8.1998962 | CC10: 8.208894 | CD10: 8.2188933 | CE10: 8.2299902 | CF10: 8.2422862 | CG10: 8.2558869 | CH10: 8.270901 | CI10: 8.2874385 | CJ10: 8.3056076 | CK10: 8.3255122 | CL10: 8.3472472 | CM10: 8.3708936 | CN10: 8.3965122 | CO10: 8.424136 | CP10: 8.453762 | CQ10: 8.4853413 | CR10: 8.5187697 | CS10: 8.5538771 | CT10: 8.5904185 | CU10: 8.6280671 | CV10: 8.6664104 | CW10: 8.7049524 | CX10: 8.7431227 | CY10: 8.7802945 | DA10: North America high-fast
A11: Arizona | B11: Non-residential | C11: 6.0981422 | D11: 6.2180039 | E11: 6.3418218 | F11: 6.4696779 | G11: 6.6127852 | H11: 6.7869074 | I11: 6.9585929 | J11: 7.0815372 | K11: 7.2178193 | L11: 7.3856374 | M11: 7.5051192 | N11: 7.6719773 | O11: 7.8433143 | P11: 8.0363393 | Q11: 8.2342547 | R11: 8.4295989 | S11: 8.6191387 | T11: 8.7913355 | U11: 8.9766383 | V11: 9.1511151 | W11: 9.2955064 | X11: 9.2195967 | Y11: 9.1712372 | Z11: 9.1527403 | AA11: 9.1021719 | AB11: 9.0048205 | AC11: 8.9320011 | AD11: 8.8891949 | AE11: 8.8727259 | AF11: 8.8557256 | AG11: 8.806539 | AH11: 8.7454162 | AI11: 8.6648162 | AJ11: 8.6097122 | AK11: 8.5910382 | AL11: 8.5809558 | AM11: 8.5827826 | AN11: 8.5874953 | AO11: 8.5897193 | AP11: 8.5864554 | AQ11: 8.5779781 | AR11: 8.4275461 | AS11: 8.2979735 | AT11: 8.1848478 | AU11: 8.0941062 | AV11: 7.9993495 | AW11: 7.9372021 | AX11: 7.8818083 | AY11: 7.8787054 | AZ11: 7.9096524 | BA11: 7.9141704 | BB11: 7.9125958 | BC11: 7.8840095 | BD11: 7.8568405 | BE11: 7.8604966 | BF11: 7.8916009 | BG11: 7.935595 | BH11: 7.9965387 | BI11: 7.9758759 | BJ11: 7.866945 | BK11: 7.7145629 | BL11: 7.6392511 | BM11: 7.5521138 | BN11: 7.4841004 | BO11: 7.3966229 | BP11: 7.318258 | BQ11: 7.2099371 | BR11: 7.1152403 | BS11: 7.0477609 | BT11: 6.9670316 | BU11: 7.1439066 | BV11: 7.1586802 | BW11: 7.1682823 | BX11: 7.1791008 | BY11: 7.1912831 | BZ11: 7.2049921 | CA11: 7.220408 | CB11: 7.2377286 | CC11: 7.2571706 | CD11: 7.2789698 | CE11: 7.3033812 | CF11: 7.3306781 | CG11: 7.3611508 | CH11: 7.3951036 | CI11: 7.43285 | CJ11: 7.4747067 | CK11: 7.5209841 | CL11: 7.5719737 | CM11: 7.6279321 | CN11: 7.68906 | CO11: 7.7554764 | CP11: 7.8271882 | CQ11: 7.9040543 | CR11: 7.9857476 | CS11: 8.0717156 | CT11: 8.1611453 | CU11: 8.2529388 | CV11: 8.3457072 | CW11: 8.4377928 | CX11: 8.5273295 | CY11: 8.6123455 | DA11: North America high-fast
A12: Arizona | B12: Infrastructure | C12: 4.204943 | D12: 4.2875927 | E12: 4.3729696 | F12: 4.4611295 | G12: 4.5598023 | H12: 4.6798545 | I12: 4.7982135 | J12: 4.8829406 | K12: 4.9768272 | L12: 5.0923997 | M12: 5.1745523 | N12: 5.2892368 | O12: 5.4068214 | P12: 5.5391052 | Q12: 5.6744249 | R12: 5.8075418 | S12: 5.9361213 | T12: 6.0520927 | U12: 6.1763307 | V12: 6.2922086 | W12: 6.3863225 | X12: 6.3281591 | Y12: 6.2880533 | Z12: 6.2675533 | AA12: 6.2239204 | AB12: 6.1469929 | AC12: 6.0859424 | AD12: 6.0445593 | AE12: 6.0203312 | AF12: 5.9947637 | AG12: 5.9460692 | AH12: 5.8882537 | AI12: 5.816165 | AJ12: 5.7608605 | AK12: 5.7299238 | AL12: 5.7041997 | AM12: 5.6860129 | AN12: 5.6691744 | AO12: 5.6500079 | AP12: 5.6264725 | AQ12: 5.5987835 | AR12: 5.4772811 | AS12: 5.3699155 | AT12: 5.2736645 | AU12: 5.1926454 | AV12: 5.1086822 | AW12: 5.0500279 | AX12: 4.9836791 | AY12: 4.918428 | AZ12: 4.8861916 | BA12: 4.8556581 | BB12: 4.8428945 | BC12: 4.8367435 | BD12: 4.8509818 | BE12: 4.8961416 | BF12: 4.958707 | BG12: 5.0029903 | BH12: 5.0502667 | BI12: 5.0422946 | BJ12: 5.0062585 | BK12: 4.9563207 | BL12: 4.9644961 | BM12: 4.9515082 | BN12: 4.9579675 | BO12: 4.9187592 | BP12: 4.8772839 | BQ12: 4.82814 | BR12: 4.8008573 | BS12: 4.8010196 | BT12: 4.7883776 | BU12: 4.8969862 | BV12: 4.890574 | BW12: 4.9599103 | BX12: 5.0326019 | BY12: 5.1087569 | BZ12: 5.1884764 | CA12: 5.2718515 | CB12: 5.358961 | CC12: 5.4498684 | CD12: 5.5446178 | CE12: 5.6432305 | CF12: 5.7457004 | CG12: 5.8519897 | CH12: 5.9620235 | CI12: 6.0756855 | CJ12: 6.1928119 | CK12: 6.3131875 | CL12: 6.4365402 | CM12: 6.5625378 | CN12: 6.6907845 | CO12: 6.8208193 | CP12: 6.9521162 | CQ12: 7.0840862 | CR12: 7.2160818 | CS12: 7.3474041 | CT12: 7.477313 | CU12: 7.6050398 | CV12: 7.7298034 | CW12: 7.8508278 | CX12: 7.967362 | CY12: 8.0787006 | DA12: North America high-fast
A13: Arizona | B13: Total | C13: =SUM(C10:C12) -> 16.433329 | D13: =SUM(D10:D12) -> 16.756333 | E13: =SUM(E10:E12) -> 17.089998 | F13: =SUM(F10:F12) -> 17.434543 | G13: =SUM(G10:G12) -> 17.820184 | H13: =SUM(H10:H12) -> 18.289397 | I13: =SUM(I10:I12) -> 18.752031 | J13: =SUM(J10:J12) -> 19.083294 | ... CY13: =SUM(CY10:CY12) -> 25.471341
A14: Arkansas | B14: Residential | C14: 0.43480355 | D14: 0.47912453 | E14: 0.52562947 | F14: 0.57443239 | G14: 0.62670701 | H14: 0.68436082 | I14: 0.74443227 | J14: 0.80168809 | K14: 0.86268014 | L14: 0.93000005 | M14: 0.9937347 | N14: 1.0443837 | O14: 1.0964603 | P14: 1.1524631 | Q14: 1.2101371 | R14: 1.2683904 | S14: 1.3266781 | T14: 1.3831066 | U14: 1.4423765 | V14: 1.5006796 | W14: 1.5546746 | X14: 1.5943985 | Y14: 1.6362998 | Z14: 1.6813914 | AA14: 1.7185654 | AB14: 1.7446029 | AC14: 1.7731024 | AD14: 1.8056443 | AE14: 1.8419769 | AF14: 1.8768417 | AG14: 1.9034726 | AH14: 1.9510895 | AI14: 1.9931558 | AJ14: 2.0399316 | AK14: 2.0946197 | AL14: 2.1510176 | AM14: 2.2101662 | AN14: 2.2699421 | AO14: 2.3289641 | AP14: 2.3863653 | AQ14: 2.4421268 | AR14: 2.4632035 | AS14: 2.4868228 | AT14: 2.512229 | AU14: 2.5417382 | AV14: 2.5675163 | AW14: 2.5959718 | AX14: 2.6189077 | AY14: 2.6465603 | AZ14: 2.6808175 | BA14: 2.7260968 | BB14: 2.7797129 | BC14: 2.8334044 | BD14: 2.9086822 | BE14: 2.9706392 | BF14: 3.052081 | BG14: 3.1165462 | BH14: 3.1572386 | BI14: 3.1960027 | BJ14: 3.2121922 | BK14: 3.2237018 | BL14: 3.2548257 | BM14: 3.2884184 | BN14: 3.3267081 | BO14: 3.3539511 | BP14: 3.3844673 | BQ14: 3.431399 | BR14: 3.4851403 | BS14: 3.5468262 | BT14: 3.5989946 | BU14: 3.6647101 | BV14: 3.7179174 | BW14: 3.7268174 | BX14: 3.736329 | BY14: 3.7464948 | BZ14: 3.7573601 | CA14: 3.7689737 | CB14: 3.7813874 | CC14: 3.7946572 | CD14: 3.8088426 | CE14: 3.8240074 | CF14: 3.8402202 | CG14: 3.8575541 | CH14: 3.8760874 | CI14: 3.8959039 | CJ14: 3.9170935 | CK14: 3.939752 | CL14: 3.9639821 | CM14: 3.9898937 | CN14: 4.0176039 | CO14: 4.047238 | CP14: 4.0789298 | CQ14: 4.1128216 | CR14: 4.1490654 | CS14: 4.1878227 | CT14: 4.229265 | CU14: 4.2735743 | CV14: 4.3209431 | CW14: 4.3715745 | CX14: 4.4256822 | CY14: 4.4834901 | DA14: North America high-moderate
A15: Arkansas | B15: Non-residential | C15: 0.8771475 | D15: 0.96655808 | E15: 1.0603745 | F15: 1.1588266 | G15: 1.2642824 | H15: 1.3805899 | I15: 1.5017745 | J15: 1.6172791 | K15: 1.7403209 | L15: 1.876128 | M15: 2.0047023 | N15: 2.106878 | O15: 2.2119333 | P15: 2.3249081 | Q15: 2.4412526 | R15: 2.5587631 | S15: 2.676339 | T15: 2.7901579 | U15: 2.9096998 | V15: 3.0272781 | W15: 3.1361469 | X15: 3.2162039 | Y15: 3.3006224 | Z15: 3.3914373 | AA15: 3.4662295 | AB15: 3.5184935 | AC15: 3.5756489 | AD15: 3.6408694 | AE15: 3.713631 | AF15: 3.783309 | AG15: 3.8362369 | AH15: 3.931282 | AI15: 4.0149259 | AJ15: 4.1078418 | AK15: 4.2164669 | AL15: 4.3282643 | AM15: 4.4453106 | AN15: 4.5632993 | AO15: 4.6794232 | AP15: 4.7919134 | AQ15: 4.9007134 | AR15: 4.9394679 | AS15: 4.9830246 | AT15: 5.0298547 | AU15: 5.0846285 | AV15: 5.1315404 | AW15: 5.1612798 | AX15: 5.2167385 | AY15: 5.2844264 | AZ15: 5.3289447 | BA15: 5.3426504 | BB15: 5.3767421 | BC15: 5.3900867 | BD15: 5.4044392 | BE15: 5.4411851 | BF15: 5.4864242 | BG15: 5.5269765 | BH15: 5.5541749 | BI15: 5.5635317 | BJ15: 5.5281849 | BK15: 5.4756759 | BL15: 5.4372087 | BM15: 5.4224964 | BN15: 5.4075475 | BO15: 5.3994284 | BP15: 5.3754951 | BQ15: 5.3477636 | BR15: 5.3161109 | BS15: 5.2966683 | BT15: 5.2712406 | BU15: 5.2817008 | BV15: 5.2682934 | BW15: 5.2811474 | BX15: 5.2948277 | BY15: 5.3093863 | BZ15: 5.3248779 | CA15: 5.3413607 | CB15: 5.3588961 | CC15: 5.3775487 | CD15: 5.3973871 | CE15: 5.4184833 | CF15: 5.4409132 | CG15: 5.4647567 | CH15: 5.4900975 | CI15: 5.5170236 | CJ15: 5.5456268 | CK15: 5.576003 | CL15: 5.6082523 | CM15: 5.6424782 | CN15: 5.6787881 | CO15: 5.7172926 | CP15: 5.7581052 | CQ15: 5.8013418 | CR15: 5.8471197 | CS15: 5.8955573 | CT15: 5.9467725 | CU15: 6.0008814 | CV15: 6.0579971 | CW15: 6.1182274 | CX15: 6.1816725 | CY15: 6.2484228 | DA15: North America high-moderate
A16: Arkansas | B16: Infrastructure | C16: 1.3555532 | D16: 1.4937291 | E16: 1.6387135 | F16: 1.7908615 | G16: 1.9538313 | H16: 2.1335679 | I16: 2.3208348 | J16: 2.4993106 | K16: 2.6894114 | L16: 2.899201 | M16: 3.0977505 | N16: 3.2554157 | O16: 3.4173997 | P16: 3.591439 | Q16: 3.7704365 | R16: 3.9509075 | S16: 4.1310588 | T16: 4.3048781 | U16: 4.4868996 | V16: 4.6651194 | W16: 4.8289815 | X16: 4.9475523 | Y16: 5.0718394 | Z16: 5.2048958 | AA16: 5.3119952 | AB16: 5.3830171 | AC16: 5.4602849 | AD16: 5.5486671 | AE16: 5.6473334 | AF16: 5.7398573 | AG16: 5.8051235 | AH16: 5.9322792 | AI16: 6.0399905 | AJ16: 6.1601856 | AK16: 6.302796 | AL16: 6.4484329 | AM16: 6.6002928 | AN16: 6.7517075 | AO16: 6.8983269 | AP16: 7.0374059 | AQ16: 7.1688485 | AR16: 7.1949109 | AS16: 7.2271954 | AT16: 7.2633786 | AU16: 7.3107234 | AV16: 7.3448565 | AW16: 7.3730865 | AX16: 7.4144921 | AY16: 7.4452555 | AZ16: 7.4633055 | BA16: 7.4780382 | BB16: 7.5120408 | BC16: 7.5479918 | BD16: 7.5941463 | BE16: 7.6654157 | BF16: 7.7114793 | BG16: 7.7643647 | BH16: 7.8064004 | BI16: 7.8007551 | BJ16: 7.7973244 | BK16: 7.7849603 | BL16: 7.7920076 | BM16: 7.8254911 | BN16: 7.8864791 | BO16: 7.9479258 | BP16: 7.9883337 | BQ16: 8.023841 | BR16: 8.043496 | BS16: 8.0475826 | BT16: 8.0687135 | BU16: 8.1231395 | BV16: 8.1229073 | BW16: 8.1462082 | BX16: 8.1693251 | BY16: 8.1922469 | BZ16: 8.2149621 | CA16: 8.2374595 | CB16: 8.259728 | CC16: 8.2817568 | CD16: 8.3035351 | CE16: 8.3250522 | CF16: 8.3462977 | CG16: 8.3672617 | CH16: 8.3879342 | CI16: 8.4083056 | CJ16: 8.4283666 | CK16: 8.4481085 | CL16: 8.4675225 | CM16: 8.4866005 | CN16: 8.5053347 | CO16: 8.5237177 | CP16: 8.5417426 | CQ16: 8.5594029 | CR16: 8.5766926 | CS16: 8.5936062 | CT16: 8.6101387 | CU16: 8.6262856 | CV16: 8.6420429 | CW16: 8.6574073 | CX16: 8.6723757 | CY16: 8.686946 | DA16: North America high-moderate
A17: Arkansas | B17: Total | C17: =SUM(C14:C16) -> 2.6675042 | D17: =SUM(D14:D16) -> 2.9394117 | E17: =SUM(E14:E16) -> 3.2247175 | F17: =SUM(F14:F16) -> 3.5241205 | G17: =SUM(G14:G16) -> 3.8448207 | H17: =SUM(H14:H16) -> 4.1985186 | I17: =SUM(I14:I16) -> 4.5670416 | J17: =SUM(J14:J16) -> 4.9182778 | ... CY17: =SUM(CY14:CY16) -> 19.418859
A18: California | B18: Residential | C18: 0.97863063 | D18: 1.0218961 | E18: 1.0645877 | F18: 1.1069148 | G18: 1.1509935 | H18: 1.1998415 | I18: 1.2477757 | J18: 1.2864193 | K18: 1.3269117 | L18: 1.3727779 | M18: 1.4092478 | N18: 1.453269 | O18: 1.4980348 | P18: 1.5468864 | Q18: 1.5966659 | R18: 1.6459383 | S18: 1.6940594 | T18: 1.738728 | U18: 1.7859442 | V18: 1.8309703 | W18: 1.8699021 | X18: 1.9181769 | Y18: 1.9690783 | Z18: 2.0238272 | AA18: 2.0690526 | AB18: 2.1008713 | AC18: 2.1356535 | AD18: 2.1753051 | AE18: 2.2195256 | AF18: 2.2619803 | AG18: 2.294512 | AH18: 2.2993391 | AI18: 2.2978378 | AJ18: 2.3019875 | AK18: 2.3149757 | AL18: 2.3295516 | AM18: 2.3467295 | AN18: 2.364151 | AO18: 2.3803944 | AP18: 2.3946572 | AQ18: 2.4070294 | AR18: 2.4275893 | AS18: 2.450657 | AT18: 2.475487 | AU18: 2.504361 | AV18: 2.5295596 | AW18: 2.5571747 | AX18: 2.5936105 | AY18: 2.6367577 | AZ18: 2.6957068 | BA18: 2.7717818 | BB18: 2.8655881 | BC18: 2.962808 | BD18: 3.0502737 | BE18: 3.1543198 | BF18: 3.2616945 | BG18: 3.331795 | BH18: 3.3692912 | BI18: 3.3729505 | BJ18: 3.37933 | BK18: 3.3712915 | BL18: 3.3719619 | BM18: 3.3777394 | BN18: 3.3981795 | BO18: 3.4054256 | BP18: 3.4313439 | BQ18: 3.4614267 | BR18: 3.5020892 | BS18: 3.5538369 | BT18: 3.6119935 | BU18: 3.6703151 | BV18: 3.7661062 | BW18: 3.774657 | BX18: 3.7836713 | BY18: 3.7931738 | BZ18: 3.8031905 | CA18: 3.813749 | CB18: 3.8248778 | CC18: 3.8366073 | CD18: 3.8489692 | CE18: 3.8619967 | CF18: 3.8757247 | CG18: 3.8901899 | CH18: 3.9054304 | CI18: 3.9214865 | CJ18: 3.9384001 | CK18: 3.9562148 | CL18: 3.9749765 | CM18: 3.9947328 | CN18: 4.0155334 | CO18: 4.0374297 | CP18: 4.0604753 | CQ18: 4.0847256 | CR18: 4.1102379 | CS18: 4.1370713 | CT18: 4.1652865 | CU18: 4.1949458 | CV18: 4.2261127 | CW18: 4.2588519 | CX18: 4.2932287 | CY18: 4.3293091 | DA18: North America medium-moderate
A19: California | B19: Non-residential | C19: 1.4038584 | D19: 1.4659234 | E19: 1.527165 | F19: 1.5878837 | G19: 1.6511153 | H19: 1.7211883 | I19: 1.7899505 | J19: 1.8453852 | K19: 1.9034721 | L19: 1.9692676 | M19: 2.0215838 | N19: 2.0847322 | O19: 2.1489484 | P19: 2.2190247 | Q19: 2.2904306 | R19: 2.3611068 | S19: 2.430128 | T19: 2.4941912 | U19: 2.5619012 | V19: 2.6264587 | W19: 2.6822592 | X19: 2.7514417 | Y19: 2.8243657 | Z19: 2.902775 | AA19: 2.9674797 | AB19: 3.0128991 | AC19: 3.062505 | AD19: 3.119019 | AE19: 3.1819965 | AF19: 3.2423356 | AG19: 3.28832 | AH19: 3.2944658 | AI19: 3.2913997 | AJ19: 3.2962948 | AK19: 3.3137132 | AL19: 3.3332441 | AM19: 3.356334 | AN19: 3.3795927 | AO19: 3.4009748 | AP19: 3.4193248 | AQ19: 3.4347684 | AR19: 3.4616253 | AS19: 3.4918508 | AT19: 3.5243727 | AU19: 3.5624626 | AV19: 3.5950458 | AW19: 3.6257697 | AX19: 3.6696647 | AY19: 3.7309917 | AZ19: 3.8014974 | BA19: 3.8650156 | BB19: 3.9171978 | BC19: 3.9546574 | BD19: 3.9993814 | BE19: 4.0524143 | BF19: 4.1068228 | BG19: 4.1611082 | BH19: 4.1944161 | BI19: 4.2056838 | BJ19: 4.1802806 | BK19: 4.1389125 | BL19: 4.1067294 | BM19: 4.0762928 | BN19: 4.0464813 | BO19: 4.0268652 | BP19: 4.024852 | BQ19: 4.0212838 | BR19: 4.0347925 | BS19: 4.0566622 | BT19: 4.0644717 | BU19: 4.0820581 | BV19: 4.1460479 | BW19: 4.156443 | BX19: 4.1674646 | BY19: 4.1791493 | BZ19: 4.1915359 | CA19: 4.2046649 | CB19: 4.2185791 | CC19: 4.2333236 | CD19: 4.2489455 | CE19: 4.2654946 | CF19: 4.2830226 | CG19: 4.3015841 | CH19: 4.3212356 | CI19: 4.3420366 | CJ19: 4.3640485 | CK19: 4.3873354 | CL19: 4.4119637 | CM19: 4.4380016 | CN19: 4.4655198 | CO19: 4.4945904 | CP19: 4.5252872 | CQ19: 4.5576849 | CR19: 4.5918591 | CS19: 4.6278853 | CT19: 4.6658384 | CU19: 4.7057918 | CV19: 4.7478168 | CW19: 4.7919807 | CX19: 4.8383463 | CY19: 4.8869695 | DA19: North America medium-moderate
A20: California | B20: Infrastructure | C20: 1.7779474 | D20: 1.8565507 | E20: 1.934111 | F20: 2.0110084 | G20: 2.0910866 | H20: 2.1798259 | I20: 2.266899 | J20: 2.3370821 | K20: 2.4106052 | L20: 2.4938611 | M20: 2.5599999 | N20: 2.6397877 | O20: 2.72083 | P20: 2.8091602 | Q20: 2.8989966 | R20: 2.98768 | S20: 3.0739802 | T20: 3.1536499 | U20: 3.2375181 | V20: 3.3169024 | W20: 3.3846327 | X20: 3.4686366 | Y20: 3.5566591 | Z20: 3.650844 | AA20: 3.7268316 | AB20: 3.7775067 | AC20: 3.8325594 | AD20: 3.8954107 | AE20: 3.9654825 | AF20: 4.0312423 | AG20: 4.077855 | AH20: 4.0740283 | AI20: 4.0578034 | AJ20: 4.0509584 | AK20: 4.0592998 | AL20: 4.06967 | AM20: 4.0839265 | AN20: 4.0977993 | AO20: 4.1087197 | AP20: 4.1152446 | AQ20: 4.1175532 | AR20: 4.1321584 | AS20: 4.1503441 | AT20: 4.1707747 | AU20: 4.1976197 | AV20: 4.216884 | AW20: 4.239046 | AX20: 4.2673668 | AY20: 4.2888552 | AZ20: 4.3304474 | BA20: 4.3748431 | BB20: 4.4266351 | BC20: 4.4834943 | BD20: 4.5364455 | BE20: 4.6015627 | BF20: 4.6850446 | BG20: 4.7694779 | BH20: 4.8463804 | BI20: 4.8908032 | BJ20: 4.8873843 | BK20: 4.8801427 | BL20: 4.8981993 | BM20: 4.9236194 | BN20: 4.9470158 | BO20: 4.9764114 | BP20: 4.9915414 | BQ20: 5.0200172 | BR20: 5.058522 | BS20: 5.1124713 | BT20: 5.1727226 | BU20: 5.2449227 | BV20: 5.3547808 | BW20: 5.3924785 | BX20: 5.4295713 | BY20: 5.4660572 | BZ20: 5.5019346 | CA20: 5.5372027 | CB20: 5.5718613 | CC20: 5.6059105 | CD20: 5.6393511 | CE20: 5.6721845 | CF20: 5.7044125 | CG20: 5.7360373 | CH20: 5.7670616 | CI20: 5.7974886 | CJ20: 5.8273218 | CK20: 5.8565653 | CL20: 5.8852233 | CM20: 5.9133005 | CN20: 5.9408019 | CO20: 5.9677329 | CP20: 5.994099 | CQ20: 6.0199061 | CR20: 6.0451604 | CS20: 6.0698681 | CT20: 6.094036 | CU20: 6.1176706 | CV20: 6.1407791 | CW20: 6.1633685 | CX20: 6.1854461 | CY20: 6.2070193 | DA20: North America medium-moderate
A21: California | B21: Total | C21: =SUM(C18:C20) -> 4.1604365 | D21: =SUM(D18:D20) -> 4.3443702 | E21: =SUM(E18:E20) -> 4.5258636 | F21: =SUM(F18:F20) -> 4.7058069 | G21: =SUM(G18:G20) -> 4.8931954 | H21: =SUM(H18:H20) -> 5.1008556 | I21: =SUM(I18:I20) -> 5.3046252 | J21: =SUM(J18:J20) -> 5.4688866 | ... CY21: =SUM(CY18:CY20) -> 15.423298
A22: Colorado | B22: Residential | C22: 2.2062608 | D22: 2.3397375 | E22: 2.4726469 | F22: 2.6053608 | G22: 2.7428329 | H22: 2.8924342 | I22: 3.0406393 | J22: 3.1666937 | K22: 3.2975695 | L22: 3.4422125 | M22: 3.5635942 | N22: 3.6788723 | O22: 3.7960768 | P22: 3.9236851 | Q22: 4.0537058 | R22: 4.1824947 | S22: 4.3084067 | T22: 4.4255738 | U22: 4.5492567 | V22: 4.6673913 | W22: 4.7700042 | X22: 4.8347106 | Y22: 4.9065107 | Z22: 4.9881537 | AA22: 5.0467009 | AB22: 5.0734554 | AC22: 5.1084519 | AD22: 5.155926 | AE22: 5.2148 | AF22: 5.2699965 | AG22: 5.3027325 | AH22: 5.3754422 | AI22: 5.4317715 | AJ22: 5.4999176 | AK22: 5.5880601 | AL22: 5.6792118 | AM22: 5.7760141 | AN22: 5.8728152 | AO22: 5.9660909 | AP22: 6.0537574 | AQ22: 6.1359407 | AR22: 6.0877881 | AS22: 6.049965 | AT22: 6.0200338 | AU22: 6.002985 | AV22: 5.9799157 | AW22: 6.0057217 | AX22: 6.0384948 | AY22: 6.0751169 | AZ22: 6.1228117 | BA22: 6.1769386 | BB22: 6.2976247 | BC22: 6.4039143 | BD22: 6.4453673 | BE22: 6.5145912 | BF22: 6.6262471 | BG22: 6.7483123 | BH22: 6.7682848 | BI22: 6.7209288 | BJ22: 6.6489496 | BK22: 6.581502 | BL22: 6.5373217 | BM22: 6.523376 | BN22: 6.5092845 | BO22: 6.5093379 | BP22: 6.4937365 | BQ22: 6.5078964 | BR22: 6.5530452 | BS22: 6.6375745 | BT22: 6.6791653 | BU22: 6.7983386 | BV22: 6.9318293 | BW22: 6.9383169 | BX22: 6.9452296 | BY22: 6.952594 | BZ22: 6.9604382 | CA22: 6.9687921 | CB22: 6.9776868 | CC22: 6.9871553 | CD22: 6.9972324 | CE22: 7.0079545 | CF22: 7.0193597 | CG22: 7.0314881 | CH22: 7.0443816 | CI22: 7.0580838 | CJ22: 7.0726401 | CK22: 7.0880977 | CL22: 7.1045056 | CM22: 7.1219142 | CN22: 7.1403755 | CO22: 7.1599428 | CP22: 7.1806703 | CQ22: 7.2026134 | CR22: 7.2258276 | CS22: 7.2503688 | CT22: 7.2762923 | CU22: 7.3036527 | CV22: 7.3325029 | CW22: 7.3628933 | CX22: 7.3948715 | CY22: 7.4284804 | DA22: North America high-moderate
A23: Colorado | B23: Non-residential | C23: 2.6568472 | D23: 2.8175839 | E23: 2.9776375 | F23: 3.1374556 | G23: 3.3030038 | H23: 3.4831583 | I23: 3.6616314 | J23: 3.8134299 | K23: 3.9710345 | L23: 4.1452178 | M23: 4.2913887 | N23: 4.430209 | O23: 4.571348 | P23: 4.7250137 | Q23: 4.8815813 | R23: 5.0366608 | S23: 5.1882682 | T23: 5.3293334 | U23: 5.4782285 | V23: 5.6204191 | W23: 5.7438863 | X23: 5.8216669 | Y23: 5.9079377 | Z23: 6.0059951 | AA23: 6.076157 | AB23: 6.107932 | AC23: 6.1495104 | AD23: 6.205971 | AE23: 6.2759923 | AF23: 6.3413932 | AG23: 6.3795298 | AH23: 6.4654891 | AI23: 6.5314252 | AJ23: 6.6112636 | AK23: 6.714826 | AL23: 6.8216284 | AM23: 6.9348263 | AN23: 7.047591 | AO23: 7.155658 | AP23: 7.2565005 | AQ23: 7.3502554 | AR23: 7.2873491 | AS23: 7.2365442 | AT23: 7.1949094 | AU23: 7.1684597 | AV23: 7.1344383 | AW23: 7.1113229 | AX23: 7.1063602 | AY23: 7.1674583 | AZ23: 7.2296387 | BA23: 7.2807398 | BB23: 7.3475263 | BC23: 7.3966467 | BD23: 7.4149265 | BE23: 7.4265253 | BF23: 7.4253001 | BG23: 7.4349836 | BH23: 7.4779413 | BI23: 7.5098682 | BJ23: 7.4577996 | BK23: 7.3574336 | BL23: 7.2737729 | BM23: 7.2066092 | BN23: 7.1397503 | BO23: 7.0771655 | BP23: 7.0044345 | BQ23: 6.9556721 | BR23: 6.9317971 | BS23: 6.8475577 | BT23: 6.7838774 | BU23: 6.8037607 | BV23: 6.8187426 | BW23: 6.8284573 | BX23: 6.838775 | BY23: 6.8497307 | BZ23: 6.8613611 | CA23: 6.8737045 | CB23: 6.8868012 | CC23: 6.9006929 | CD23: 6.9154233 | CE23: 6.9310377 | CF23: 6.947583 | CG23: 6.9651078 | CH23: 6.9836622 | CI23: 7.0032975 | CJ23: 7.0240665 | CK23: 7.0460228 | CL23: 7.0692207 | CM23: 7.0937152 | CN23: 7.1195611 | CO23: 7.146813 | CP23: 7.1755244 | CQ23: 7.2057477 | CR23: 7.2375326 | CS23: 7.270926 | CT23: 7.3059709 | CU23: 7.3427052 | CV23: 7.3811606 | CW23: 7.4213613 | CX23: 7.4633225 | CY23: 7.5070488 | DA23: North America high-moderate
A24: Colorado | B24: Infrastructure | C24: 1.8443877 | D24: 1.9559712 | E24: 2.0670801 | F24: 2.1780248 | G24: 2.2929456 | H24: 2.4180022 | I24: 2.5418846 | J24: 2.6472364 | K24: 2.756597 | L24: 2.877431 | M24: 2.978764 | N24: 3.074914 | O24: 3.1725593 | P24: 3.2787438 | Q24: 3.3867345 | R24: 3.4934231 | S24: 3.5973639 | T24: 3.6935728 | U24: 3.7947225 | V24: 3.8906383 | W24: 3.9728913 | X24: 4.022869 | Y24: 4.0780004 | Z24: 4.1405204 | AA24: 4.182838 | AB24: 4.1976372 | AC24: 4.2183506 | AD24: 4.2484941 | AE24: 4.287151 | AF24: 4.3217105 | AG24: 4.3364708 | AH24: 4.3825863 | AI24: 4.4137566 | AJ24: 4.4535493 | AK24: 4.5088005 | AL24: 4.565309 | AM24: 4.6252838 | AN24: 4.6840019 | AO24: 4.73852 | AP24: 4.7871008 | AQ24: 4.8298565 | AR24: 4.7682227 | AS24: 4.7146526 | AT24: 4.6671341 | AU24: 4.6298687 | AV24: 4.5870879 | AW24: 4.5508275 | AX24: 4.5170404 | AY24: 4.4933547 | AZ24: 4.4858882 | BA24: 4.4934756 | BB24: 4.5317578 | BC24: 4.5846147 | BD24: 4.6314376 | BE24: 4.7001847 | BF24: 4.7466864 | BG24: 4.7874086 | BH24: 4.8388628 | BI24: 4.9079778 | BJ24: 4.9271687 | BK24: 4.9326722 | BL24: 4.9482303 | BM24: 4.9678649 | BN24: 5.0001347 | BO24: 5.0435573 | BP24: 5.0463645 | BQ24: 5.0631261 | BR24: 5.1049683 | BS24: 5.1230194 | BT24: 5.2209722 | BU24: 5.2991529 | BV24: 5.3520942 | BW24: 5.4165312 | BX24: 5.4816351 | BY24: 5.5473769 | BZ24: 5.6137256 | CA24: 5.6806476 | CB24: 5.7481069 | CC24: 5.8160652 | CD24: 5.8844816 | CE24: 5.953313 | CF24: 6.0225136 | CG24: 6.0920356 | CH24: 6.1618286 | CI24: 6.23184 | CJ24: 6.3020153 | CK24: 6.3722976 | CL24: 6.4426282 | CM24: 6.5129466 | CN24: 6.5831907 | CO24: 6.6532968 | CP24: 6.7231998 | CQ24: 6.7928338 | CR24: 6.8621318 | CS24: 6.9310262 | CT24: 6.9994489 | CU24: 7.0673317 | CV24: 7.1346067 | CW24: 7.2012061 | CX24: 7.2670629 | CY24: 7.3321111 | DA24: North America high-moderate
A25: Colorado | B25: Total | C25: =SUM(C22:C24) -> 6.7074957 | D25: =SUM(D22:D24) -> 7.1132925 | E25: =SUM(E22:E24) -> 7.5173644 | F25: =SUM(F22:F24) -> 7.9208412 | G25: =SUM(G22:G24) -> 8.3387823 | H25: =SUM(H22:H24) -> 8.7935948 | I25: =SUM(I22:I24) -> 9.2441554 | J25: =SUM(J22:J24) -> 9.62736 | ... CY25: =SUM(CY22:CY24) -> 22.26764
A26: Connecticut | B26: Residential | C26: 0.44802285 | D26: 0.47793445 | E26: 0.50790148 | F26: 0.53798631 | G26: 0.56920505 | H26: 0.60309844 | I26: 0.63685789 | J26: 0.66610341 | K26: 0.69646515 | L26: 0.7298455 | M26: 0.75839048 | N26: 0.78773223 | O26: 0.81760333 | P26: 0.84984056 | Q26: 0.88273401 | R26: 0.91548719 | S26: 0.94772739 | T26: 0.97814242 | U26: 1.0100886 | V26: 1.0408904 | W26: 1.0682939 | X26: 1.1134897 | Y26: 1.161031 | Z26: 1.2117145 | AA26: 1.2575118 | AB26: 1.295764 | AC26: 1.3363488 | AD26: 1.3805515 | AE26: 1.4283044 | AF26: 1.4755916 | AG26: 1.5169687 | AH26: 1.5503319 | AI26: 1.5791275 | AJ26: 1.6115016 | AK26: 1.6499477 | AL26: 1.6895431 | AM26: 1.7310952 | AN26: 1.7729305 | AO26: 1.8139726 | AP26: 1.8535564 | AQ26: 1.8916809 | AR26: 1.9272528 | AS26: 1.9650242 | AT26: 2.0044489 | AU26: 2.0474312 | AV26: 2.0876918 | AW26: 2.1409539 | AX26: 2.1847747 | AY26: 2.2449351 | AZ26: 2.3084164 | BA26: 2.3621559 | BB26: 2.4091404 | BC26: 2.4612107 | BD26: 2.5138471 | BE26: 2.5674363 | BF26: 2.6252994 | BG26: 2.6620461 | BH26: 2.7010024 | BI26: 2.7155411 | BJ26: 2.723813 | BK26: 2.7251059 | BL26: 2.7374662 | BM26: 2.760619 | BN26: 2.7899667 | BO26: 2.8218851 | BP26: 2.8611988 | BQ26: 2.8974043 | BR26: 2.9310957 | BS26: 2.9636817 | BT26: 2.9938108 | BU26: 3.0110354 | BV26: 3.0171243 | BW26: 3.0190105 | BX26: 3.0210447 | BY26: 3.0232385 | BZ26: 3.0256042 | CA26: 3.0281554 | CB26: 3.0309064 | CC26: 3.0338727 | CD26: 3.0370711 | CE26: 3.0405196 | CF26: 3.0442375 | CG26: 3.0482457 | CH26: 3.0525666 | CI26: 3.0572242 | CJ26: 3.0622444 | CK26: 3.067655 | CL26: 3.0734859 | CM26: 3.0797691 | CN26: 3.0865389 | CO26: 3.0938322 | CP26: 3.1016885 | CQ26: 3.11015 | CR26: 3.1192618 | CS26: 3.1290724 | CT26: 3.1396332 | CU26: 3.1509993 | CV26: 3.163229 | CW26: 3.1763847 | CX26: 3.1905322 | CY26: 3.2057416 | DA26: North America low-moderate
A27: Connecticut | B27: Non-residential | C27: 0.7301917 | D27: 0.77876677 | E27: 0.82743579 | F27: 0.87645987 | G27: 0.92757615 | H27: 0.98255868 | I27: 1.0365872 | J27: 1.0842249 | K27: 1.1339871 | L27: 1.1873341 | M27: 1.2336099 | N27: 1.2812885 | O27: 1.3301281 | P27: 1.3825184 | Q27: 1.4358371 | R27: 1.488862 | S27: 1.5408319 | T27: 1.5903928 | U27: 1.6419859 | V27: 1.6913398 | W27: 1.7361642 | X27: 1.8097091 | Y27: 1.8871645 | Z27: 1.9683708 | AA27: 2.0411959 | AB27: 2.103376 | AC27: 2.1694946 | AD27: 2.2414012 | AE27: 2.3183283 | AF27: 2.393524 | AG27: 2.4595467 | AH27: 2.5122174 | AI27: 2.5586987 | AJ27: 2.6112472 | AK27: 2.6726711 | AL27: 2.7359213 | AM27: 2.8018852 | AN27: 2.8679367 | AO27: 2.9323878 | AP27: 2.9942588 | AQ27: 3.0527745 | AR27: 3.1082401 | AS27: 3.1669259 | AT27: 3.2283401 | AU27: 3.2942197 | AV27: 3.3561543 | AW27: 3.415792 | AX27: 3.4886294 | AY27: 3.5687525 | AZ27: 3.6472541 | BA27: 3.7369228 | BB27: 3.8074148 | BC27: 3.8694184 | BD27: 3.9248346 | BE27: 4.0056571 | BF27: 4.0795259 | BG27: 4.154995 | BH27: 4.2032533 | BI27: 4.233325 | BJ27: 4.2338492 | BK27: 4.2194546 | BL27: 4.2217691 | BM27: 4.2247851 | BN27: 4.2292983 | BO27: 4.2326226 | BP27: 4.2390458 | BQ27: 4.2484501 | BR27: 4.2500377 | BS27: 4.2434389 | BT27: 4.2425082 | BU27: 4.2317676 | BV27: 4.20761 | BW27: 4.2135964 | BX27: 4.2198131 | BY27: 4.2262668 | BZ27: 4.2329644 | CA27: 4.2399128 | CB27: 4.2471187 | CC27: 4.254589 | CD27: 4.2623302 | CE27: 4.2703488 | CF27: 4.2786511 | CG27: 4.2872431 | CH27: 4.2961307 | CI27: 4.3053192 | CJ27: 4.3148137 | CK27: 4.3246189 | CL27: 4.3347388 | CM27: 4.3451768 | CN27: 4.355936 | CO27: 4.3670182 | CP27: 4.3784248 | CQ27: 4.390156 | CR27: 4.4022113 | CS27: 4.4145887 | CT27: 4.4272853 | CU27: 4.4402968 | CV27: 4.4536173 | CW27: 4.4672396 | CX27: 4.4811548 | CY27: 4.4953522 | DA27: North America low-moderate
A28: Connecticut | B28: Infrastructure | C28: 0.47307146 | D28: 0.50465534 | E28: 0.53629768 | F28: 0.56806418 | G28: 0.60102752 | H28: 0.63681405 | I28: 0.67245724 | J28: 0.70333067 | K28: 0.73537681 | L28: 0.77060068 | M28: 0.80070392 | N28: 0.83162608 | O28: 0.86307519 | P28: 0.89697846 | Q28: 0.93151533 | R28: 0.96582688 | S28: 0.99949895 | T28: 1.0311228 | U28: 1.0642172 | V28: 1.0959302 | W28: 1.123854 | X28: 1.1702613 | Y28: 1.218848 | Z28: 1.270418 | AA28: 1.3164573 | AB28: 1.3541232 | AC28: 1.3938127 | AD28: 1.4368524 | AE28: 1.4831434 | AF28: 1.5284202 | AG28: 1.5669118 | AH28: 1.596512 | AI28: 1.6207473 | AJ28: 1.6482081 | AK28: 1.6815173 | AL28: 1.715468 | AM28: 1.7509039 | AN28: 1.7860501 | AO28: 1.8197628 | AP28: 1.8513332 | AQ28: 1.8807548 | AR28: 1.9066321 | AS28: 1.9341759 | AT28: 1.9628068 | AU28: 1.9945364 | AV28: 2.0227379 | AW28: 2.0508931 | AX28: 2.0824748 | AY28: 2.1068059 | AZ28: 2.1349892 | BA28: 2.1748684 | BB28: 2.2140791 | BC28: 2.2470382 | BD28: 2.2646288 | BE28: 2.2797545 | BF28: 2.2887235 | BG28: 2.3069366 | BH28: 2.3373145 | BI28: 2.3703848 | BJ28: 2.3944552 | BK28: 2.421754 | BL28: 2.4530639 | BM28: 2.4855561 | BN28: 2.5346066 | BO28: 2.5786886 | BP28: 2.6418051 | BQ28: 2.7073796 | BR28: 2.7647358 | BS28: 2.8156988 | BT28: 2.8701346 | BU28: 2.9065407 | BV28: 2.9250143 | BW28: 2.9253111 | BX28: 2.925644 | BY28: 2.9260177 | BZ28: 2.9264369 | CA28: 2.9269074 | CB28: 2.9274354 | CC28: 2.9280279 | CD28: 2.9286927 | CE28: 2.9294386 | CF28: 2.9302757 | CG28: 2.931215 | CH28: 2.9322688 | CI28: 2.9334514 | CJ28: 2.9347782 | CK28: 2.9362668 | CL28: 2.937937 | CM28: 2.9398109 | CN28: 2.9419132 | CO28: 2.9442717 | CP28: 2.9469175 | CQ28: 2.9498854 | CR28: 2.9532145 | CS28: 2.9569485 | CT28: 2.9611363 | CU28: 2.9658328 | CV28: 2.9710992 | CW28: 2.9770042 | CX28: 2.9836243 | CY28: 2.9910451 | DA28: North America low-moderate
A29: Connecticut | B29: Total | C29: =SUM(C26:C28) -> 1.651286 | D29: =SUM(D26:D28) -> 1.7613566 | E29: =SUM(E26:E28) -> 1.871635 | F29: =SUM(F26:F28) -> 1.9825104 | G29: =SUM(G26:G28) -> 2.0978087 | H29: =SUM(H26:H28) -> 2.2224712 | I29: =SUM(I26:I28) -> 2.3459023 | J29: =SUM(J26:J28) -> 2.453659 | ... CY29: =SUM(CY26:CY28) -> 10.692139
A30: Delaware | B30: Residential | C30: 1.3189018 | D30: 1.3880168 | E30: 1.4564214 | F30: 1.5243804 | G30: 1.5948107 | H30: 1.6719542 | I30: 1.747949 | J30: 1.8109709 | K30: 1.8765835 | L30: 1.9498294 | M30: 2.0097375 | N30: 2.0809013 | O30: 2.1532665 | P30: 2.2316566 | Q30: 2.3115537 | R30: 2.3908768 | S30: 2.4686704 | T30: 2.5415464 | U30: 2.618249 | V30: 2.6918396 | W30: 2.7565306 | X30: 2.8562466 | Y30: 2.9608637 | Z30: 3.0723252 | AA30: 3.1702825 | AB30: 3.2483069 | AC30: 3.3313636 | AD30: 3.4225613 | AE30: 3.521606 | AF30: 3.6185287 | AG30: 3.7000908 | AH30: 3.7578988 | AI30: 3.8042566 | AJ30: 3.8588855 | AK30: 3.9275789 | AL30: 3.9984485 | AM30: 4.0733655 | AN30: 4.1483552 | AO30: 4.2209217 | AP30: 4.2895746 | AQ30: 4.3543834 | AR30: 4.3751259 | AS30: 4.400658 | AT30: 4.4295837 | AU30: 4.4659278 | AV30: 4.4958884 | AW30: 4.5135145 | AX30: 4.5289036 | AY30: 4.5558972 | AZ30: 4.5864989 | BA30: 4.6211676 | BB30: 4.6563583 | BC30: 4.7148028 | BD30: 4.8060137 | BE30: 4.9104176 | BF30: 5.0042866 | BG30: 5.0745132 | BH30: 5.1230685 | BI30: 5.1306356 | BJ30: 5.1265737 | BK30: 5.107031 | BL30: 5.1222473 | BM30: 5.135659 | BN30: 5.1502445 | BO30: 5.1872271 | BP30: 5.232875 | BQ30: 5.290795 | BR30: 5.3564834 | BS30: 5.4123165 | BT30: 5.5011651 | BU30: 5.580231 | BV30: 5.7000191 | BW30: 5.7052145 | BX30: 5.7106761 | BY30: 5.7164168 | BZ30: 5.7224495 | CA30: 5.7287877 | CB30: 5.7354456 | CC30: 5.7424377 | CD30: 5.7497789 | CE30: 5.7574847 | CF30: 5.7655709 | CG30: 5.7740539 | CH30: 5.7829504 | CI30: 5.7922775 | CJ30: 5.8020526 | CK30: 5.8122935 | CL30: 5.8230181 | CM30: 5.8342446 | CN30: 5.8459912 | CO30: 5.8582763 | CP30: 5.8711181 | CQ30: 5.8845345 | CR30: 5.8985434 | CS30: 5.9131621 | CT30: 5.9284072 | CU30: 5.9442947 | CV30: 5.9608395 | CW30: 5.9780554 | CX30: 5.9959547 | CY30: 6.014548 | DA30: North America medium-moderate
A31: Delaware | B31: Non-residential | C31: 1.0883426 | D31: 1.1453755 | E31: 1.2018222 | F31: 1.2579012 | G31: 1.3160195 | H31: 1.3796774 | I31: 1.4423874 | J31: 1.4943924 | K31: 1.548535 | L31: 1.6089766 | M31: 1.6584119 | N31: 1.7171349 | O31: 1.776849 | P31: 1.841534 | Q31: 1.9074613 | R31: 1.972913 | S31: 2.0370996 | T31: 2.0972238 | U31: 2.1604991 | V31: 2.2211972 | W31: 2.2745387 | X31: 2.3567635 | Y31: 2.4430087 | Z31: 2.5348705 | AA31: 2.6155488 | AB31: 2.6797288 | AC31: 2.7479999 | AD31: 2.8229146 | AE31: 2.9042163 | AF31: 2.9836634 | AG31: 3.0503157 | AH31: 3.0972461 | AI31: 3.1345825 | AJ31: 3.1785836 | AK31: 3.2340152 | AL31: 3.2910535 | AM31: 3.3512295 | AN31: 3.4112515 | AO31: 3.4690491 | AP31: 3.5233833 | AQ31: 3.5743031 | AR31: 3.588757 | AS31: 3.6069441 | AT31: 3.6277116 | AU31: 3.6543803 | AV31: 3.6755614 | AW31: 3.7092261 | AX31: 3.7492498 | AY31: 3.8190849 | AZ31: 3.843594 | BA31: 3.8200738 | BB31: 3.792403 | BC31: 3.7669675 | BD31: 3.7167058 | BE31: 3.6626218 | BF31: 3.621336 | BG31: 3.6239236 | BH31: 3.6117582 | BI31: 3.6042142 | BJ31: 3.5617539 | BK31: 3.51658 | BL31: 3.4916234 | BM31: 3.4646032 | BN31: 3.4428337 | BO31: 3.4061091 | BP31: 3.3758316 | BQ31: 3.3297298 | BR31: 3.2871812 | BS31: 3.2428208 | BT31: 3.1910723 | BU31: 3.1161301 | BV31: 3.048286 | BW31: 3.0589907 | BX31: 3.0701543 | BY31: 3.081795 | BZ31: 3.0939314 | CA31: 3.1065826 | CB31: 3.1197683 | CC31: 3.1335086 | CD31: 3.1478239 | CE31: 3.1627353 | CF31: 3.1782641 | CG31: 3.1944319 | CH31: 3.2112607 | CI31: 3.2287726 | CJ31: 3.2469898 | CK31: 3.2659346 | CL31: 3.2856292 | CM31: 3.3060956 | CN31: 3.3273554 | CO31: 3.3494297 | CP31: 3.372339 | CQ31: 3.3961028 | CR31: 3.4207395 | CS31: 3.4462663 | CT31: 3.4726985 | CU31: 3.5000496 | CV31: 3.5283307 | CW31: 3.5575504 | CX31: 3.5877142 | CY31: 3.6188239 | DA31: North America low-moderate
A32: Delaware | B32: Infrastructure | C32: 1.386757 | D32: 1.4594277 | E32: 1.5313513 | F32: 1.6028056 | G32: 1.6768572 | H32: 1.7579647 | I32: 1.8378592 | J32: 1.9041042 | K32: 1.9730576 | L32: 2.050012 | M32: 2.1129039 | N32: 2.1875717 | O32: 2.2634197 | P32: 2.3454882 | Q32: 2.4289885 | R32: 2.5116872 | S32: 2.5925273 | T32: 2.6678885 | U32: 2.7469014 | V32: 2.8222039 | W32: 2.8876417 | X32: 2.9891909 | Y32: 3.0951769 | Z32: 3.2075604 | AA32: 3.3048671 | AB32: 3.3802644 | AC32: 3.4599352 | AD32: 3.5470894 | AE32: 3.641367 | AF32: 3.7322431 | AG32: 3.8057623 | AH32: 3.8534872 | AI32: 3.8880268 | AJ32: 3.9301085 | AK32: 3.9858177 | AL32: 4.0426503 | AM32: 4.1025708 | AN32: 4.1613977 | AO32: 4.2165059 | AP32: 4.266329 | AQ32: 4.3109431 | AR32: 4.3100283 | AS32: 4.3132736 | AT32: 4.3192348 | AU32: 4.3321719 | AV32: 4.3376057 | AW32: 4.3647211 | AX32: 4.3870019 | AY32: 4.4157358 | AZ32: 4.4047841 | BA32: 4.3510046 | BB32: 4.2970619 | BC32: 4.254283 | BD32: 4.1720731 | BE32: 4.0917827 | BF32: 4.0384411 | BG32: 4.0059754 | BH32: 3.9874338 | BI32: 3.9825285 | BJ32: 3.9548873 | BK32: 3.9357388 | BL32: 3.9329876 | BM32: 3.8984102 | BN32: 3.8893055 | BO32: 3.8557464 | BP32: 3.8642639 | BQ32: 3.8504744 | BR32: 3.8021298 | BS32: 3.7432832 | BT32: 3.6725365 | BU32: 3.5689077 | BV32: 3.4845951 | BW32: 3.4848532 | BX32: 3.4851429 | BY32: 3.4854679 | BZ32: 3.4858326 | CA32: 3.4862419 | CB32: 3.486701 | CC32: 3.4872162 | CD32: 3.4877943 | CE32: 3.4884428 | CF32: 3.4891704 | CG32: 3.4899868 | CH32: 3.4909026 | CI32: 3.4919299 | CJ32: 3.4930823 | CK32: 3.494375 | CL32: 3.4958249 | CM32: 3.4974511 | CN32: 3.4992749 | CO32: 3.50132 | CP32: 3.5036132 | CQ32: 3.5061843 | CR32: 3.5090666 | CS32: 3.5122974 | CT32: 3.5159182 | CU32: 3.5199755 | CV32: 3.524521 | CW32: 3.5296124 | CX32: 3.5353139 | CY32: 3.5416967 | DA32: North America low-moderate
A33: Delaware | B33: Total | C33: =SUM(C30:C32) -> 3.7940013 | D33: =SUM(D30:D32) -> 3.99282 | E33: =SUM(E30:E32) -> 4.1895948 | F33: =SUM(F30:F32) -> 4.3850872 | G33: =SUM(G30:G32) -> 4.5876874 | H33: =SUM(H30:H32) -> 4.8095963 | I33: =SUM(I30:I32) -> 5.0281955 | J33: =SUM(J30:J32) -> 5.2094675 | ... CY33: =SUM(CY30:CY32) -> 13.175069
A34: Florida | B34: Residential | C34: 5.1315705 | D34: 5.2083962 | E34: 5.2909268 | F34: 5.3787368 | G34: 5.4807435 | H34: 5.6096083 | I34: 5.737365 | J34: 5.8257965 | K34: 5.9260005 | L34: 6.0527175 | M34: 6.1403819 | N34: 6.27012 | O34: 6.4037002 | P34: 6.555132 | Q34: 6.7106654 | R34: 6.8642066 | S34: 7.0131245 | T34: 7.1480446 | U34: 7.2937352 | V34: 7.4307431 | W34: 7.5434607 | X34: 7.5533183 | Y34: 7.5791667 | Z34: 7.6242807 | AA34: 7.6378961 | AB34: 7.6075683 | AC34: 7.5936615 | AD34: 7.6017034 | AE34: 7.6293483 | AF34: 7.6540598 | AG34: 7.6486366 | AH34: 7.6127258 | AI34: 7.558982 | AJ34: 7.5266851 | AK34: 7.5256208 | AL34: 7.5316649 | AM34: 7.5478375 | AN34: 7.5663262 | AO34: 7.5824715 | AP34: 7.5936725 | AQ34: 7.6001953 | AR34: 7.5923565 | AS34: 7.5943546 | AT34: 7.6035577 | AU34: 7.6266605 | AV34: 7.6399438 | AW34: 7.6628367 | AX34: 7.6909296 | AY34: 7.7365684 | AZ34: 7.8031861 | BA34: 7.9195715 | BB34: 8.0495532 | BC34: 8.2034821 | BD34: 8.3576249 | BE34: 8.5446195 | BF34: 8.7820557 | BG34: 8.9430631 | BH34: 8.9408345 | BI34: 8.8716201 | BJ34: 8.79031 | BK34: 8.6882984 | BL34: 8.6462005 | BM34: 8.6009191 | BN34: 8.5857448 | BO34: 8.5612482 | BP34: 8.5314265 | BQ34: 8.5012213 | BR34: 8.5049488 | BS34: 8.5711036 | BT34: 8.6181797 | BU34: 8.7361516 | BV34: 8.840531 | BW34: 8.8414948 | BX34: 8.8425708 | BY34: 8.843771 | BZ34: 8.8451086 | CA34: 8.8465979 | CB34: 8.8482543 | CC34: 8.8500941 | CD34: 8.8521348 | CE34: 8.8543948 | CF34: 8.8568933 | CG34: 8.8596499 | CH34: 8.8626844 | CI34: 8.8660164 | CJ34: 8.8696648 | CK34: 8.8736468 | CL34: 8.8779774 | CM34: 8.882668 | CN34: 8.8877255 | CO34: 8.8931508 | CP34: 8.8989373 | CQ34: 8.905069 | CR34: 8.9115193 | CS34: 8.9182492 | CT34: 8.9252063 | CU34: 8.9323237 | CV34: 8.9395205 | CW34: 8.9467022 | CX34: 8.9537634 | CY34: 8.9605915 | DA34: North America high-fast
A35: Florida | B35: Non-residential | C35: 3.6088764 | D35: 3.6629056 | E35: 3.7209468 | F35: 3.7827009 | G35: 3.854439 | H35: 3.9450657 | I35: 4.0349131 | J35: 4.0971042 | K35: 4.1675744 | L35: 4.2566903 | M35: 4.3183414 | N35: 4.4095811 | O35: 4.5035217 | P35: 4.6100151 | Q35: 4.7193901 | R35: 4.8273594 | S35: 4.9320702 | T35: 5.0269265 | U35: 5.1293423 | V35: 5.2256309 | W35: 5.3048082 | X35: 5.3116157 | Y35: 5.3296243 | Z35: 5.361126 | AA35: 5.3704064 | AB35: 5.3486994 | AC35: 5.3384411 | AD35: 5.3435019 | AE35: 5.3622144 | AF35: 5.3787108 | AG35: 5.3738429 | AH35: 5.3473593 | AI35: 5.3081325 | AJ35: 5.2837714 | AK35: 5.281144 | AL35: 5.2832719 | AM35: 5.2922685 | AN35: 5.3026309 | AO35: 5.3110756 | AP35: 5.3157686 | AQ35: 5.3168941 | AR35: 5.3076054 | AS35: 5.304949 | AT35: 5.307075 | AU35: 5.3186938 | AV35: 5.3231275 | AW35: 5.3320497 | AX35: 5.3533756 | AY35: 5.3918962 | AZ35: 5.4174397 | BA35: 5.4250638 | BB35: 5.4196186 | BC35: 5.399949 | BD35: 5.3846766 | BE35: 5.3988365 | BF35: 5.4285454 | BG35: 5.4984926 | BH35: 5.5379377 | BI35: 5.550928 | BJ35: 5.5032979 | BK35: 5.4170211 | BL35: 5.3633847 | BM35: 5.3010445 | BN35: 5.2437668 | BO35: 5.1843294 | BP35: 5.0990418 | BQ35: 5.0197296 | BR35: 4.9502742 | BS35: 4.8906976 | BT35: 4.8598417 | BU35: 4.8586689 | BV35: 4.8308282 | BW35: 4.8455246 | BX35: 4.8621428 | BY35: 4.8809322 | BZ35: 4.902174 | CA35: 4.9261846 | CB35: 4.9533201 | CC35: 4.9839804 | CD35: 5.0186138 | CE35: 5.0577221 | CF35: 5.1018651 | CG35: 5.1516652 | CH35: 5.2078113 | CI35: 5.2710614 | CJ35: 5.3422433 | CK35: 5.4222516 | CL35: 5.5120404 | CM35: 5.6126081 | CN35: 5.7249726 | CO35: 5.8501324 | CP35: 5.9890089 | CQ35: 6.1423653 | CR35: 6.310697 | CS35: 6.49409 | CT35: 6.6920486 | CU35: 6.9033002 | CV35: 7.1255995 | CW35: 7.3555686 | CX35: 7.5886303 | CY35: 7.8191023 | DA35: North America high-fast
A36: Florida | B36: Infrastructure | C36: 2.5778005 | D36: 2.616393 | E36: 2.6578509 | F36: 2.7019599 | G36: 2.7531984 | H36: 2.8179248 | I36: 2.8820868 | J36: 2.9264805 | K36: 2.9767657 | L36: 3.0403339 | M36: 3.0842309 | N36: 3.149182 | O36: 3.2159508 | P36: 3.2915346 | Q36: 3.3689779 | R36: 3.4451632 | S36: 3.5187052 | T36: 3.5848252 | U36: 3.6558908 | V36: 3.722053 | W36: 3.7753934 | X36: 3.7766509 | Y36: 3.785294 | Z36: 3.8029239 | AA36: 3.8040032 | AB36: 3.7822529 | AC36: 3.7679771 | AD36: 3.7639419 | AE36: 3.768966 | AF36: 3.7717322 | AG36: 3.7585851 | AH36: 3.7295816 | AI36: 3.6909134 | AJ36: 3.66233 | AK36: 3.6487653 | AL36: 3.6381177 | AM36: 3.6319205 | AN36: 3.6262641 | AO36: 3.6188226 | AP36: 3.6083036 | AQ36: 3.5948558 | AR36: 3.5733639 | AS36: 3.5562424 | AT36: 3.5421899 | AU36: 3.5345936 | AV36: 3.5215658 | AW36: 3.5115447 | AX36: 3.5025946 | AY36: 3.4825399 | AZ36: 3.4663059 | BA36: 3.4436004 | BB36: 3.4254413 | BC36: 3.4076299 | BD36: 3.3946789 | BE36: 3.4027566 | BF36: 3.4257321 | BG36: 3.4642 | BH36: 3.4999028 | BI36: 3.5086298 | BJ36: 3.4842067 | BK36: 3.4586957 | BL36: 3.4503491 | BM36: 3.4359961 | BN36: 3.4263185 | BO36: 3.4173059 | BP36: 3.4064972 | BQ36: 3.3849954 | BR36: 3.3626018 | BS36: 3.3494075 | BT36: 3.3755975 | BU36: 3.3941132 | BV36: 3.392569 | BW36: 3.4585414 | BX36: 3.5284464 | BY36: 3.6025081 | BZ36: 3.6809573 | CA36: 3.7640305 | CB36: 3.8519676 | CC36: 3.9450091 | CD36: 4.0433937 | CE36: 4.1473532 | CF36: 4.2571085 | CG36: 4.3728628 | CH36: 4.4947951 | CI36: 4.6230514 | CJ36: 4.757735 | CK36: 4.8988958 | CL36: 5.046518 | CM36: 5.2005069 | CN36: 5.3606751 | CO36: 5.5267284 | CP36: 5.6982523 | CQ36: 5.8746999 | CR36: 6.0553821 | CS36: 6.2394617 | CT36: 6.4259527 | CU36: 6.6137255 | CV36: 6.8015205 | CW36: 6.9879694 | CX36: 7.1716257 | CY36: 7.3510032 | DA36: North America high-fast
A37: Florida | B37: Total | C37: =SUM(C34:C36) -> 11.318247 | D37: =SUM(D34:D36) -> 11.487695 | E37: =SUM(E34:E36) -> 11.669725 | F37: =SUM(F34:F36) -> 11.863398 | G37: =SUM(G34:G36) -> 12.088381 | H37: =SUM(H34:H36) -> 12.372599 | I37: =SUM(I34:I36) -> 12.654365 | J37: =SUM(J34:J36) -> 12.849381 | ... CY37: =SUM(CY34:CY36) -> 24.130697
A38: Georgia | B38: Residential | C38: 1.6664615 | D38: 1.7984487 | E38: 1.9326219 | F38: 2.0691454 | G38: 2.2119041 | H38: 2.3670028 | I38: 2.5235418 | J38: 2.663912 | K38: 2.8102732 | L38: 2.9704276 | M38: 3.1123939 | N38: 3.242952 | O38: 3.3761175 | P38: 3.5194966 | Q38: 3.6660518 | R38: 3.812468 | S38: 3.9571646 | T38: 4.0946133 | U38: 4.2388252 | V38: 4.3785773 | W38: 4.5043175 | X38: 4.6187204 | Y38: 4.7394216 | Z38: 4.8693523 | AA38: 4.976345 | AB38: 5.0510891 | AC38: 5.1329638 | AD38: 5.2265408 | AE38: 5.3310872 | AF38: 5.4313819 | AG38: 5.5078488 | AH38: 5.5582277 | AI38: 5.5919761 | AJ38: 5.6382014 | AK38: 5.7050869 | AL38: 5.7751028 | AM38: 5.8508856 | AN38: 5.9266653 | AO38: 5.9988985 | AP38: 6.0655349 | AQ38: 6.1267573 | AR38: 6.1035163 | AS38: 6.0890441 | AT38: 6.0811119 | AU38: 6.0849639 | AV38: 6.0815942 | AW38: 6.0919006 | AX38: 6.0994896 | AY38: 6.1168505 | AZ38: 6.1349737 | BA38: 6.2014492 | BB38: 6.2705895 | BC38: 6.3223979 | BD38: 6.3994389 | BE38: 6.4796276 | BF38: 6.5912308 | BG38: 6.7253942 | BH38: 6.7623355 | BI38: 6.7467601 | BJ38: 6.6748186 | BK38: 6.5893819 | BL38: 6.5586643 | BM38: 6.5451567 | BN38: 6.5800082 | BO38: 6.5751094 | BP38: 6.5716815 | BQ38: 6.584244 | BR38: 6.6088307 | BS38: 6.6750983 | BT38: 6.6986804 | BU38: 6.7217063 | BV38: 6.7952738 | BW38: 6.7968221 | BX38: 6.7985087 | BY38: 6.8003445 | BZ38: 6.8023411 | CA38: 6.8045105 | CB38: 6.8068653 | CC38: 6.8094186 | CD38: 6.8121836 | CE38: 6.815174 | CF38: 6.8184033 | CG38: 6.8218851 | CH38: 6.8256324 | CI38: 6.8296574 | CJ38: 6.8339716 | CK38: 6.8385848 | CL38: 6.8435048 | CM38: 6.848737 | CN38: 6.8542837 | CO38: 6.8601435 | CP38: 6.8663103 | CQ38: 6.8727731 | CR38: 6.8795147 | CS38: 6.8865115 | CT38: 6.8937325 | CU38: 6.9011389 | CV38: 6.9086842 | CW38: 6.9163136 | CX38: 6.9239649 | CY38: 6.931569 | DA38: North America medium-fast
A39: Georgia | B39: Non-residential | C39: 1.8190649 | D39: 1.9631387 | E39: 2.1095985 | F39: 2.2586239 | G39: 2.4144555 | H39: 2.5837571 | I39: 2.7546309 | J39: 2.9078552 | K39: 3.0676191 | L39: 3.2424392 | M39: 3.3974053 | N39: 3.5399181 | O39: 3.6852762 | P39: 3.8417816 | Q39: 4.0017513 | R39: 4.1615653 | S39: 4.3194955 | T39: 4.4695046 | U39: 4.6268818 | V39: 4.7793706 | W39: 4.9165364 | X39: 5.0412907 | Y39: 5.1728715 | Z39: 5.3144649 | AA39: 5.4309411 | AB39: 5.5121188 | AC39: 5.600962 | AD39: 5.7024384 | AE39: 5.8157231 | AF39: 5.9241752 | AG39: 6.0063987 | AH39: 6.0599176 | AI39: 6.0950175 | AJ39: 6.1434464 | AK39: 6.2141132 | AL39: 6.2878607 | AM39: 6.3675468 | AN39: 6.4468558 | AO39: 6.5219042 | AP39: 6.5904417 | AQ39: 6.6526571 | AR39: 6.6226736 | AS39: 6.6019263 | AT39: 6.5879848 | AU39: 6.5865772 | AV39: 6.5769623 | AW39: 6.5679628 | AX39: 6.5659883 | AY39: 6.594219 | AZ39: 6.5988018 | BA39: 6.5702018 | BB39: 6.5531675 | BC39: 6.514882 | BD39: 6.4739814 | BE39: 6.4750546 | BF39: 6.4676337 | BG39: 6.4474804 | BH39: 6.4326573 | BI39: 6.4088633 | BJ39: 6.3451545 | BK39: 6.2421049 | BL39: 6.1990381 | BM39: 6.1375006 | BN39: 6.0788784 | BO39: 6.0278028 | BP39: 5.976111 | BQ39: 5.9185456 | BR39: 5.8729241 | BS39: 5.8199953 | BT39: 5.7930368 | BU39: 5.7657843 | BV39: 5.7567402 | BW39: 5.7642043 | BX39: 5.7725368 | BY39: 5.7818328 | BZ39: 5.7921962 | CA39: 5.8037404 | CB39: 5.816588 | CC39: 5.8308714 | CD39: 5.8467323 | CE39: 5.8643215 | CF39: 5.8837976 | CG39: 5.9053259 | CH39: 5.9290758 | CI39: 5.9552178 | CJ39: 5.9839192 | CK39: 6.0153386 | CL39: 6.0496182 | CM39: 6.0868754 | CN39: 6.1271911 | CO39: 6.1705969 | CP39: 6.2170598 | CQ39: 6.2664657 | CR39: 6.3186014 | CS39: 6.3731376 | CT39: 6.429614 | CU39: 6.4874294 | CV39: 6.5458403 | CW39: 6.6039707 | CX39: 6.6608377 | CY39: 6.7153951 | DA39: North America medium-fast
A40: Georgia | B40: Infrastructure | C40: 1.3199778 | D40: 1.4245227 | E40: 1.5307988 | F40: 1.6389359 | G40: 1.7520104 | H40: 1.8748562 | I40: 1.9988372 | J40: 2.1100005 | K40: 2.2258908 | L40: 2.3526765 | M40: 2.4650085 | N40: 2.5682352 | O40: 2.6734269 | P40: 2.7865695 | Q40: 2.9020408 | R40: 3.0171577 | S40: 3.1306016 | T40: 3.2379189 | U40: 3.3501256 | V40: 3.4582443 | W40: 3.5546179 | X40: 3.6413555 | Y40: 3.732294 | Z40: 3.8296784 | AA40: 3.9079587 | AB40: 3.9596982 | AC40: 4.0160357 | AD40: 4.0805498 | AE40: 4.1526269 | AF40: 4.2201869 | AG40: 4.2677082 | AH40: 4.2936695 | AI40: 4.3053473 | AJ40: 4.3258023 | AK40: 4.3615236 | AL40: 4.3986341 | AM40: 4.439231 | AN40: 4.4787532 | AO40: 4.5144034 | AP40: 4.5445687 | AQ40: 4.569406 | AR40: 4.5295297 | AS40: 4.495955 | AT40: 4.4669423 | AU40: 4.4466753 | AV40: 4.4201339 | AW40: 4.3944788 | AX40: 4.367286 | AY40: 4.3361788 | AZ40: 4.3086468 | BA40: 4.262829 | BB40: 4.2382869 | BC40: 4.2079213 | BD40: 4.1782597 | BE40: 4.1876801 | BF40: 4.1981525 | BG40: 4.1998649 | BH40: 4.2339875 | BI40: 4.2267418 | BJ40: 4.1829719 | BK40: 4.1322698 | BL40: 4.1087112 | BM40: 4.082675 | BN40: 4.0538883 | BO40: 4.054253 | BP40: 4.0605533 | BQ40: 4.0652063 | BR40: 4.0751427 | BS40: 4.0659521 | BT40: 4.0743653 | BU40: 4.0696346 | BV40: 4.0968772 | BW40: 4.183037 | BX40: 4.268388 | BY40: 4.3528322 | BZ40: 4.4362761 | CA40: 4.5186308 | CB40: 4.5998123 | CC40: 4.6797421 | CD40: 4.7583469 | CE40: 4.8355594 | CF40: 4.911318 | CG40: 4.985567 | CH40: 5.0582567 | CI40: 5.1293434 | CJ40: 5.1987893 | CK40: 5.2665624 | CL40: 5.3326365 | CM40: 5.396991 | CN40: 5.4596106 | CO40: 5.5204851 | CP40: 5.5796095 | CQ40: 5.6369833 | CR40: 5.6926105 | CS40: 5.7464993 | CT40: 5.7986618 | CU40: 5.8491136 | CV40: 5.8978737 | CW40: 5.9449641 | CX40: 5.9904097 | CY40: 6.0342376 | DA40: North America medium-fast
A41: Georgia | B41: Total | C41: =SUM(C38:C40) -> 4.8055043 | D41: =SUM(D38:D40) -> 5.1861102 | E41: =SUM(E38:E40) -> 5.5730192 | F41: =SUM(F38:F40) -> 5.9667052 | G41: =SUM(G38:G40) -> 6.37837 | H41: =SUM(H38:H40) -> 6.8256161 | I41: =SUM(I38:I40) -> 7.2770098 | J41: =SUM(J38:J40) -> 7.6817677 | ... CY41: =SUM(CY38:CY40) -> 19.681202
...

Sheet SD2
A1: Future cement demand per state and application (ready-mix concrete only)
A2: 1950-2024: Historical, 2025-2500: Projected
A3: thousand metric tons
A5: State | B5: Application | C5: 1950 | D5: 1951 | E5: 1952 | F5: 1953 | G5: 1954 | H5: 1955 | I5: 1956 | J5: 1957 | K5: 1958 | L5: 1959 | M5: 1960 | N5: 1961 | O5: 1962 | P5: 1963 | Q5: 1964 | R5: 1965 | S5: 1966 | T5: 1967 | U5: 1968 | V5: 1969 | W5: 1970 | X5: 1971 | Y5: 1972 | Z5: 1973 | AA5: 1974 | AB5: 1975 | AC5: 1976 | AD5: 1977 | AE5: 1978 | AF5: 1979 | AG5: 1980 | AH5: 1981 | AI5: 1982 | AJ5: 1983 | AK5: 1984 | AL5: 1985 | AM5: 1986 | AN5: 1987 | AO5: 1988 | AP5: 1989 | AQ5: 1990 | AR5: 1991 | AS5: 1992 | AT5: 1993 | AU5: 1994 | AV5: 1995 | AW5: 1996 | AX5: 1997 | AY5: 1998 | AZ5: 1999 | BA5: 2000 | BB5: 2001 | BC5: 2002 | BD5: 2003 | BE5: 2004 | BF5: 2005 | BG5: 2006 | BH5: 2007 | BI5: 2008 | BJ5: 2009 | BK5: 2010 | BL5: 2011 | BM5: 2012 | BN5: 2013 | BO5: 2014 | BP5: 2015 | BQ5: 2016 | BR5: 2017 | BS5: 2018 | BT5: 2019 | BU5: 2020 | BV5: 2021 | BW5: 2022 | BX5: 2023 | BY5: 2024 | BZ5: 2025 | CA5: 2026 | CB5: 2027 | CC5: 2028 | CD5: 2029 | CE5: 2030 | CF5: 2031 | CG5: 2032 | CH5: 2033 | CI5: 2034 | CJ5: 2035 | CK5: 2036 | CL5: 2037 | CM5: 2038 | CN5: 2039 | CO5: 2040 | CP5: 2041 | CQ5: 2042 | CR5: 2043 | CS5: 2044 | CT5: 2045 | CU5: 2046 | CV5: 2047 | CW5: 2048 | CX5: 2049 | CY5: 2050
